Workbook

Sheet Прайс
A1: ="ПРАЙС BUKOVEL · "&$B$3&" · "&$U$11&" · Тариф: "&$B$4&" · Пакет: "&$B$5 -> ПРАЙС BUKOVEL · Осінь 2026 (00-10%) · 01.10.2026 – 30.11.2026 · Тариф: Rack Rate · Пакет: ROSPA | U1: ТЕХНІЧНІ ДАНІ — НЕ РЕДАГУВАТИ
A3: Активний прайс-лист | B3: Осінь 2026 (00-10%) | D3: ="Період дії: "&$U$11 -> Період дії: 01.10.2026 – 30.11.2026 | U3: =IFERROR(MATCH($B$3,ПЛ_РЯДОК,0),0) -> 5 | V3: колонка прайс-листа
A4: Тариф (знижка) | B4: Rack Rate | D4: ="Знижка на проживання: "&TEXT($U$5,"0%")&IF($B$5="BBSPA"," — фіксована для пакета BBSPA; обраний тариф не застосовується","") -> Знижка на проживання: 0% | U4: =IFERROR(SUMIFS(ТАРИФИ_ЗНИЖКИ,ТАРИФИ_НАЗВИ,$B$4),0) -> 0 | V4: знижка тарифу
A5: Пакет | B5: ROSPA | D5: =IF($B$5="RO","Лише проживання.",IF($B$5="BB","Проживання + сніданок за кожного гостя.",IF($B$5="BBSPA","Проживання + сніданок і SPA за кожного гостя.",IF($B$5="ROSPA","Проживання + 1 SPA-візит на обʼєкт.",IF($B$5="ROSPABB","Проживання + сніданки за кількістю гостей + 1 SPA-візит на обʼєкт.",""))))) -> Проживання + 1 SPA-візит на обʼєкт. | U5: =IF($B$5="BBSPA",ЗНИЖКА_BBSPA,$U$4) -> 0 | V5: знижка на проживання
A6: =IF($U$3=0,"⚠ Прайс-лист не обрано або не знайдено — оберіть значення у клітинці B3.",IF($U$13=0,"⚠ У цьому прайс-листі ще не заповнені базові RO-ціни — сітка буде порожньою. Заповніть його блок на листі «Керування прайсом».","Усі ціни — за ніч, за дорослих гостей, у гривні. Дитячі тарифи рахує лист «Калькулятор». З 3-го гостя додається фіксований крок; вихідні рахуються через множник вихідних.")) -> Усі ціни — за ніч, за дорослих гостей, у гривні. Дитячі тарифи рахує лист «Калькулятор». З 3-го гостя додається фіксований крок; вихідні рахуються через множник вихідних. | U6: =IF($U$3=0,0,IFERROR(INDEX(ПЕРЕМИКАЧІ,IF($B$5="BBSPA",2,1),$U$3),0)) -> 0 | V6: перемикач: пакет
D7: БУДНІ — кількість гостей | L7: ВИХІДНІ — кількість гостей | U7: =IF($U$3=0,0,IFERROR(INDEX(ПЕРЕМИКАЧІ,3,$U$3),0)) -> 0 | V7: перемикач: SPA
A8: Категорія | B8: Назва на Booking | C8: Група | D8: 1 | E8: 2 | F8: 3 | G8: 4 | H8: 5 | I8: 6 | J8: 7 | K8: 8 | L8: 1 | M8: 2 | N8: 3 | O8: 4 | P8: 5 | Q8: 6 | R8: 7 | S8: 8 | U8: =IF(OR($B$5="BB",$B$5="BBSPA",$B$5="ROSPABB"),1,0) -> 0 | V8: потрібен пакет
A9: =IF('Довідник категорій'!A5="","",'Довідник категорій'!A5) -> Міні-котедж | B9: =IF($A9="","",IFERROR(INDEX(ДОВ_BOOKING,MATCH($A9,КАТЕГОРІЇ,0)),"")) -> Віла з 1 спальнею 45 м² | C9: =IF($A9="","",IFERROR(INDEX(ДОВ_ГРУПА,MATCH($A9,КАТЕГОРІЇ,0)),"")) -> Котеджі 1 спальня | D9: =IF(OR($AE9=0,D$8>$Z9),"",ROUND(((W9*X9+MAX(0,D$8-$AA9)*КРОК_ГОСТЯ)*(1-$U$5)+D$8*$AB9*(1-$U$5*$U$6)+$AD9*(1-$U$5*$U$7))/ОКРУГЛЕННЯ,0)*ОКРУГЛЕННЯ) -> 5398 | E9: =IF(OR($AE9=0,E$8>$Z9),"",ROUND(((W9*X9+MAX(0,E$8-$AA9)*КРОК_ГОСТЯ)*(1-$U$5)+E$8*$AB9*(1-$U$5*$U$6)+$AD9*(1-$U$5*$U$7))/ОКРУГЛЕННЯ,0)*ОКРУГЛЕННЯ) -> 5398 | F9: =IF(OR($AE9=0,F$8>$Z9),"",ROUND(((W9*X9+MAX(0,F$8-$AA9)*КРОК_ГОСТЯ)*(1-$U$5)+F$8*$AB9*(1-$U$5*$U$6)+$AD9*(1-$U$5*$U$7))/ОКРУГЛЕННЯ,0)*ОКРУГЛЕННЯ) -> 5898 | G9: =IF(OR($AE9=0,G$8>$Z9),"",ROUND(((W9*X9+MAX(0,G$8-$AA9)*КРОК_ГОСТЯ)*(1-$U$5)+G$8*$AB9*(1-$U$5*$U$6)+$AD9*(1-$U$5*$U$7))/ОКРУГЛЕННЯ,0)*ОКРУГЛЕННЯ) | H9: =IF(OR($AE9=0,H$8>$Z9),"",ROUND(((W9*X9+MAX(0,H$8-$AA9)*КРОК_ГОСТЯ)*(1-$U$5)+H$8*$AB9*(1-$U$5*$U$6)+$AD9*(1-$U$5*$U$7))/ОКРУГЛЕННЯ,0)*ОКРУГЛЕННЯ) | I9: =IF(OR($AE9=0,I$8>$Z9),"",ROUND(((W9*X9+MAX(0,I$8-$AA9)*КРОК_ГОСТЯ)*(1-$U$5)+I$8*$AB9*(1-$U$5*$U$6)+$AD9*(1-$U$5*$U$7))/ОКРУГЛЕННЯ,0)*ОКРУГЛЕННЯ) | J9: =IF(OR($AE9=0,J$8>$Z9),"",ROUND(((W9*X9+MAX(0,J$8-$AA9)*КРОК_ГОСТЯ)*(1-$U$5)+J$8*$AB9*(1-$U$5*$U$6)+$AD9*(1-$U$5*$U$7))/ОКРУГЛЕННЯ,0)*ОКРУГЛЕННЯ) | K9: =IF(OR($AE9=0,K$8>$Z9),"",ROUND(((W9*X9+MAX(0,K$8-$AA9)*КРОК_ГОСТЯ)*(1-$U$5)+K$8*$AB9*(1-$U$5*$U$6)+$AD9*(1-$U$5*$U$7))/ОКРУГЛЕННЯ,0)*ОКРУГЛЕННЯ) | L9: =IF(OR($AF9=0,L$8>$Z9),"",ROUND(((W9*X9*Y9+MAX(0,L$8-$AA9)*КРОК_ГОСТЯ)*(1-$U$5)+L$8*$AC9*(1-$U$5*$U$6)+$AD9*(1-$U$5*$U$7))/ОКРУГЛЕННЯ,0)*ОКРУГЛЕННЯ) -> 5898 | M9: =IF(OR($AF9=0,M$8>$Z9),"",ROUND(((W9*X9*Y9+MAX(0,M$8-$AA9)*КРОК_ГОСТЯ)*(1-$U$5)+M$8*$AC9*(1-$U$5*$U$6)+$AD9*(1-$U$5*$U$7))/ОКРУГЛЕННЯ,0)*ОКРУГЛЕННЯ) -> 5898 | N9: =IF(OR($AF9=0,N$8>$Z9),"",ROUND(((W9*X9*Y9+MAX(0,N$8-$AA9)*КРОК_ГОСТЯ)*(1-$U$5)+N$8*$AC9*(1-$U$5*$U$6)+$AD9*(1-$U$5*$U$7))/ОКРУГЛЕННЯ,0)*ОКРУГЛЕННЯ) -> 6398 | O9: =IF(OR($AF9=0,O$8>$Z9),"",ROUND(((W9*X9*Y9+MAX(0,O$8-$AA9)*КРОК_ГОСТЯ)*(1-$U$5)+O$8*$AC9*(1-$U$5*$U$6)+$AD9*(1-$U$5*$U$7))/ОКРУГЛЕННЯ,0)*ОКРУГЛЕННЯ) | P9: =IF(OR($AF9=0,P$8>$Z9),"",ROUND(((W9*X9*Y9+MAX(0,P$8-$AA9)*КРОК_ГОСТЯ)*(1-$U$5)+P$8*$AC9*(1-$U$5*$U$6)+$AD9*(1-$U$5*$U$7))/ОКРУГЛЕННЯ,0)*ОКРУГЛЕННЯ) | Q9: =IF(OR($AF9=0,Q$8>$Z9),"",ROUND(((W9*X9*Y9+MAX(0,Q$8-$AA9)*КРОК_ГОСТЯ)*(1-$U$5)+Q$8*$AC9*(1-$U$5*$U$6)+$AD9*(1-$U$5*$U$7))/ОКРУГЛЕННЯ,0)*ОКРУГЛЕННЯ) | R9: =IF(OR($AF9=0,R$8>$Z9),"",ROUND(((W9*X9*Y9+MAX(0,R$8-$AA9)*КРОК_ГОСТЯ)*(1-$U$5)+R$8*$AC9*(1-$U$5*$U$6)+$AD9*(1-$U$5*$U$7))/ОКРУГЛЕННЯ,0)*ОКРУГЛЕННЯ) | S9: =IF(OR($AF9=0,S$8>$Z9),"",ROUND(((W9*X9*Y9+MAX(0,S$8-$AA9)*КРОК_ГОСТЯ)*(1-$U$5)+S$8*$AC9*(1-$U$5*$U$6)+$AD9*(1-$U$5*$U$7))/ОКРУГЛЕННЯ,0)*ОКРУГЛЕННЯ) | U9: =IF(OR($B$5="ROSPA",$B$5="ROSPABB"),1,0) -> 1 | V9: потрібен SPA | W9: =IF(OR($U$3=0,$A9=""),0,IFERROR(INDEX(БАЗА_RO,MATCH(INDEX(ДОВ_ОПОРА,MATCH($A9,КАТЕГОРІЇ,0)),БАЗА_КАТ,0),$U$3),0)) -> 4998 | X9: =IF(OR($U$3=0,$A9=""),0,IFERROR(INDEX(МНОЖНИКИ,MATCH($A9,МНОЖ_КАТ,0),$U$3),0)) -> 1 | Y9: =IF(OR($U$3=0,$A9=""),0,IFERROR(INDEX(МНОЖНИКИ,MATCH($A9,МНОЖ_КАТ,0),$U$3+1),0)) -> 1.1 | Z9: =IF($A9="",0,IFERROR(INDEX(ДОВ_МАКС,MATCH($A9,КАТЕГОРІЇ,0)),0)) -> 3 | AA9: =IF($A9="",0,IFERROR(INDEX(ДОВ_ВКЛ,MATCH($A9,КАТЕГОРІЇ,0)),0)) -> 2 | AB9: =IF(OR($U$3=0,$U$8=0),0,IFERROR(INDEX(ПАКЕТИ_ЦІНИ,MATCH($U$10&"|Будні",ПАКЕТИ_КЛЮЧ,0),$U$3),0)) -> 0 | AC9: =IF(OR($U$3=0,$U$8=0),0,IFERROR(INDEX(ПАКЕТИ_ЦІНИ,MATCH($U$10&"|Вихідні",ПАКЕТИ_КЛЮЧ,0),$U$3),0)) -> 0 | AD9: =IF(OR($U$3=0,$U$9=0,$A9=""),0,IFERROR(INDEX(SPA_ЦІНИ,MATCH(INDEX(ДОВ_SPA,MATCH($A9,КАТЕГОРІЇ,0)),SPA_РОЛЬ,0),$U$3),0)) -> 400 | AE9: =IF(OR($A9="",W9=0,X9=0,AND($U$8=1,AB9=0),AND($U$9=1,AD9=0)),0,1) -> 1 | AF9: =IF(OR(AE9=0,Y9=0,AND($U$8=1,AC9=0)),0,1) -> 1
A10: =IF('Довідник категорій'!A6="","",'Довідник категорій'!A6) -> Міні-котедж East Hill | B10: =IF($A10="","",IFERROR(INDEX(ДОВ_BOOKING,MATCH($A10,КАТЕГОРІЇ,0)),"")) -> Віла з 1 спальнею 45 м² | C10: =IF($A10="","",IFERROR(INDEX(ДОВ_ГРУПА,MATCH($A10,КАТЕГОРІЇ,0)),"")) -> Котеджі 1 спальня | D10: =IF(OR($AE10=0,D$8>$Z10),"",ROUND(((W10*X10+MAX(0,D$8-$AA10)*КРОК_ГОСТЯ)*(1-$U$5)+D$8*$AB10*(1-$U$5*$U$6)+$AD10*(1-$U$5*$U$7))/ОКРУГЛЕННЯ,0)*ОКРУГЛЕННЯ) -> 5648 | E10: =IF(OR($AE10=0,E$8>$Z10),"",ROUND(((W10*X10+MAX(0,E$8-$AA10)*КРОК_ГОСТЯ)*(1-$U$5)+E$8*$AB10*(1-$U$5*$U$6)+$AD10*(1-$U$5*$U$7))/ОКРУГЛЕННЯ,0)*ОКРУГЛЕННЯ) -> 5648 | F10: =IF(OR($AE10=0,F$8>$Z10),"",ROUND(((W10*X10+MAX(0,F$8-$AA10)*КРОК_ГОСТЯ)*(1-$U$5)+F$8*$AB10*(1-$U$5*$U$6)+$AD10*(1-$U$5*$U$7))/ОКРУГЛЕННЯ,0)*ОКРУГЛЕННЯ) -> 6148 | G10: =IF(OR($AE10=0,G$8>$Z10),"",ROUND(((W10*X10+MAX(0,G$8-$AA10)*КРОК_ГОСТЯ)*(1-$U$5)+G$8*$AB10*(1-$U$5*$U$6)+$AD10*(1-$U$5*$U$7))/ОКРУГЛЕННЯ,0)*ОКРУГЛЕННЯ) | H10: =IF(OR($AE10=0,H$8>$Z10),"",ROUND(((W10*X10+MAX(0,H$8-$AA10)*КРОК_ГОСТЯ)*(1-$U$5)+H$8*$AB10*(1-$U$5*$U$6)+$AD10*(1-$U$5*$U$7))/ОКРУГЛЕННЯ,0)*ОКРУГЛЕННЯ) | I10: =IF(OR($AE10=0,I$8>$Z10),"",ROUND(((W10*X10+MAX(0,I$8-$AA10)*КРОК_ГОСТЯ)*(1-$U$5)+I$8*$AB10*(1-$U$5*$U$6)+$AD10*(1-$U$5*$U$7))/ОКРУГЛЕННЯ,0)*ОКРУГЛЕННЯ) | J10: =IF(OR($AE10=0,J$8>$Z10),"",ROUND(((W10*X10+MAX(0,J$8-$AA10)*КРОК_ГОСТЯ)*(1-$U$5)+J$8*$AB10*(1-$U$5*$U$6)+$AD10*(1-$U$5*$U$7))/ОКРУГЛЕННЯ,0)*ОКРУГЛЕННЯ) | K10: =IF(OR($AE10=0,K$8>$Z10),"",ROUND(((W10*X10+MAX(0,K$8-$AA10)*КРОК_ГОСТЯ)*(1-$U$5)+K$8*$AB10*(1-$U$5*$U$6)+$AD10*(1-$U$5*$U$7))/ОКРУГЛЕННЯ,0)*ОКРУГЛЕННЯ) | L10: =IF(OR($AF10=0,L$8>$Z10),"",ROUND(((W10*X10*Y10+MAX(0,L$8-$AA10)*КРОК_ГОСТЯ)*(1-$U$5)+L$8*$AC10*(1-$U$5*$U$6)+$AD10*(1-$U$5*$U$7))/ОКРУГЛЕННЯ,0)*ОКРУГЛЕННЯ) -> 6120 | M10: =IF(OR($AF10=0,M$8>$Z10),"",ROUND(((W10*X10*Y10+MAX(0,M$8-$AA10)*КРОК_ГОСТЯ)*(1-$U$5)+M$8*$AC10*(1-$U$5*$U$6)+$AD10*(1-$U$5*$U$7))/ОКРУГЛЕННЯ,0)*ОКРУГЛЕННЯ) -> 6120 | N10: =IF(OR($AF10=0,N$8>$Z10),"",ROUND(((W10*X10*Y10+MAX(0,N$8-$AA10)*КРОК_ГОСТЯ)*(1-$U$5)+N$8*$AC10*(1-$U$5*$U$6)+$AD10*(1-$U$5*$U$7))/ОКРУГЛЕННЯ,0)*ОКРУГЛЕННЯ) -> 6620 | O10: =IF(OR($AF10=0,O$8>$Z10),"",ROUND(((W10*X10*Y10+MAX(0,O$8-$AA10)*КРОК_ГОСТЯ)*(1-$U$5)+O$8*$AC10*(1-$U$5*$U$6)+$AD10*(1-$U$5*$U$7))/ОКРУГЛЕННЯ,0)*ОКРУГЛЕННЯ) | P10: =IF(OR($AF10=0,P$8>$Z10),"",ROUND(((W10*X10*Y10+MAX(0,P$8-$AA10)*КРОК_ГОСТЯ)*(1-$U$5)+P$8*$AC10*(1-$U$5*$U$6)+$AD10*(1-$U$5*$U$7))/ОКРУГЛЕННЯ,0)*ОКРУГЛЕННЯ) | Q10: =IF(OR($AF10=0,Q$8>$Z10),"",ROUND(((W10*X10*Y10+MAX(0,Q$8-$AA10)*КРОК_ГОСТЯ)*(1-$U$5)+Q$8*$AC10*(1-$U$5*$U$6)+$AD10*(1-$U$5*$U$7))/ОКРУГЛЕННЯ,0)*ОКРУГЛЕННЯ) | R10: =IF(OR($AF10=0,R$8>$Z10),"",ROUND(((W10*X10*Y10+MAX(0,R$8-$AA10)*КРОК_ГОСТЯ)*(1-$U$5)+R$8*$AC10*(1-$U$5*$U$6)+$AD10*(1-$U$5*$U$7))/ОКРУГЛЕННЯ,0)*ОКРУГЛЕННЯ) | S10: =IF(OR($AF10=0,S$8>$Z10),"",ROUND(((W10*X10*Y10+MAX(0,S$8-$AA10)*КРОК_ГОСТЯ)*(1-$U$5)+S$8*$AC10*(1-$U$5*$U$6)+$AD10*(1-$U$5*$U$7))/ОКРУГЛЕННЯ,0)*ОКРУГЛЕННЯ) | U10: =IF($U$8=0,"",IF($B$5="ROSPABB","BB",$B$5)) | V10: ключ пакета | W10: =IF(OR($U$3=0,$A10=""),0,IFERROR(INDEX(БАЗА_RO,MATCH(INDEX(ДОВ_ОПОРА,MATCH($A10,КАТЕГОРІЇ,0)),БАЗА_КАТ,0),$U$3),0)) -> 4998 | X10: =IF(OR($U$3=0,$A10=""),0,IFERROR(INDEX(МНОЖНИКИ,MATCH($A10,МНОЖ_КАТ,0),$U$3),0)) -> 1.05 | Y10: =IF(OR($U$3=0,$A10=""),0,IFERROR(INDEX(МНОЖНИКИ,MATCH($A10,МНОЖ_КАТ,0),$U$3+1),0)) -> 1.09 | Z10: =IF($A10="",0,IFERROR(INDEX(ДОВ_МАКС,MATCH($A10,КАТЕГОРІЇ,0)),0)) -> 3 | AA10: =IF($A10="",0,IFERROR(INDEX(ДОВ_ВКЛ,MATCH($A10,КАТЕГОРІЇ,0)),0)) -> 2 | AB10: =IF(OR($U$3=0,$U$8=0),0,IFERROR(INDEX(ПАКЕТИ_ЦІНИ,MATCH($U$10&"|Будні",ПАКЕТИ_КЛЮЧ,0),$U$3),0)) -> 0 | AC10: =IF(OR($U$3=0,$U$8=0),0,IFERROR(INDEX(ПАКЕТИ_ЦІНИ,MATCH($U$10&"|Вихідні",ПАКЕТИ_КЛЮЧ,0),$U$3),0)) -> 0 | AD10: =IF(OR($U$3=0,$U$9=0,$A10=""),0,IFERROR(INDEX(SPA_ЦІНИ,MATCH(INDEX(ДОВ_SPA,MATCH($A10,КАТЕГОРІЇ,0)),SPA_РОЛЬ,0),$U$3),0)) -> 400 | AE10: =IF(OR($A10="",W10=0,X10=0,AND($U$8=1,AB10=0),AND($U$9=1,AD10=0)),0,1) -> 1 | AF10: =IF(OR(AE10=0,Y10=0,AND($U$8=1,AC10=0)),0,1) -> 1
A11: =IF('Довідник категорій'!A7="","",'Довідник категорій'!A7) -> Котедж комфорт класу | B11: =IF($A11="","",IFERROR(INDEX(ДОВ_BOOKING,MATCH($A11,КАТЕГОРІЇ,0)),"")) -> Стандартна віла 96 м² | C11: =IF($A11="","",IFERROR(INDEX(ДОВ_ГРУПА,MATCH($A11,КАТЕГОРІЇ,0)),"")) -> Котеджі 3 спальні | D11: =IF(OR($AE11=0,D$8>$Z11),"",ROUND(((W11*X11+MAX(0,D$8-$AA11)*КРОК_ГОСТЯ)*(1-$U$5)+D$8*$AB11*(1-$U$5*$U$6)+$AD11*(1-$U$5*$U$7))/ОКРУГЛЕННЯ,0)*ОКРУГЛЕННЯ) -> 7380 | E11: =IF(OR($AE11=0,E$8>$Z11),"",ROUND(((W11*X11+MAX(0,E$8-$AA11)*КРОК_ГОСТЯ)*(1-$U$5)+E$8*$AB11*(1-$U$5*$U$6)+$AD11*(1-$U$5*$U$7))/ОКРУГЛЕННЯ,0)*ОКРУГЛЕННЯ) -> 7380 | F11: =IF(OR($AE11=0,F$8>$Z11),"",ROUND(((W11*X11+MAX(0,F$8-$AA11)*КРОК_ГОСТЯ)*(1-$U$5)+F$8*$AB11*(1-$U$5*$U$6)+$AD11*(1-$U$5*$U$7))/ОКРУГЛЕННЯ,0)*ОКРУГЛЕННЯ) -> 7880 | G11: =IF(OR($AE11=0,G$8>$Z11),"",ROUND(((W11*X11+MAX(0,G$8-$AA11)*КРОК_ГОСТЯ)*(1-$U$5)+G$8*$AB11*(1-$U$5*$U$6)+$AD11*(1-$U$5*$U$7))/ОКРУГЛЕННЯ,0)*ОКРУГЛЕННЯ) -> 8380 | H11: =IF(OR($AE11=0,H$8>$Z11),"",ROUND(((W11*X11+MAX(0,H$8-$AA11)*КРОК_ГОСТЯ)*(1-$U$5)+H$8*$AB11*(1-$U$5*$U$6)+$AD11*(1-$U$5*$U$7))/ОКРУГЛЕННЯ,0)*ОКРУГЛЕННЯ) -> 8880 | I11: =IF(OR($AE11=0,I$8>$Z11),"",ROUND(((W11*X11+MAX(0,I$8-$AA11)*КРОК_ГОСТЯ)*(1-$U$5)+I$8*$AB11*(1-$U$5*$U$6)+$AD11*(1-$U$5*$U$7))/ОКРУГЛЕННЯ,0)*ОКРУГЛЕННЯ) -> 9380 | J11: =IF(OR($AE11=0,J$8>$Z11),"",ROUND(((W11*X11+MAX(0,J$8-$AA11)*КРОК_ГОСТЯ)*(1-$U$5)+J$8*$AB11*(1-$U$5*$U$6)+$AD11*(1-$U$5*$U$7))/ОКРУГЛЕННЯ,0)*ОКРУГЛЕННЯ) | K11: =IF(OR($AE11=0,K$8>$Z11),"",ROUND(((W11*X11+MAX(0,K$8-$AA11)*КРОК_ГОСТЯ)*(1-$U$5)+K$8*$AB11*(1-$U$5*$U$6)+$AD11*(1-$U$5*$U$7))/ОКРУГЛЕННЯ,0)*ОКРУГЛЕННЯ) | L11: =IF(OR($AF11=0,L$8>$Z11),"",ROUND(((W11*X11*Y11+MAX(0,L$8-$AA11)*КРОК_ГОСТЯ)*(1-$U$5)+L$8*$AC11*(1-$U$5*$U$6)+$AD11*(1-$U$5*$U$7))/ОКРУГЛЕННЯ,0)*ОКРУГЛЕННЯ) -> 8038 | M11: =IF(OR($AF11=0,M$8>$Z11),"",ROUND(((W11*X11*Y11+MAX(0,M$8-$AA11)*КРОК_ГОСТЯ)*(1-$U$5)+M$8*$AC11*(1-$U$5*$U$6)+$AD11*(1-$U$5*$U$7))/ОКРУГЛЕННЯ,0)*ОКРУГЛЕННЯ) -> 8038 | N11: =IF(OR($AF11=0,N$8>$Z11),"",ROUND(((W11*X11*Y11+MAX(0,N$8-$AA11)*КРОК_ГОСТЯ)*(1-$U$5)+N$8*$AC11*(1-$U$5*$U$6)+$AD11*(1-$U$5*$U$7))/ОКРУГЛЕННЯ,0)*ОКРУГЛЕННЯ) -> 8538 | O11: =IF(OR($AF11=0,O$8>$Z11),"",ROUND(((W11*X11*Y11+MAX(0,O$8-$AA11)*КРОК_ГОСТЯ)*(1-$U$5)+O$8*$AC11*(1-$U$5*$U$6)+$AD11*(1-$U$5*$U$7))/ОКРУГЛЕННЯ,0)*ОКРУГЛЕННЯ) -> 9038 | P11: =IF(OR($AF11=0,P$8>$Z11),"",ROUND(((W11*X11*Y11+MAX(0,P$8-$AA11)*КРОК_ГОСТЯ)*(1-$U$5)+P$8*$AC11*(1-$U$5*$U$6)+$AD11*(1-$U$5*$U$7))/ОКРУГЛЕННЯ,0)*ОКРУГЛЕННЯ) -> 9538 | Q11: =IF(OR($AF11=0,Q$8>$Z11),"",ROUND(((W11*X11*Y11+MAX(0,Q$8-$AA11)*КРОК_ГОСТЯ)*(1-$U$5)+Q$8*$AC11*(1-$U$5*$U$6)+$AD11*(1-$U$5*$U$7))/ОКРУГЛЕННЯ,0)*ОКРУГЛЕННЯ) -> 10038 | R11: =IF(OR($AF11=0,R$8>$Z11),"",ROUND(((W11*X11*Y11+MAX(0,R$8-$AA11)*КРОК_ГОСТЯ)*(1-$U$5)+R$8*$AC11*(1-$U$5*$U$6)+$AD11*(1-$U$5*$U$7))/ОКРУГЛЕННЯ,0)*ОКРУГЛЕННЯ) | S11: =IF(OR($AF11=0,S$8>$Z11),"",ROUND(((W11*X11*Y11+MAX(0,S$8-$AA11)*КРОК_ГОСТЯ)*(1-$U$5)+S$8*$AC11*(1-$U$5*$U$6)+$AD11*(1-$U$5*$U$7))/ОКРУГЛЕННЯ,0)*ОКРУГЛЕННЯ) | U11: =IF($U$12=0,"період не заданий",IFERROR(IF(OR(INDEX(ПЛ_ДАТА_З,$U$12)="",INDEX(ПЛ_ДАТА_ПО,$U$12)=""),"період не заданий",TEXT(DAY(INDEX(ПЛ_ДАТА_З,$U$12)),"00")&"."&TEXT(MONTH(INDEX(ПЛ_ДАТА_З,$U$12)),"00")&"."&YEAR(INDEX(ПЛ_ДАТА_З,$U$12))&" – "&TEXT(DAY(INDEX(ПЛ_ДАТА_ПО,$U$12)),"00")&"."&TEXT(MONTH(INDEX(ПЛ_ДАТА_ПО,$U$12)),"00")&"."&YEAR(INDEX(ПЛ_ДАТА_ПО,$U$12))),"період не заданий")) -> 01.10.2026 – 30.11.2026 | V11: період (текст) | W11: =IF(OR($U$3=0,$A11=""),0,IFERROR(INDEX(БАЗА_RO,MATCH(INDEX(ДОВ_ОПОРА,MATCH($A11,КАТЕГОРІЇ,0)),БАЗА_КАТ,0),$U$3),0)) -> 6580 | X11: =IF(OR($U$3=0,$A11=""),0,IFERROR(INDEX(МНОЖНИКИ,MATCH($A11,МНОЖ_КАТ,0),$U$3),0)) -> 1 | Y11: =IF(OR($U$3=0,$A11=""),0,IFERROR(INDEX(МНОЖНИКИ,MATCH($A11,МНОЖ_КАТ,0),$U$3+1),0)) -> 1.1 | Z11: =IF($A11="",0,IFERROR(INDEX(ДОВ_МАКС,MATCH($A11,КАТЕГОРІЇ,0)),0)) -> 6 | AA11: =IF($A11="",0,IFERROR(INDEX(ДОВ_ВКЛ,MATCH($A11,КАТЕГОРІЇ,0)),0)) -> 2 | AB11: =IF(OR($U$3=0,$U$8=0),0,IFERROR(INDEX(ПАКЕТИ_ЦІНИ,MATCH($U$10&"|Будні",ПАКЕТИ_КЛЮЧ,0),$U$3),0)) -> 0 | AC11: =IF(OR($U$3=0,$U$8=0),0,IFERROR(INDEX(ПАКЕТИ_ЦІНИ,MATCH($U$10&"|Вихідні",ПАКЕТИ_КЛЮЧ,0),$U$3),0)) -> 0 | AD11: =IF(OR($U$3=0,$U$9=0,$A11=""),0,IFERROR(INDEX(SPA_ЦІНИ,MATCH(INDEX(ДОВ_SPA,MATCH($A11,КАТЕГОРІЇ,0)),SPA_РОЛЬ,0),$U$3),0)) -> 800 | AE11: =IF(OR($A11="",W11=0,X11=0,AND($U$8=1,AB11=0),AND($U$9=1,AD11=0)),0,1) -> 1 | AF11: =IF(OR(AE11=0,Y11=0,AND($U$8=1,AC11=0)),0,1) -> 1
A12: =IF('Довідник категорій'!A8="","",'Довідник категорій'!A8) -> Шале преміум | B12: =IF($A12="","",IFERROR(INDEX(ДОВ_BOOKING,MATCH($A12,КАТЕГОРІЇ,0)),"")) -> Віла з 3 спальнями 96 м² | C12: =IF($A12="","",IFERROR(INDEX(ДОВ_ГРУПА,MATCH($A12,КАТЕГОРІЇ,0)),"")) -> Котеджі 3 спальні | D12: =IF(OR($AE12=0,D$8>$Z12),"",ROUND(((W12*X12+MAX(0,D$8-$AA12)*КРОК_ГОСТЯ)*(1-$U$5)+D$8*$AB12*(1-$U$5*$U$6)+$AD12*(1-$U$5*$U$7))/ОКРУГЛЕННЯ,0)*ОКРУГЛЕННЯ) -> 7709 | E12: =IF(OR($AE12=0,E$8>$Z12),"",ROUND(((W12*X12+MAX(0,E$8-$AA12)*КРОК_ГОСТЯ)*(1-$U$5)+E$8*$AB12*(1-$U$5*$U$6)+$AD12*(1-$U$5*$U$7))/ОКРУГЛЕННЯ,0)*ОКРУГЛЕННЯ) -> 7709 | F12: =IF(OR($AE12=0,F$8>$Z12),"",ROUND(((W12*X12+MAX(0,F$8-$AA12)*КРОК_ГОСТЯ)*(1-$U$5)+F$8*$AB12*(1-$U$5*$U$6)+$AD12*(1-$U$5*$U$7))/ОКРУГЛЕННЯ,0)*ОКРУГЛЕННЯ) -> 8209 | G12: =IF(OR($AE12=0,G$8>$Z12),"",ROUND(((W12*X12+MAX(0,G$8-$AA12)*КРОК_ГОСТЯ)*(1-$U$5)+G$8*$AB12*(1-$U$5*$U$6)+$AD12*(1-$U$5*$U$7))/ОКРУГЛЕННЯ,0)*ОКРУГЛЕННЯ) -> 8709 | H12: =IF(OR($AE12=0,H$8>$Z12),"",ROUND(((W12*X12+MAX(0,H$8-$AA12)*КРОК_ГОСТЯ)*(1-$U$5)+H$8*$AB12*(1-$U$5*$U$6)+$AD12*(1-$U$5*$U$7))/ОКРУГЛЕННЯ,0)*ОКРУГЛЕННЯ) -> 9209 | I12: =IF(OR($AE12=0,I$8>$Z12),"",ROUND(((W12*X12+MAX(0,I$8-$AA12)*КРОК_ГОСТЯ)*(1-$U$5)+I$8*$AB12*(1-$U$5*$U$6)+$AD12*(1-$U$5*$U$7))/ОКРУГЛЕННЯ,0)*ОКРУГЛЕННЯ) -> 9709 | J12: =IF(OR($AE12=0,J$8>$Z12),"",ROUND(((W12*X12+MAX(0,J$8-$AA12)*КРОК_ГОСТЯ)*(1-$U$5)+J$8*$AB12*(1-$U$5*$U$6)+$AD12*(1-$U$5*$U$7))/ОКРУГЛЕННЯ,0)*ОКРУГЛЕННЯ) | K12: =IF(OR($AE12=0,K$8>$Z12),"",ROUND(((W12*X12+MAX(0,K$8-$AA12)*КРОК_ГОСТЯ)*(1-$U$5)+K$8*$AB12*(1-$U$5*$U$6)+$AD12*(1-$U$5*$U$7))/ОКРУГЛЕННЯ,0)*ОКРУГЛЕННЯ) | L12: =IF(OR($AF12=0,L$8>$Z12),"",ROUND(((W12*X12*Y12+MAX(0,L$8-$AA12)*КРОК_ГОСТЯ)*(1-$U$5)+L$8*$AC12*(1-$U$5*$U$6)+$AD12*(1-$U$5*$U$7))/ОКРУГЛЕННЯ,0)*ОКРУГЛЕННЯ) -> 8262 | M12: =IF(OR($AF12=0,M$8>$Z12),"",ROUND(((W12*X12*Y12+MAX(0,M$8-$AA12)*КРОК_ГОСТЯ)*(1-$U$5)+M$8*$AC12*(1-$U$5*$U$6)+$AD12*(1-$U$5*$U$7))/ОКРУГЛЕННЯ,0)*ОКРУГЛЕННЯ) -> 8262 | N12: =IF(OR($AF12=0,N$8>$Z12),"",ROUND(((W12*X12*Y12+MAX(0,N$8-$AA12)*КРОК_ГОСТЯ)*(1-$U$5)+N$8*$AC12*(1-$U$5*$U$6)+$AD12*(1-$U$5*$U$7))/ОКРУГЛЕННЯ,0)*ОКРУГЛЕННЯ) -> 8762 | O12: =IF(OR($AF12=0,O$8>$Z12),"",ROUND(((W12*X12*Y12+MAX(0,O$8-$AA12)*КРОК_ГОСТЯ)*(1-$U$5)+O$8*$AC12*(1-$U$5*$U$6)+$AD12*(1-$U$5*$U$7))/ОКРУГЛЕННЯ,0)*ОКРУГЛЕННЯ) -> 9262 | P12: =IF(OR($AF12=0,P$8>$Z12),"",ROUND(((W12*X12*Y12+MAX(0,P$8-$AA12)*КРОК_ГОСТЯ)*(1-$U$5)+P$8*$AC12*(1-$U$5*$U$6)+$AD12*(1-$U$5*$U$7))/ОКРУГЛЕННЯ,0)*ОКРУГЛЕННЯ) -> 9762 | Q12: =IF(OR($AF12=0,Q$8>$Z12),"",ROUND(((W12*X12*Y12+MAX(0,Q$8-$AA12)*КРОК_ГОСТЯ)*(1-$U$5)+Q$8*$AC12*(1-$U$5*$U$6)+$AD12*(1-$U$5*$U$7))/ОКРУГЛЕННЯ,0)*ОКРУГЛЕННЯ) -> 10262 | R12: =IF(OR($AF12=0,R$8>$Z12),"",ROUND(((W12*X12*Y12+MAX(0,R$8-$AA12)*КРОК_ГОСТЯ)*(1-$U$5)+R$8*$AC12*(1-$U$5*$U$6)+$AD12*(1-$U$5*$U$7))/ОКРУГЛЕННЯ,0)*ОКРУГЛЕННЯ) | S12: =IF(OR($AF12=0,S$8>$Z12),"",ROUND(((W12*X12*Y12+MAX(0,S$8-$AA12)*КРОК_ГОСТЯ)*(1-$U$5)+S$8*$AC12*(1-$U$5*$U$6)+$AD12*(1-$U$5*$U$7))/ОКРУГЛЕННЯ,0)*ОКРУГЛЕННЯ) | U12: =IFERROR(MATCH($B$3,ПРАЙС_ЛИСТИ,0),0) -> 3 | V12: рядок прайс-листа | W12: =IF(OR($U$3=0,$A12=""),0,IFERROR(INDEX(БАЗА_RO,MATCH(INDEX(ДОВ_ОПОРА,MATCH($A12,КАТЕГОРІЇ,0)),БАЗА_КАТ,0),$U$3),0)) -> 6580 | X12: =IF(OR($U$3=0,$A12=""),0,IFERROR(INDEX(МНОЖНИКИ,MATCH($A12,МНОЖ_КАТ,0),$U$3),0)) -> 1.05 | Y12: =IF(OR($U$3=0,$A12=""),0,IFERROR(INDEX(МНОЖНИКИ,MATCH($A12,МНОЖ_КАТ,0),$U$3+1),0)) -> 1.08 | Z12: =IF($A12="",0,IFERROR(INDEX(ДОВ_МАКС,MATCH($A12,КАТЕГОРІЇ,0)),0)) -> 6 | AA12: =IF($A12="",0,IFERROR(INDEX(ДОВ_ВКЛ,MATCH($A12,КАТЕГОРІЇ,0)),0)) -> 2 | AB12: =IF(OR($U$3=0,$U$8=0),0,IFERROR(INDEX(ПАКЕТИ_ЦІНИ,MATCH($U$10&"|Будні",ПАКЕТИ_КЛЮЧ,0),$U$3),0)) -> 0 | AC12: =IF(OR($U$3=0,$U$8=0),0,IFERROR(INDEX(ПАКЕТИ_ЦІНИ,MATCH($U$10&"|Вихідні",ПАКЕТИ_КЛЮЧ,0),$U$3),0)) -> 0 | AD12: =IF(OR($U$3=0,$U$9=0,$A12=""),0,IFERROR(INDEX(SPA_ЦІНИ,MATCH(INDEX(ДОВ_SPA,MATCH($A12,КАТЕГОРІЇ,0)),SPA_РОЛЬ,0),$U$3),0)) -> 800 | AE12: =IF(OR($A12="",W12=0,X12=0,AND($U$8=1,AB12=0),AND($U$9=1,AD12=0)),0,1) -> 1 | AF12: =IF(OR(AE12=0,Y12=0,AND($U$8=1,AC12=0)),0,1) -> 1
A13: =IF('Довідник категорій'!A9="","",'Довідник категорій'!A9) -> Шале преміум збільшене | B13: =IF($A13="","",IFERROR(INDEX(ДОВ_BOOKING,MATCH($A13,КАТЕГОРІЇ,0)),"")) -> Шале з 3 спальнями 112 м² | C13: =IF($A13="","",IFERROR(INDEX(ДОВ_ГРУПА,MATCH($A13,КАТЕГОРІЇ,0)),"")) -> Котеджі 3 спальні | D13: =IF(OR($AE13=0,D$8>$Z13),"",ROUND(((W13*X13+MAX(0,D$8-$AA13)*КРОК_ГОСТЯ)*(1-$U$5)+D$8*$AB13*(1-$U$5*$U$6)+$AD13*(1-$U$5*$U$7))/ОКРУГЛЕННЯ,0)*ОКРУГЛЕННЯ) -> 8038 | E13: =IF(OR($AE13=0,E$8>$Z13),"",ROUND(((W13*X13+MAX(0,E$8-$AA13)*КРОК_ГОСТЯ)*(1-$U$5)+E$8*$AB13*(1-$U$5*$U$6)+$AD13*(1-$U$5*$U$7))/ОКРУГЛЕННЯ,0)*ОКРУГЛЕННЯ) -> 8038 | F13: =IF(OR($AE13=0,F$8>$Z13),"",ROUND(((W13*X13+MAX(0,F$8-$AA13)*КРОК_ГОСТЯ)*(1-$U$5)+F$8*$AB13*(1-$U$5*$U$6)+$AD13*(1-$U$5*$U$7))/ОКРУГЛЕННЯ,0)*ОКРУГЛЕННЯ) -> 8538 | G13: =IF(OR($AE13=0,G$8>$Z13),"",ROUND(((W13*X13+MAX(0,G$8-$AA13)*КРОК_ГОСТЯ)*(1-$U$5)+G$8*$AB13*(1-$U$5*$U$6)+$AD13*(1-$U$5*$U$7))/ОКРУГЛЕННЯ,0)*ОКРУГЛЕННЯ) -> 9038 | H13: =IF(OR($AE13=0,H$8>$Z13),"",ROUND(((W13*X13+MAX(0,H$8-$AA13)*КРОК_ГОСТЯ)*(1-$U$5)+H$8*$AB13*(1-$U$5*$U$6)+$AD13*(1-$U$5*$U$7))/ОКРУГЛЕННЯ,0)*ОКРУГЛЕННЯ) -> 9538 | I13: =IF(OR($AE13=0,I$8>$Z13),"",ROUND(((W13*X13+MAX(0,I$8-$AA13)*КРОК_ГОСТЯ)*(1-$U$5)+I$8*$AB13*(1-$U$5*$U$6)+$AD13*(1-$U$5*$U$7))/ОКРУГЛЕННЯ,0)*ОКРУГЛЕННЯ) -> 10038 | J13: =IF(OR($AE13=0,J$8>$Z13),"",ROUND(((W13*X13+MAX(0,J$8-$AA13)*КРОК_ГОСТЯ)*(1-$U$5)+J$8*$AB13*(1-$U$5*$U$6)+$AD13*(1-$U$5*$U$7))/ОКРУГЛЕННЯ,0)*ОКРУГЛЕННЯ) | K13: =IF(OR($AE13=0,K$8>$Z13),"",ROUND(((W13*X13+MAX(0,K$8-$AA13)*КРОК_ГОСТЯ)*(1-$U$5)+K$8*$AB13*(1-$U$5*$U$6)+$AD13*(1-$U$5*$U$7))/ОКРУГЛЕННЯ,0)*ОКРУГЛЕННЯ) | L13: =IF(OR($AF13=0,L$8>$Z13),"",ROUND(((W13*X13*Y13+MAX(0,L$8-$AA13)*КРОК_ГОСТЯ)*(1-$U$5)+L$8*$AC13*(1-$U$5*$U$6)+$AD13*(1-$U$5*$U$7))/ОКРУГЛЕННЯ,0)*ОКРУГЛЕННЯ) -> 8545 | M13: =IF(OR($AF13=0,M$8>$Z13),"",ROUND(((W13*X13*Y13+MAX(0,M$8-$AA13)*КРОК_ГОСТЯ)*(1-$U$5)+M$8*$AC13*(1-$U$5*$U$6)+$AD13*(1-$U$5*$U$7))/ОКРУГЛЕННЯ,0)*ОКРУГЛЕННЯ) -> 8545 | N13: =IF(OR($AF13=0,N$8>$Z13),"",ROUND(((W13*X13*Y13+MAX(0,N$8-$AA13)*КРОК_ГОСТЯ)*(1-$U$5)+N$8*$AC13*(1-$U$5*$U$6)+$AD13*(1-$U$5*$U$7))/ОКРУГЛЕННЯ,0)*ОКРУГЛЕННЯ) -> 9045 | O13: =IF(OR($AF13=0,O$8>$Z13),"",ROUND(((W13*X13*Y13+MAX(0,O$8-$AA13)*КРОК_ГОСТЯ)*(1-$U$5)+O$8*$AC13*(1-$U$5*$U$6)+$AD13*(1-$U$5*$U$7))/ОКРУГЛЕННЯ,0)*ОКРУГЛЕННЯ) -> 9545 | P13: =IF(OR($AF13=0,P$8>$Z13),"",ROUND(((W13*X13*Y13+MAX(0,P$8-$AA13)*КРОК_ГОСТЯ)*(1-$U$5)+P$8*$AC13*(1-$U$5*$U$6)+$AD13*(1-$U$5*$U$7))/ОКРУГЛЕННЯ,0)*ОКРУГЛЕННЯ) -> 10045 | Q13: =IF(OR($AF13=0,Q$8>$Z13),"",ROUND(((W13*X13*Y13+MAX(0,Q$8-$AA13)*КРОК_ГОСТЯ)*(1-$U$5)+Q$8*$AC13*(1-$U$5*$U$6)+$AD13*(1-$U$5*$U$7))/ОКРУГЛЕННЯ,0)*ОКРУГЛЕННЯ) -> 10545 | R13: =IF(OR($AF13=0,R$8>$Z13),"",ROUND(((W13*X13*Y13+MAX(0,R$8-$AA13)*КРОК_ГОСТЯ)*(1-$U$5)+R$8*$AC13*(1-$U$5*$U$6)+$AD13*(1-$U$5*$U$7))/ОКРУГЛЕННЯ,0)*ОКРУГЛЕННЯ) | S13: =IF(OR($AF13=0,S$8>$Z13),"",ROUND(((W13*X13*Y13+MAX(0,S$8-$AA13)*КРОК_ГОСТЯ)*(1-$U$5)+S$8*$AC13*(1-$U$5*$U$6)+$AD13*(1-$U$5*$U$7))/ОКРУГЛЕННЯ,0)*ОКРУГЛЕННЯ) | U13: =IF($U$3=0,0,COUNT(INDEX(БАЗА_RO,1,$U$3),INDEX(БАЗА_RO,2,$U$3),INDEX(БАЗА_RO,3,$U$3),INDEX(БАЗА_RO,4,$U$3))) -> 4 | V13: заповнених баз RO | W13: =IF(OR($U$3=0,$A13=""),0,IFERROR(INDEX(БАЗА_RO,MATCH(INDEX(ДОВ_ОПОРА,MATCH($A13,КАТЕГОРІЇ,0)),БАЗА_КАТ,0),$U$3),0)) -> 6580 | X13: =IF(OR($U$3=0,$A13=""),0,IFERROR(INDEX(МНОЖНИКИ,MATCH($A13,МНОЖ_КАТ,0),$U$3),0)) -> 1.1 | Y13: =IF(OR($U$3=0,$A13=""),0,IFERROR(INDEX(МНОЖНИКИ,MATCH($A13,МНОЖ_КАТ,0),$U$3+1),0)) -> 1.07 | Z13: =IF($A13="",0,IFERROR(INDEX(ДОВ_МАКС,MATCH($A13,КАТЕГОРІЇ,0)),0)) -> 6 | AA13: =IF($A13="",0,IFERROR(INDEX(ДОВ_ВКЛ,MATCH($A13,КАТЕГОРІЇ,0)),0)) -> 2 | AB13: =IF(OR($U$3=0,$U$8=0),0,IFERROR(INDEX(ПАКЕТИ_ЦІНИ,MATCH($U$10&"|Будні",ПАКЕТИ_КЛЮЧ,0),$U$3),0)) -> 0 | AC13: =IF(OR($U$3=0,$U$8=0),0,IFERROR(INDEX(ПАКЕТИ_ЦІНИ,MATCH($U$10&"|Вихідні",ПАКЕТИ_КЛЮЧ,0),$U$3),0)) -> 0 | AD13: =IF(OR($U$3=0,$U$9=0,$A13=""),0,IFERROR(INDEX(SPA_ЦІНИ,MATCH(INDEX(ДОВ_SPA,MATCH($A13,КАТЕГОРІЇ,0)),SPA_РОЛЬ,0),$U$3),0)) -> 800 | AE13: =IF(OR($A13="",W13=0,X13=0,AND($U$8=1,AB13=0),AND($U$9=1,AD13=0)),0,1) -> 1 | AF13: =IF(OR(AE13=0,Y13=0,AND($U$8=1,AC13=0)),0,1) -> 1
A14: =IF('Довідник категорій'!A10="","",'Довідник категорій'!A10) -> Шале преміум збільшене East Hill | B14: =IF($A14="","",IFERROR(INDEX(ДОВ_BOOKING,MATCH($A14,КАТЕГОРІЇ,0)),"")) -> Шале з 3 спальнями 112 м² | C14: =IF($A14="","",IFERROR(INDEX(ДОВ_ГРУПА,MATCH($A14,КАТЕГОРІЇ,0)),"")) -> Котеджі 3 спальні | D14: =IF(OR($AE14=0,D$8>$Z14),"",ROUND(((W14*X14+MAX(0,D$8-$AA14)*КРОК_ГОСТЯ)*(1-$U$5)+D$8*$AB14*(1-$U$5*$U$6)+$AD14*(1-$U$5*$U$7))/ОКРУГЛЕННЯ,0)*ОКРУГЛЕННЯ) -> 8367 | E14: =IF(OR($AE14=0,E$8>$Z14),"",ROUND(((W14*X14+MAX(0,E$8-$AA14)*КРОК_ГОСТЯ)*(1-$U$5)+E$8*$AB14*(1-$U$5*$U$6)+$AD14*(1-$U$5*$U$7))/ОКРУГЛЕННЯ,0)*ОКРУГЛЕННЯ) -> 8367 | F14: =IF(OR($AE14=0,F$8>$Z14),"",ROUND(((W14*X14+MAX(0,F$8-$AA14)*КРОК_ГОСТЯ)*(1-$U$5)+F$8*$AB14*(1-$U$5*$U$6)+$AD14*(1-$U$5*$U$7))/ОКРУГЛЕННЯ,0)*ОКРУГЛЕННЯ) -> 8867 | G14: =IF(OR($AE14=0,G$8>$Z14),"",ROUND(((W14*X14+MAX(0,G$8-$AA14)*КРОК_ГОСТЯ)*(1-$U$5)+G$8*$AB14*(1-$U$5*$U$6)+$AD14*(1-$U$5*$U$7))/ОКРУГЛЕННЯ,0)*ОКРУГЛЕННЯ) -> 9367 | H14: =IF(OR($AE14=0,H$8>$Z14),"",ROUND(((W14*X14+MAX(0,H$8-$AA14)*КРОК_ГОСТЯ)*(1-$U$5)+H$8*$AB14*(1-$U$5*$U$6)+$AD14*(1-$U$5*$U$7))/ОКРУГЛЕННЯ,0)*ОКРУГЛЕННЯ) -> 9867 | I14: =IF(OR($AE14=0,I$8>$Z14),"",ROUND(((W14*X14+MAX(0,I$8-$AA14)*КРОК_ГОСТЯ)*(1-$U$5)+I$8*$AB14*(1-$U$5*$U$6)+$AD14*(1-$U$5*$U$7))/ОКРУГЛЕННЯ,0)*ОКРУГЛЕННЯ) -> 10367 | J14: =IF(OR($AE14=0,J$8>$Z14),"",ROUND(((W14*X14+MAX(0,J$8-$AA14)*КРОК_ГОСТЯ)*(1-$U$5)+J$8*$AB14*(1-$U$5*$U$6)+$AD14*(1-$U$5*$U$7))/ОКРУГЛЕННЯ,0)*ОКРУГЛЕННЯ) | K14: =IF(OR($AE14=0,K$8>$Z14),"",ROUND(((W14*X14+MAX(0,K$8-$AA14)*КРОК_ГОСТЯ)*(1-$U$5)+K$8*$AB14*(1-$U$5*$U$6)+$AD14*(1-$U$5*$U$7))/ОКРУГЛЕННЯ,0)*ОКРУГЛЕННЯ) | L14: =IF(OR($AF14=0,L$8>$Z14),"",ROUND(((W14*X14*Y14+MAX(0,L$8-$AA14)*КРОК_ГОСТЯ)*(1-$U$5)+L$8*$AC14*(1-$U$5*$U$6)+$AD14*(1-$U$5*$U$7))/ОКРУГЛЕННЯ,0)*ОКРУГЛЕННЯ) -> 8821 | M14: =IF(OR($AF14=0,M$8>$Z14),"",ROUND(((W14*X14*Y14+MAX(0,M$8-$AA14)*КРОК_ГОСТЯ)*(1-$U$5)+M$8*$AC14*(1-$U$5*$U$6)+$AD14*(1-$U$5*$U$7))/ОКРУГЛЕННЯ,0)*ОКРУГЛЕННЯ) -> 8821 | N14: =IF(OR($AF14=0,N$8>$Z14),"",ROUND(((W14*X14*Y14+MAX(0,N$8-$AA14)*КРОК_ГОСТЯ)*(1-$U$5)+N$8*$AC14*(1-$U$5*$U$6)+$AD14*(1-$U$5*$U$7))/ОКРУГЛЕННЯ,0)*ОКРУГЛЕННЯ) -> 9321 | O14: =IF(OR($AF14=0,O$8>$Z14),"",ROUND(((W14*X14*Y14+MAX(0,O$8-$AA14)*КРОК_ГОСТЯ)*(1-$U$5)+O$8*$AC14*(1-$U$5*$U$6)+$AD14*(1-$U$5*$U$7))/ОКРУГЛЕННЯ,0)*ОКРУГЛЕННЯ) -> 9821 | P14: =IF(OR($AF14=0,P$8>$Z14),"",ROUND(((W14*X14*Y14+MAX(0,P$8-$AA14)*КРОК_ГОСТЯ)*(1-$U$5)+P$8*$AC14*(1-$U$5*$U$6)+$AD14*(1-$U$5*$U$7))/ОКРУГЛЕННЯ,0)*ОКРУГЛЕННЯ) -> 10321 | Q14: =IF(OR($AF14=0,Q$8>$Z14),"",ROUND(((W14*X14*Y14+MAX(0,Q$8-$AA14)*КРОК_ГОСТЯ)*(1-$U$5)+Q$8*$AC14*(1-$U$5*$U$6)+$AD14*(1-$U$5*$U$7))/ОКРУГЛЕННЯ,0)*ОКРУГЛЕННЯ) -> 10821 | R14: =IF(OR($AF14=0,R$8>$Z14),"",ROUND(((W14*X14*Y14+MAX(0,R$8-$AA14)*КРОК_ГОСТЯ)*(1-$U$5)+R$8*$AC14*(1-$U$5*$U$6)+$AD14*(1-$U$5*$U$7))/ОКРУГЛЕННЯ,0)*ОКРУГЛЕННЯ) | S14: =IF(OR($AF14=0,S$8>$Z14),"",ROUND(((W14*X14*Y14+MAX(0,S$8-$AA14)*КРОК_ГОСТЯ)*(1-$U$5)+S$8*$AC14*(1-$U$5*$U$6)+$AD14*(1-$U$5*$U$7))/ОКРУГЛЕННЯ,0)*ОКРУГЛЕННЯ) | W14: =IF(OR($U$3=0,$A14=""),0,IFERROR(INDEX(БАЗА_RO,MATCH(INDEX(ДОВ_ОПОРА,MATCH($A14,КАТЕГОРІЇ,0)),БАЗА_КАТ,0),$U$3),0)) -> 6580 | X14: =IF(OR($U$3=0,$A14=""),0,IFERROR(INDEX(МНОЖНИКИ,MATCH($A14,МНОЖ_КАТ,0),$U$3),0)) -> 1.15 | Y14: =IF(OR($U$3=0,$A14=""),0,IFERROR(INDEX(МНОЖНИКИ,MATCH($A14,МНОЖ_КАТ,0),$U$3+1),0)) -> 1.06 | Z14: =IF($A14="",0,IFERROR(INDEX(ДОВ_МАКС,MATCH($A14,КАТЕГОРІЇ,0)),0)) -> 6 | AA14: =IF($A14="",0,IFERROR(INDEX(ДОВ_ВКЛ,MATCH($A14,КАТЕГОРІЇ,0)),0)) -> 2 | AB14: =IF(OR($U$3=0,$U$8=0),0,IFERROR(INDEX(ПАКЕТИ_ЦІНИ,MATCH($U$10&"|Будні",ПАКЕТИ_КЛЮЧ,0),$U$3),0)) -> 0 | AC14: =IF(OR($U$3=0,$U$8=0),0,IFERROR(INDEX(ПАКЕТИ_ЦІНИ,MATCH($U$10&"|Вихідні",ПАКЕТИ_КЛЮЧ,0),$U$3),0)) -> 0 | AD14: =IF(OR($U$3=0,$U$9=0,$A14=""),0,IFERROR(INDEX(SPA_ЦІНИ,MATCH(INDEX(ДОВ_SPA,MATCH($A14,КАТЕГОРІЇ,0)),SPA_РОЛЬ,0),$U$3),0)) -> 800 | AE14: =IF(OR($A14="",W14=0,X14=0,AND($U$8=1,AB14=0),AND($U$9=1,AD14=0)),0,1) -> 1 | AF14: =IF(OR(AE14=0,Y14=0,AND($U$8=1,AC14=0)),0,1) -> 1
A15: =IF('Довідник категорій'!A11="","",'Довідник категорій'!A11) -> Президентське шале | B15: =IF($A15="","",IFERROR(INDEX(ДОВ_BOOKING,MATCH($A15,КАТЕГОРІЇ,0)),"")) -> Шале Люкс | C15: =IF($A15="","",IFERROR(INDEX(ДОВ_ГРУПА,MATCH($A15,КАТЕГОРІЇ,0)),"")) -> Котеджі 3 спальні | D15: =IF(OR($AE15=0,D$8>$Z15),"",ROUND(((W15*X15+MAX(0,D$8-$AA15)*КРОК_ГОСТЯ)*(1-$U$5)+D$8*$AB15*(1-$U$5*$U$6)+$AD15*(1-$U$5*$U$7))/ОКРУГЛЕННЯ,0)*ОКРУГЛЕННЯ) -> 10670 | E15: =IF(OR($AE15=0,E$8>$Z15),"",ROUND(((W15*X15+MAX(0,E$8-$AA15)*КРОК_ГОСТЯ)*(1-$U$5)+E$8*$AB15*(1-$U$5*$U$6)+$AD15*(1-$U$5*$U$7))/ОКРУГЛЕННЯ,0)*ОКРУГЛЕННЯ) -> 10670 | F15: =IF(OR($AE15=0,F$8>$Z15),"",ROUND(((W15*X15+MAX(0,F$8-$AA15)*КРОК_ГОСТЯ)*(1-$U$5)+F$8*$AB15*(1-$U$5*$U$6)+$AD15*(1-$U$5*$U$7))/ОКРУГЛЕННЯ,0)*ОКРУГЛЕННЯ) -> 11170 | G15: =IF(OR($AE15=0,G$8>$Z15),"",ROUND(((W15*X15+MAX(0,G$8-$AA15)*КРОК_ГОСТЯ)*(1-$U$5)+G$8*$AB15*(1-$U$5*$U$6)+$AD15*(1-$U$5*$U$7))/ОКРУГЛЕННЯ,0)*ОКРУГЛЕННЯ) -> 11670 | H15: =IF(OR($AE15=0,H$8>$Z15),"",ROUND(((W15*X15+MAX(0,H$8-$AA15)*КРОК_ГОСТЯ)*(1-$U$5)+H$8*$AB15*(1-$U$5*$U$6)+$AD15*(1-$U$5*$U$7))/ОКРУГЛЕННЯ,0)*ОКРУГЛЕННЯ) -> 12170 | I15: =IF(OR($AE15=0,I$8>$Z15),"",ROUND(((W15*X15+MAX(0,I$8-$AA15)*КРОК_ГОСТЯ)*(1-$U$5)+I$8*$AB15*(1-$U$5*$U$6)+$AD15*(1-$U$5*$U$7))/ОКРУГЛЕННЯ,0)*ОКРУГЛЕННЯ) -> 12670 | J15: =IF(OR($AE15=0,J$8>$Z15),"",ROUND(((W15*X15+MAX(0,J$8-$AA15)*КРОК_ГОСТЯ)*(1-$U$5)+J$8*$AB15*(1-$U$5*$U$6)+$AD15*(1-$U$5*$U$7))/ОКРУГЛЕННЯ,0)*ОКРУГЛЕННЯ) -> 13170 | K15: =IF(OR($AE15=0,K$8>$Z15),"",ROUND(((W15*X15+MAX(0,K$8-$AA15)*КРОК_ГОСТЯ)*(1-$U$5)+K$8*$AB15*(1-$U$5*$U$6)+$AD15*(1-$U$5*$U$7))/ОКРУГЛЕННЯ,0)*ОКРУГЛЕННЯ) -> 13670 | L15: =IF(OR($AF15=0,L$8>$Z15),"",ROUND(((W15*X15*Y15+MAX(0,L$8-$AA15)*КРОК_ГОСТЯ)*(1-$U$5)+L$8*$AC15*(1-$U$5*$U$6)+$AD15*(1-$U$5*$U$7))/ОКРУГЛЕННЯ,0)*ОКРУГЛЕННЯ) -> 11065 | M15: =IF(OR($AF15=0,M$8>$Z15),"",ROUND(((W15*X15*Y15+MAX(0,M$8-$AA15)*КРОК_ГОСТЯ)*(1-$U$5)+M$8*$AC15*(1-$U$5*$U$6)+$AD15*(1-$U$5*$U$7))/ОКРУГЛЕННЯ,0)*ОКРУГЛЕННЯ) -> 11065 | N15: =IF(OR($AF15=0,N$8>$Z15),"",ROUND(((W15*X15*Y15+MAX(0,N$8-$AA15)*КРОК_ГОСТЯ)*(1-$U$5)+N$8*$AC15*(1-$U$5*$U$6)+$AD15*(1-$U$5*$U$7))/ОКРУГЛЕННЯ,0)*ОКРУГЛЕННЯ) -> 11565 | O15: =IF(OR($AF15=0,O$8>$Z15),"",ROUND(((W15*X15*Y15+MAX(0,O$8-$AA15)*КРОК_ГОСТЯ)*(1-$U$5)+O$8*$AC15*(1-$U$5*$U$6)+$AD15*(1-$U$5*$U$7))/ОКРУГЛЕННЯ,0)*ОКРУГЛЕННЯ) -> 12065 | P15: =IF(OR($AF15=0,P$8>$Z15),"",ROUND(((W15*X15*Y15+MAX(0,P$8-$AA15)*КРОК_ГОСТЯ)*(1-$U$5)+P$8*$AC15*(1-$U$5*$U$6)+$AD15*(1-$U$5*$U$7))/ОКРУГЛЕННЯ,0)*ОКРУГЛЕННЯ) -> 12565 | Q15: =IF(OR($AF15=0,Q$8>$Z15),"",ROUND(((W15*X15*Y15+MAX(0,Q$8-$AA15)*КРОК_ГОСТЯ)*(1-$U$5)+Q$8*$AC15*(1-$U$5*$U$6)+$AD15*(1-$U$5*$U$7))/ОКРУГЛЕННЯ,0)*ОКРУГЛЕННЯ) -> 13065 | R15: =IF(OR($AF15=0,R$8>$Z15),"",ROUND(((W15*X15*Y15+MAX(0,R$8-$AA15)*КРОК_ГОСТЯ)*(1-$U$5)+R$8*$AC15*(1-$U$5*$U$6)+$AD15*(1-$U$5*$U$7))/ОКРУГЛЕННЯ,0)*ОКРУГЛЕННЯ) -> 13565 | S15: =IF(OR($AF15=0,S$8>$Z15),"",ROUND(((W15*X15*Y15+MAX(0,S$8-$AA15)*КРОК_ГОСТЯ)*(1-$U$5)+S$8*$AC15*(1-$U$5*$U$6)+$AD15*(1-$U$5*$U$7))/ОКРУГЛЕННЯ,0)*ОКРУГЛЕННЯ) -> 14065 | W15: =IF(OR($U$3=0,$A15=""),0,IFERROR(INDEX(БАЗА_RO,MATCH(INDEX(ДОВ_ОПОРА,MATCH($A15,КАТЕГОРІЇ,0)),БАЗА_КАТ,0),$U$3),0)) -> 6580 | X15: =IF(OR($U$3=0,$A15=""),0,IFERROR(INDEX(МНОЖНИКИ,MATCH($A15,МНОЖ_КАТ,0),$U$3),0)) -> 1.5 | Y15: =IF(OR($U$3=0,$A15=""),0,IFERROR(INDEX(МНОЖНИКИ,MATCH($A15,МНОЖ_КАТ,0),$U$3+1),0)) -> 1.04 | Z15: =IF($A15="",0,IFERROR(INDEX(ДОВ_МАКС,MATCH($A15,КАТЕГОРІЇ,0)),0)) -> 8 | AA15: =IF($A15="",0,IFERROR(INDEX(ДОВ_ВКЛ,MATCH($A15,КАТЕГОРІЇ,0)),0)) -> 2 | AB15: =IF(OR($U$3=0,$U$8=0),0,IFERROR(INDEX(ПАКЕТИ_ЦІНИ,MATCH($U$10&"|Будні",ПАКЕТИ_КЛЮЧ,0),$U$3),0)) -> 0 | AC15: =IF(OR($U$3=0,$U$8=0),0,IFERROR(INDEX(ПАКЕТИ_ЦІНИ,MATCH($U$10&"|Вихідні",ПАКЕТИ_КЛЮЧ,0),$U$3),0)) -> 0 | AD15: =IF(OR($U$3=0,$U$9=0,$A15=""),0,IFERROR(INDEX(SPA_ЦІНИ,MATCH(INDEX(ДОВ_SPA,MATCH($A15,КАТЕГОРІЇ,0)),SPA_РОЛЬ,0),$U$3),0)) -> 800 | AE15: =IF(OR($A15="",W15=0,X15=0,AND($U$8=1,AB15=0),AND($U$9=1,AD15=0)),0,1) -> 1 | AF15: =IF(OR(AE15=0,Y15=0,AND($U$8=1,AC15=0)),0,1) -> 1
A16: =IF('Довідник категорій'!A12="","",'Довідник категорій'!A12) -> Апартаменти стандартні 20 м² | B16: =IF($A16="","",IFERROR(INDEX(ДОВ_BOOKING,MATCH($A16,КАТЕГОРІЇ,0)),"")) -> Апартаменти стандартні 20 м² | C16: =IF($A16="","",IFERROR(INDEX(ДОВ_ГРУПА,MATCH($A16,КАТЕГОРІЇ,0)),"")) -> Apartments A | D16: =IF(OR($AE16=0,D$8>$Z16),"",ROUND(((W16*X16+MAX(0,D$8-$AA16)*КРОК_ГОСТЯ)*(1-$U$5)+D$8*$AB16*(1-$U$5*$U$6)+$AD16*(1-$U$5*$U$7))/ОКРУГЛЕННЯ,0)*ОКРУГЛЕННЯ) -> 2770 | E16: =IF(OR($AE16=0,E$8>$Z16),"",ROUND(((W16*X16+MAX(0,E$8-$AA16)*КРОК_ГОСТЯ)*(1-$U$5)+E$8*$AB16*(1-$U$5*$U$6)+$AD16*(1-$U$5*$U$7))/ОКРУГЛЕННЯ,0)*ОКРУГЛЕННЯ) -> 2770 | F16: =IF(OR($AE16=0,F$8>$Z16),"",ROUND(((W16*X16+MAX(0,F$8-$AA16)*КРОК_ГОСТЯ)*(1-$U$5)+F$8*$AB16*(1-$U$5*$U$6)+$AD16*(1-$U$5*$U$7))/ОКРУГЛЕННЯ,0)*ОКРУГЛЕННЯ) | G16: =IF(OR($AE16=0,G$8>$Z16),"",ROUND(((W16*X16+MAX(0,G$8-$AA16)*КРОК_ГОСТЯ)*(1-$U$5)+G$8*$AB16*(1-$U$5*$U$6)+$AD16*(1-$U$5*$U$7))/ОКРУГЛЕННЯ,0)*ОКРУГЛЕННЯ) | H16: =IF(OR($AE16=0,H$8>$Z16),"",ROUND(((W16*X16+MAX(0,H$8-$AA16)*КРОК_ГОСТЯ)*(1-$U$5)+H$8*$AB16*(1-$U$5*$U$6)+$AD16*(1-$U$5*$U$7))/ОКРУГЛЕННЯ,0)*ОКРУГЛЕННЯ) | I16: =IF(OR($AE16=0,I$8>$Z16),"",ROUND(((W16*X16+MAX(0,I$8-$AA16)*КРОК_ГОСТЯ)*(1-$U$5)+I$8*$AB16*(1-$U$5*$U$6)+$AD16*(1-$U$5*$U$7))/ОКРУГЛЕННЯ,0)*ОКРУГЛЕННЯ) | J16: =IF(OR($AE16=0,J$8>$Z16),"",ROUND(((W16*X16+MAX(0,J$8-$AA16)*КРОК_ГОСТЯ)*(1-$U$5)+J$8*$AB16*(1-$U$5*$U$6)+$AD16*(1-$U$5*$U$7))/ОКРУГЛЕННЯ,0)*ОКРУГЛЕННЯ) | K16: =IF(OR($AE16=0,K$8>$Z16),"",ROUND(((W16*X16+MAX(0,K$8-$AA16)*КРОК_ГОСТЯ)*(1-$U$5)+K$8*$AB16*(1-$U$5*$U$6)+$AD16*(1-$U$5*$U$7))/ОКРУГЛЕННЯ,0)*ОКРУГЛЕННЯ) | L16: =IF(OR($AF16=0,L$8>$Z16),"",ROUND(((W16*X16*Y16+MAX(0,L$8-$AA16)*КРОК_ГОСТЯ)*(1-$U$5)+L$8*$AC16*(1-$U$5*$U$6)+$AD16*(1-$U$5*$U$7))/ОКРУГЛЕННЯ,0)*ОКРУГЛЕННЯ) -> 3007 | M16: =IF(OR($AF16=0,M$8>$Z16),"",ROUND(((W16*X16*Y16+MAX(0,M$8-$AA16)*КРОК_ГОСТЯ)*(1-$U$5)+M$8*$AC16*(1-$U$5*$U$6)+$AD16*(1-$U$5*$U$7))/ОКРУГЛЕННЯ,0)*ОКРУГЛЕННЯ) -> 3007 | N16: =IF(OR($AF16=0,N$8>$Z16),"",ROUND(((W16*X16*Y16+MAX(0,N$8-$AA16)*КРОК_ГОСТЯ)*(1-$U$5)+N$8*$AC16*(1-$U$5*$U$6)+$AD16*(1-$U$5*$U$7))/ОКРУГЛЕННЯ,0)*ОКРУГЛЕННЯ) | O16: =IF(OR($AF16=0,O$8>$Z16),"",ROUND(((W16*X16*Y16+MAX(0,O$8-$AA16)*КРОК_ГОСТЯ)*(1-$U$5)+O$8*$AC16*(1-$U$5*$U$6)+$AD16*(1-$U$5*$U$7))/ОКРУГЛЕННЯ,0)*ОКРУГЛЕННЯ) | P16: =IF(OR($AF16=0,P$8>$Z16),"",ROUND(((W16*X16*Y16+MAX(0,P$8-$AA16)*КРОК_ГОСТЯ)*(1-$U$5)+P$8*$AC16*(1-$U$5*$U$6)+$AD16*(1-$U$5*$U$7))/ОКРУГЛЕННЯ,0)*ОКРУГЛЕННЯ) | Q16: =IF(OR($AF16=0,Q$8>$Z16),"",ROUND(((W16*X16*Y16+MAX(0,Q$8-$AA16)*КРОК_ГОСТЯ)*(1-$U$5)+Q$8*$AC16*(1-$U$5*$U$6)+$AD16*(1-$U$5*$U$7))/ОКРУГЛЕННЯ,0)*ОКРУГЛЕННЯ) | R16: =IF(OR($AF16=0,R$8>$Z16),"",ROUND(((W16*X16*Y16+MAX(0,R$8-$AA16)*КРОК_ГОСТЯ)*(1-$U$5)+R$8*$AC16*(1-$U$5*$U$6)+$AD16*(1-$U$5*$U$7))/ОКРУГЛЕННЯ,0)*ОКРУГЛЕННЯ) | S16: =IF(OR($AF16=0,S$8>$Z16),"",ROUND(((W16*X16*Y16+MAX(0,S$8-$AA16)*КРОК_ГОСТЯ)*(1-$U$5)+S$8*$AC16*(1-$U$5*$U$6)+$AD16*(1-$U$5*$U$7))/ОКРУГЛЕННЯ,0)*ОКРУГЛЕННЯ) | W16: =IF(OR($U$3=0,$A16=""),0,IFERROR(INDEX(БАЗА_RO,MATCH(INDEX(ДОВ_ОПОРА,MATCH($A16,КАТЕГОРІЇ,0)),БАЗА_КАТ,0),$U$3),0)) -> 2370 | X16: =IF(OR($U$3=0,$A16=""),0,IFERROR(INDEX(МНОЖНИКИ,MATCH($A16,МНОЖ_КАТ,0),$U$3),0)) -> 1 | Y16: =IF(OR($U$3=0,$A16=""),0,IFERROR(INDEX(МНОЖНИКИ,MATCH($A16,МНОЖ_КАТ,0),$U$3+1),0)) -> 1.1 | Z16: =IF($A16="",0,IFERROR(INDEX(ДОВ_МАКС,MATCH($A16,КАТЕГОРІЇ,0)),0)) -> 2 | AA16: =IF($A16="",0,IFERROR(INDEX(ДОВ_ВКЛ,MATCH($A16,КАТЕГОРІЇ,0)),0)) -> 2 | AB16: =IF(OR($U$3=0,$U$8=0),0,IFERROR(INDEX(ПАКЕТИ_ЦІНИ,MATCH($U$10&"|Будні",ПАКЕТИ_КЛЮЧ,0),$U$3),0)) -> 0 | AC16: =IF(OR($U$3=0,$U$8=0),0,IFERROR(INDEX(ПАКЕТИ_ЦІНИ,MATCH($U$10&"|Вихідні",ПАКЕТИ_КЛЮЧ,0),$U$3),0)) -> 0 | AD16: =IF(OR($U$3=0,$U$9=0,$A16=""),0,IFERROR(INDEX(SPA_ЦІНИ,MATCH(INDEX(ДОВ_SPA,MATCH($A16,КАТЕГОРІЇ,0)),SPA_РОЛЬ,0),$U$3),0)) -> 400 | AE16: =IF(OR($A16="",W16=0,X16=0,AND($U$8=1,AB16=0),AND($U$9=1,AD16=0)),0,1) -> 1 | AF16: =IF(OR(AE16=0,Y16=0,AND($U$8=1,AC16=0)),0,1) -> 1
A17: =IF('Довідник категорій'!A13="","",'Довідник категорій'!A13) -> Апартаменти покращені 28 м² | B17: =IF($A17="","",IFERROR(INDEX(ДОВ_BOOKING,MATCH($A17,КАТЕГОРІЇ,0)),"")) -> Апартаменти покращені 28 м² | C17: =IF($A17="","",IFERROR(INDEX(ДОВ_ГРУПА,MATCH($A17,КАТЕГОРІЇ,0)),"")) -> Apartments A | D17: =IF(OR($AE17=0,D$8>$Z17),"",ROUND(((W17*X17+MAX(0,D$8-$AA17)*КРОК_ГОСТЯ)*(1-$U$5)+D$8*$AB17*(1-$U$5*$U$6)+$AD17*(1-$U$5*$U$7))/ОКРУГЛЕННЯ,0)*ОКРУГЛЕННЯ) -> 3126 | E17: =IF(OR($AE17=0,E$8>$Z17),"",ROUND(((W17*X17+MAX(0,E$8-$AA17)*КРОК_ГОСТЯ)*(1-$U$5)+E$8*$AB17*(1-$U$5*$U$6)+$AD17*(1-$U$5*$U$7))/ОКРУГЛЕННЯ,0)*ОКРУГЛЕННЯ) -> 3126 | F17: =IF(OR($AE17=0,F$8>$Z17),"",ROUND(((W17*X17+MAX(0,F$8-$AA17)*КРОК_ГОСТЯ)*(1-$U$5)+F$8*$AB17*(1-$U$5*$U$6)+$AD17*(1-$U$5*$U$7))/ОКРУГЛЕННЯ,0)*ОКРУГЛЕННЯ) | G17: =IF(OR($AE17=0,G$8>$Z17),"",ROUND(((W17*X17+MAX(0,G$8-$AA17)*КРОК_ГОСТЯ)*(1-$U$5)+G$8*$AB17*(1-$U$5*$U$6)+$AD17*(1-$U$5*$U$7))/ОКРУГЛЕННЯ,0)*ОКРУГЛЕННЯ) | H17: =IF(OR($AE17=0,H$8>$Z17),"",ROUND(((W17*X17+MAX(0,H$8-$AA17)*КРОК_ГОСТЯ)*(1-$U$5)+H$8*$AB17*(1-$U$5*$U$6)+$AD17*(1-$U$5*$U$7))/ОКРУГЛЕННЯ,0)*ОКРУГЛЕННЯ) | I17: =IF(OR($AE17=0,I$8>$Z17),"",ROUND(((W17*X17+MAX(0,I$8-$AA17)*КРОК_ГОСТЯ)*(1-$U$5)+I$8*$AB17*(1-$U$5*$U$6)+$AD17*(1-$U$5*$U$7))/ОКРУГЛЕННЯ,0)*ОКРУГЛЕННЯ) | J17: =IF(OR($AE17=0,J$8>$Z17),"",ROUND(((W17*X17+MAX(0,J$8-$AA17)*КРОК_ГОСТЯ)*(1-$U$5)+J$8*$AB17*(1-$U$5*$U$6)+$AD17*(1-$U$5*$U$7))/ОКРУГЛЕННЯ,0)*ОКРУГЛЕННЯ) | K17: =IF(OR($AE17=0,K$8>$Z17),"",ROUND(((W17*X17+MAX(0,K$8-$AA17)*КРОК_ГОСТЯ)*(1-$U$5)+K$8*$AB17*(1-$U$5*$U$6)+$AD17*(1-$U$5*$U$7))/ОКРУГЛЕННЯ,0)*ОКРУГЛЕННЯ) | L17: =IF(OR($AF17=0,L$8>$Z17),"",ROUND(((W17*X17*Y17+MAX(0,L$8-$AA17)*КРОК_ГОСТЯ)*(1-$U$5)+L$8*$AC17*(1-$U$5*$U$6)+$AD17*(1-$U$5*$U$7))/ОКРУГЛЕННЯ,0)*ОКРУГЛЕННЯ) -> 3398 | M17: =IF(OR($AF17=0,M$8>$Z17),"",ROUND(((W17*X17*Y17+MAX(0,M$8-$AA17)*КРОК_ГОСТЯ)*(1-$U$5)+M$8*$AC17*(1-$U$5*$U$6)+$AD17*(1-$U$5*$U$7))/ОКРУГЛЕННЯ,0)*ОКРУГЛЕННЯ) -> 3398 | N17: =IF(OR($AF17=0,N$8>$Z17),"",ROUND(((W17*X17*Y17+MAX(0,N$8-$AA17)*КРОК_ГОСТЯ)*(1-$U$5)+N$8*$AC17*(1-$U$5*$U$6)+$AD17*(1-$U$5*$U$7))/ОКРУГЛЕННЯ,0)*ОКРУГЛЕННЯ) | O17: =IF(OR($AF17=0,O$8>$Z17),"",ROUND(((W17*X17*Y17+MAX(0,O$8-$AA17)*КРОК_ГОСТЯ)*(1-$U$5)+O$8*$AC17*(1-$U$5*$U$6)+$AD17*(1-$U$5*$U$7))/ОКРУГЛЕННЯ,0)*ОКРУГЛЕННЯ) | P17: =IF(OR($AF17=0,P$8>$Z17),"",ROUND(((W17*X17*Y17+MAX(0,P$8-$AA17)*КРОК_ГОСТЯ)*(1-$U$5)+P$8*$AC17*(1-$U$5*$U$6)+$AD17*(1-$U$5*$U$7))/ОКРУГЛЕННЯ,0)*ОКРУГЛЕННЯ) | Q17: =IF(OR($AF17=0,Q$8>$Z17),"",ROUND(((W17*X17*Y17+MAX(0,Q$8-$AA17)*КРОК_ГОСТЯ)*(1-$U$5)+Q$8*$AC17*(1-$U$5*$U$6)+$AD17*(1-$U$5*$U$7))/ОКРУГЛЕННЯ,0)*ОКРУГЛЕННЯ) | R17: =IF(OR($AF17=0,R$8>$Z17),"",ROUND(((W17*X17*Y17+MAX(0,R$8-$AA17)*КРОК_ГОСТЯ)*(1-$U$5)+R$8*$AC17*(1-$U$5*$U$6)+$AD17*(1-$U$5*$U$7))/ОКРУГЛЕННЯ,0)*ОКРУГЛЕННЯ) | S17: =IF(OR($AF17=0,S$8>$Z17),"",ROUND(((W17*X17*Y17+MAX(0,S$8-$AA17)*КРОК_ГОСТЯ)*(1-$U$5)+S$8*$AC17*(1-$U$5*$U$6)+$AD17*(1-$U$5*$U$7))/ОКРУГЛЕННЯ,0)*ОКРУГЛЕННЯ) | W17: =IF(OR($U$3=0,$A17=""),0,IFERROR(INDEX(БАЗА_RO,MATCH(INDEX(ДОВ_ОПОРА,MATCH($A17,КАТЕГОРІЇ,0)),БАЗА_КАТ,0),$U$3),0)) -> 2370 | X17: =IF(OR($U$3=0,$A17=""),0,IFERROR(INDEX(МНОЖНИКИ,MATCH($A17,МНОЖ_КАТ,0),$U$3),0)) -> 1.15 | Y17: =IF(OR($U$3=0,$A17=""),0,IFERROR(INDEX(МНОЖНИКИ,MATCH($A17,МНОЖ_КАТ,0),$U$3+1),0)) -> 1.1 | Z17: =IF($A17="",0,IFERROR(INDEX(ДОВ_МАКС,MATCH($A17,КАТЕГОРІЇ,0)),0)) -> 2 | AA17: =IF($A17="",0,IFERROR(INDEX(ДОВ_ВКЛ,MATCH($A17,КАТЕГОРІЇ,0)),0)) -> 2 | AB17: =IF(OR($U$3=0,$U$8=0),0,IFERROR(INDEX(ПАКЕТИ_ЦІНИ,MATCH($U$10&"|Будні",ПАКЕТИ_КЛЮЧ,0),$U$3),0)) -> 0 | AC17: =IF(OR($U$3=0,$U$8=0),0,IFERROR(INDEX(ПАКЕТИ_ЦІНИ,MATCH($U$10&"|Вихідні",ПАКЕТИ_КЛЮЧ,0),$U$3),0)) -> 0 | AD17: =IF(OR($U$3=0,$U$9=0,$A17=""),0,IFERROR(INDEX(SPA_ЦІНИ,MATCH(INDEX(ДОВ_SPA,MATCH($A17,КАТЕГОРІЇ,0)),SPA_РОЛЬ,0),$U$3),0)) -> 400 | AE17: =IF(OR($A17="",W17=0,X17=0,AND($U$8=1,AB17=0),AND($U$9=1,AD17=0)),0,1) -> 1 | AF17: =IF(OR(AE17=0,Y17=0,AND($U$8=1,AC17=0)),0,1) -> 1
A18: =IF('Довідник категорій'!A14="","",'Довідник категорій'!A14) -> Апартаменти Люкс 25 м² | B18: =IF($A18="","",IFERROR(INDEX(ДОВ_BOOKING,MATCH($A18,КАТЕГОРІЇ,0)),"")) -> Апартаменти Люкс 25 м² | C18: =IF($A18="","",IFERROR(INDEX(ДОВ_ГРУПА,MATCH($A18,КАТЕГОРІЇ,0)),"")) -> Apartments A | D18: =IF(OR($AE18=0,D$8>$Z18),"",ROUND(((W18*X18+MAX(0,D$8-$AA18)*КРОК_ГОСТЯ)*(1-$U$5)+D$8*$AB18*(1-$U$5*$U$6)+$AD18*(1-$U$5*$U$7))/ОКРУГЛЕННЯ,0)*ОКРУГЛЕННЯ) -> 3600 | E18: =IF(OR($AE18=0,E$8>$Z18),"",ROUND(((W18*X18+MAX(0,E$8-$AA18)*КРОК_ГОСТЯ)*(1-$U$5)+E$8*$AB18*(1-$U$5*$U$6)+$AD18*(1-$U$5*$U$7))/ОКРУГЛЕННЯ,0)*ОКРУГЛЕННЯ) -> 3600 | F18: =IF(OR($AE18=0,F$8>$Z18),"",ROUND(((W18*X18+MAX(0,F$8-$AA18)*КРОК_ГОСТЯ)*(1-$U$5)+F$8*$AB18*(1-$U$5*$U$6)+$AD18*(1-$U$5*$U$7))/ОКРУГЛЕННЯ,0)*ОКРУГЛЕННЯ) | G18: =IF(OR($AE18=0,G$8>$Z18),"",ROUND(((W18*X18+MAX(0,G$8-$AA18)*КРОК_ГОСТЯ)*(1-$U$5)+G$8*$AB18*(1-$U$5*$U$6)+$AD18*(1-$U$5*$U$7))/ОКРУГЛЕННЯ,0)*ОКРУГЛЕННЯ) | H18: =IF(OR($AE18=0,H$8>$Z18),"",ROUND(((W18*X18+MAX(0,H$8-$AA18)*КРОК_ГОСТЯ)*(1-$U$5)+H$8*$AB18*(1-$U$5*$U$6)+$AD18*(1-$U$5*$U$7))/ОКРУГЛЕННЯ,0)*ОКРУГЛЕННЯ) | I18: =IF(OR($AE18=0,I$8>$Z18),"",ROUND(((W18*X18+MAX(0,I$8-$AA18)*КРОК_ГОСТЯ)*(1-$U$5)+I$8*$AB18*(1-$U$5*$U$6)+$AD18*(1-$U$5*$U$7))/ОКРУГЛЕННЯ,0)*ОКРУГЛЕННЯ) | J18: =IF(OR($AE18=0,J$8>$Z18),"",ROUND(((W18*X18+MAX(0,J$8-$AA18)*КРОК_ГОСТЯ)*(1-$U$5)+J$8*$AB18*(1-$U$5*$U$6)+$AD18*(1-$U$5*$U$7))/ОКРУГЛЕННЯ,0)*ОКРУГЛЕННЯ) | K18: =IF(OR($AE18=0,K$8>$Z18),"",ROUND(((W18*X18+MAX(0,K$8-$AA18)*КРОК_ГОСТЯ)*(1-$U$5)+K$8*$AB18*(1-$U$5*$U$6)+$AD18*(1-$U$5*$U$7))/ОКРУГЛЕННЯ,0)*ОКРУГЛЕННЯ) | L18: =IF(OR($AF18=0,L$8>$Z18),"",ROUND(((W18*X18*Y18+MAX(0,L$8-$AA18)*КРОК_ГОСТЯ)*(1-$U$5)+L$8*$AC18*(1-$U$5*$U$6)+$AD18*(1-$U$5*$U$7))/ОКРУГЛЕННЯ,0)*ОКРУГЛЕННЯ) -> 3823 | M18: =IF(OR($AF18=0,M$8>$Z18),"",ROUND(((W18*X18*Y18+MAX(0,M$8-$AA18)*КРОК_ГОСТЯ)*(1-$U$5)+M$8*$AC18*(1-$U$5*$U$6)+$AD18*(1-$U$5*$U$7))/ОКРУГЛЕННЯ,0)*ОКРУГЛЕННЯ) -> 3823 | N18: =IF(OR($AF18=0,N$8>$Z18),"",ROUND(((W18*X18*Y18+MAX(0,N$8-$AA18)*КРОК_ГОСТЯ)*(1-$U$5)+N$8*$AC18*(1-$U$5*$U$6)+$AD18*(1-$U$5*$U$7))/ОКРУГЛЕННЯ,0)*ОКРУГЛЕННЯ) | O18: =IF(OR($AF18=0,O$8>$Z18),"",ROUND(((W18*X18*Y18+MAX(0,O$8-$AA18)*КРОК_ГОСТЯ)*(1-$U$5)+O$8*$AC18*(1-$U$5*$U$6)+$AD18*(1-$U$5*$U$7))/ОКРУГЛЕННЯ,0)*ОКРУГЛЕННЯ) | P18: =IF(OR($AF18=0,P$8>$Z18),"",ROUND(((W18*X18*Y18+MAX(0,P$8-$AA18)*КРОК_ГОСТЯ)*(1-$U$5)+P$8*$AC18*(1-$U$5*$U$6)+$AD18*(1-$U$5*$U$7))/ОКРУГЛЕННЯ,0)*ОКРУГЛЕННЯ) | Q18: =IF(OR($AF18=0,Q$8>$Z18),"",ROUND(((W18*X18*Y18+MAX(0,Q$8-$AA18)*КРОК_ГОСТЯ)*(1-$U$5)+Q$8*$AC18*(1-$U$5*$U$6)+$AD18*(1-$U$5*$U$7))/ОКРУГЛЕННЯ,0)*ОКРУГЛЕННЯ) | R18: =IF(OR($AF18=0,R$8>$Z18),"",ROUND(((W18*X18*Y18+MAX(0,R$8-$AA18)*КРОК_ГОСТЯ)*(1-$U$5)+R$8*$AC18*(1-$U$5*$U$6)+$AD18*(1-$U$5*$U$7))/ОКРУГЛЕННЯ,0)*ОКРУГЛЕННЯ) | S18: =IF(OR($AF18=0,S$8>$Z18),"",ROUND(((W18*X18*Y18+MAX(0,S$8-$AA18)*КРОК_ГОСТЯ)*(1-$U$5)+S$8*$AC18*(1-$U$5*$U$6)+$AD18*(1-$U$5*$U$7))/ОКРУГЛЕННЯ,0)*ОКРУГЛЕННЯ) | W18: =IF(OR($U$3=0,$A18=""),0,IFERROR(INDEX(БАЗА_RO,MATCH(INDEX(ДОВ_ОПОРА,MATCH($A18,КАТЕГОРІЇ,0)),БАЗА_КАТ,0),$U$3),0)) -> 2370 | X18: =IF(OR($U$3=0,$A18=""),0,IFERROR(INDEX(МНОЖНИКИ,MATCH($A18,МНОЖ_КАТ,0),$U$3),0)) -> 1.35 | Y18: =IF(OR($U$3=0,$A18=""),0,IFERROR(INDEX(МНОЖНИКИ,MATCH($A18,МНОЖ_КАТ,0),$U$3+1),0)) -> 1.07 | Z18: =IF($A18="",0,IFERROR(INDEX(ДОВ_МАКС,MATCH($A18,КАТЕГОРІЇ,0)),0)) -> 2 | AA18: =IF($A18="",0,IFERROR(INDEX(ДОВ_ВКЛ,MATCH($A18,КАТЕГОРІЇ,0)),0)) -> 2 | AB18: =IF(OR($U$3=0,$U$8=0),0,IFERROR(INDEX(ПАКЕТИ_ЦІНИ,MATCH($U$10&"|Будні",ПАКЕТИ_КЛЮЧ,0),$U$3),0)) -> 0 | AC18: =IF(OR($U$3=0,$U$8=0),0,IFERROR(INDEX(ПАКЕТИ_ЦІНИ,MATCH($U$10&"|Вихідні",ПАКЕТИ_КЛЮЧ,0),$U$3),0)) -> 0 | AD18: =IF(OR($U$3=0,$U$9=0,$A18=""),0,IFERROR(INDEX(SPA_ЦІНИ,MATCH(INDEX(ДОВ_SPA,MATCH($A18,КАТЕГОРІЇ,0)),SPA_РОЛЬ,0),$U$3),0)) -> 400 | AE18: =IF(OR($A18="",W18=0,X18=0,AND($U$8=1,AB18=0),AND($U$9=1,AD18=0)),0,1) -> 1 | AF18: =IF(OR(AE18=0,Y18=0,AND($U$8=1,AC18=0)),0,1) -> 1
A19: =IF('Довідник категорій'!A15="","",'Довідник категорій'!A15) -> Люкс зі спальнею та вітальнею | B19: =IF($A19="","",IFERROR(INDEX(ДОВ_BOOKING,MATCH($A19,КАТЕГОРІЇ,0)),"")) -> Стандартний двомісний люкс 52 м² | C19: =IF($A19="","",IFERROR(INDEX(ДОВ_ГРУПА,MATCH($A19,КАТЕГОРІЇ,0)),"")) -> Apartments A | D19: =IF(OR($AE19=0,D$8>$Z19),"",ROUND(((W19*X19+MAX(0,D$8-$AA19)*КРОК_ГОСТЯ)*(1-$U$5)+D$8*$AB19*(1-$U$5*$U$6)+$AD19*(1-$U$5*$U$7))/ОКРУГЛЕННЯ,0)*ОКРУГЛЕННЯ) -> 4192 | E19: =IF(OR($AE19=0,E$8>$Z19),"",ROUND(((W19*X19+MAX(0,E$8-$AA19)*КРОК_ГОСТЯ)*(1-$U$5)+E$8*$AB19*(1-$U$5*$U$6)+$AD19*(1-$U$5*$U$7))/ОКРУГЛЕННЯ,0)*ОКРУГЛЕННЯ) -> 4192 | F19: =IF(OR($AE19=0,F$8>$Z19),"",ROUND(((W19*X19+MAX(0,F$8-$AA19)*КРОК_ГОСТЯ)*(1-$U$5)+F$8*$AB19*(1-$U$5*$U$6)+$AD19*(1-$U$5*$U$7))/ОКРУГЛЕННЯ,0)*ОКРУГЛЕННЯ) -> 4692 | G19: =IF(OR($AE19=0,G$8>$Z19),"",ROUND(((W19*X19+MAX(0,G$8-$AA19)*КРОК_ГОСТЯ)*(1-$U$5)+G$8*$AB19*(1-$U$5*$U$6)+$AD19*(1-$U$5*$U$7))/ОКРУГЛЕННЯ,0)*ОКРУГЛЕННЯ) | H19: =IF(OR($AE19=0,H$8>$Z19),"",ROUND(((W19*X19+MAX(0,H$8-$AA19)*КРОК_ГОСТЯ)*(1-$U$5)+H$8*$AB19*(1-$U$5*$U$6)+$AD19*(1-$U$5*$U$7))/ОКРУГЛЕННЯ,0)*ОКРУГЛЕННЯ) | I19: =IF(OR($AE19=0,I$8>$Z19),"",ROUND(((W19*X19+MAX(0,I$8-$AA19)*КРОК_ГОСТЯ)*(1-$U$5)+I$8*$AB19*(1-$U$5*$U$6)+$AD19*(1-$U$5*$U$7))/ОКРУГЛЕННЯ,0)*ОКРУГЛЕННЯ) | J19: =IF(OR($AE19=0,J$8>$Z19),"",ROUND(((W19*X19+MAX(0,J$8-$AA19)*КРОК_ГОСТЯ)*(1-$U$5)+J$8*$AB19*(1-$U$5*$U$6)+$AD19*(1-$U$5*$U$7))/ОКРУГЛЕННЯ,0)*ОКРУГЛЕННЯ) | K19: =IF(OR($AE19=0,K$8>$Z19),"",ROUND(((W19*X19+MAX(0,K$8-$AA19)*КРОК_ГОСТЯ)*(1-$U$5)+K$8*$AB19*(1-$U$5*$U$6)+$AD19*(1-$U$5*$U$7))/ОКРУГЛЕННЯ,0)*ОКРУГЛЕННЯ) | L19: =IF(OR($AF19=0,L$8>$Z19),"",ROUND(((W19*X19*Y19+MAX(0,L$8-$AA19)*КРОК_ГОСТЯ)*(1-$U$5)+L$8*$AC19*(1-$U$5*$U$6)+$AD19*(1-$U$5*$U$7))/ОКРУГЛЕННЯ,0)*ОКРУГЛЕННЯ) -> 4439 | M19: =IF(OR($AF19=0,M$8>$Z19),"",ROUND(((W19*X19*Y19+MAX(0,M$8-$AA19)*КРОК_ГОСТЯ)*(1-$U$5)+M$8*$AC19*(1-$U$5*$U$6)+$AD19*(1-$U$5*$U$7))/ОКРУГЛЕННЯ,0)*ОКРУГЛЕННЯ) -> 4439 | N19: =IF(OR($AF19=0,N$8>$Z19),"",ROUND(((W19*X19*Y19+MAX(0,N$8-$AA19)*КРОК_ГОСТЯ)*(1-$U$5)+N$8*$AC19*(1-$U$5*$U$6)+$AD19*(1-$U$5*$U$7))/ОКРУГЛЕННЯ,0)*ОКРУГЛЕННЯ) -> 4939 | O19: =IF(OR($AF19=0,O$8>$Z19),"",ROUND(((W19*X19*Y19+MAX(0,O$8-$AA19)*КРОК_ГОСТЯ)*(1-$U$5)+O$8*$AC19*(1-$U$5*$U$6)+$AD19*(1-$U$5*$U$7))/ОКРУГЛЕННЯ,0)*ОКРУГЛЕННЯ) | P19: =IF(OR($AF19=0,P$8>$Z19),"",ROUND(((W19*X19*Y19+MAX(0,P$8-$AA19)*КРОК_ГОСТЯ)*(1-$U$5)+P$8*$AC19*(1-$U$5*$U$6)+$AD19*(1-$U$5*$U$7))/ОКРУГЛЕННЯ,0)*ОКРУГЛЕННЯ) | Q19: =IF(OR($AF19=0,Q$8>$Z19),"",ROUND(((W19*X19*Y19+MAX(0,Q$8-$AA19)*КРОК_ГОСТЯ)*(1-$U$5)+Q$8*$AC19*(1-$U$5*$U$6)+$AD19*(1-$U$5*$U$7))/ОКРУГЛЕННЯ,0)*ОКРУГЛЕННЯ) | R19: =IF(OR($AF19=0,R$8>$Z19),"",ROUND(((W19*X19*Y19+MAX(0,R$8-$AA19)*КРОК_ГОСТЯ)*(1-$U$5)+R$8*$AC19*(1-$U$5*$U$6)+$AD19*(1-$U$5*$U$7))/ОКРУГЛЕННЯ,0)*ОКРУГЛЕННЯ) | S19: =IF(OR($AF19=0,S$8>$Z19),"",ROUND(((W19*X19*Y19+MAX(0,S$8-$AA19)*КРОК_ГОСТЯ)*(1-$U$5)+S$8*$AC19*(1-$U$5*$U$6)+$AD19*(1-$U$5*$U$7))/ОКРУГЛЕННЯ,0)*ОКРУГЛЕННЯ) | W19: =IF(OR($U$3=0,$A19=""),0,IFERROR(INDEX(БАЗА_RO,MATCH(INDEX(ДОВ_ОПОРА,MATCH($A19,КАТЕГОРІЇ,0)),БАЗА_КАТ,0),$U$3),0)) -> 2370 | X19: =IF(OR($U$3=0,$A19=""),0,IFERROR(INDEX(МНОЖНИКИ,MATCH($A19,МНОЖ_КАТ,0),$U$3),0)) -> 1.6 | Y19: =IF(OR($U$3=0,$A19=""),0,IFERROR(INDEX(МНОЖНИКИ,MATCH($A19,МНОЖ_КАТ,0),$U$3+1),0)) -> 1.0652 | Z19: =IF($A19="",0,IFERROR(INDEX(ДОВ_МАКС,MATCH($A19,КАТЕГОРІЇ,0)),0)) -> 3 | AA19: =IF($A19="",0,IFERROR(INDEX(ДОВ_ВКЛ,MATCH($A19,КАТЕГОРІЇ,0)),0)) -> 2 | AB19: =IF(OR($U$3=0,$U$8=0),0,IFERROR(INDEX(ПАКЕТИ_ЦІНИ,MATCH($U$10&"|Будні",ПАКЕТИ_КЛЮЧ,0),$U$3),0)) -> 0 | AC19: =IF(OR($U$3=0,$U$8=0),0,IFERROR(INDEX(ПАКЕТИ_ЦІНИ,MATCH($U$10&"|Вихідні",ПАКЕТИ_КЛЮЧ,0),$U$3),0)) -> 0 | AD19: =IF(OR($U$3=0,$U$9=0,$A19=""),0,IFERROR(INDEX(SPA_ЦІНИ,MATCH(INDEX(ДОВ_SPA,MATCH($A19,КАТЕГОРІЇ,0)),SPA_РОЛЬ,0),$U$3),0)) -> 400 | AE19: =IF(OR($A19="",W19=0,X19=0,AND($U$8=1,AB19=0),AND($U$9=1,AD19=0)),0,1) -> 1 | AF19: =IF(OR(AE19=0,Y19=0,AND($U$8=1,AC19=0)),0,1) -> 1
A20: =IF('Довідник категорій'!A16="","",'Довідник категорій'!A16) -> Люкс з видом на гори (з 2-ма спальнями) 61 м² | B20: =IF($A20="","",IFERROR(INDEX(ДОВ_BOOKING,MATCH($A20,КАТЕГОРІЇ,0)),"")) -> Люкс з видом на гори (з 2-ма спальнями) 61 м² | C20: =IF($A20="","",IFERROR(INDEX(ДОВ_ГРУПА,MATCH($A20,КАТЕГОРІЇ,0)),"")) -> Apartments A | D20: =IF(OR($AE20=0,D$8>$Z20),"",ROUND(((W20*X20+MAX(0,D$8-$AA20)*КРОК_ГОСТЯ)*(1-$U$5)+D$8*$AB20*(1-$U$5*$U$6)+$AD20*(1-$U$5*$U$7))/ОКРУГЛЕННЯ,0)*ОКРУГЛЕННЯ) -> 4903 | E20: =IF(OR($AE20=0,E$8>$Z20),"",ROUND(((W20*X20+MAX(0,E$8-$AA20)*КРОК_ГОСТЯ)*(1-$U$5)+E$8*$AB20*(1-$U$5*$U$6)+$AD20*(1-$U$5*$U$7))/ОКРУГЛЕННЯ,0)*ОКРУГЛЕННЯ) -> 4903 | F20: =IF(OR($AE20=0,F$8>$Z20),"",ROUND(((W20*X20+MAX(0,F$8-$AA20)*КРОК_ГОСТЯ)*(1-$U$5)+F$8*$AB20*(1-$U$5*$U$6)+$AD20*(1-$U$5*$U$7))/ОКРУГЛЕННЯ,0)*ОКРУГЛЕННЯ) -> 5403 | G20: =IF(OR($AE20=0,G$8>$Z20),"",ROUND(((W20*X20+MAX(0,G$8-$AA20)*КРОК_ГОСТЯ)*(1-$U$5)+G$8*$AB20*(1-$U$5*$U$6)+$AD20*(1-$U$5*$U$7))/ОКРУГЛЕННЯ,0)*ОКРУГЛЕННЯ) -> 5903 | H20: =IF(OR($AE20=0,H$8>$Z20),"",ROUND(((W20*X20+MAX(0,H$8-$AA20)*КРОК_ГОСТЯ)*(1-$U$5)+H$8*$AB20*(1-$U$5*$U$6)+$AD20*(1-$U$5*$U$7))/ОКРУГЛЕННЯ,0)*ОКРУГЛЕННЯ) -> 6403 | I20: =IF(OR($AE20=0,I$8>$Z20),"",ROUND(((W20*X20+MAX(0,I$8-$AA20)*КРОК_ГОСТЯ)*(1-$U$5)+I$8*$AB20*(1-$U$5*$U$6)+$AD20*(1-$U$5*$U$7))/ОКРУГЛЕННЯ,0)*ОКРУГЛЕННЯ) | J20: =IF(OR($AE20=0,J$8>$Z20),"",ROUND(((W20*X20+MAX(0,J$8-$AA20)*КРОК_ГОСТЯ)*(1-$U$5)+J$8*$AB20*(1-$U$5*$U$6)+$AD20*(1-$U$5*$U$7))/ОКРУГЛЕННЯ,0)*ОКРУГЛЕННЯ) | K20: =IF(OR($AE20=0,K$8>$Z20),"",ROUND(((W20*X20+MAX(0,K$8-$AA20)*КРОК_ГОСТЯ)*(1-$U$5)+K$8*$AB20*(1-$U$5*$U$6)+$AD20*(1-$U$5*$U$7))/ОКРУГЛЕННЯ,0)*ОКРУГЛЕННЯ) | L20: =IF(OR($AF20=0,L$8>$Z20),"",ROUND(((W20*X20*Y20+MAX(0,L$8-$AA20)*КРОК_ГОСТЯ)*(1-$U$5)+L$8*$AC20*(1-$U$5*$U$6)+$AD20*(1-$U$5*$U$7))/ОКРУГЛЕННЯ,0)*ОКРУГЛЕННЯ) -> 5218 | M20: =IF(OR($AF20=0,M$8>$Z20),"",ROUND(((W20*X20*Y20+MAX(0,M$8-$AA20)*КРОК_ГОСТЯ)*(1-$U$5)+M$8*$AC20*(1-$U$5*$U$6)+$AD20*(1-$U$5*$U$7))/ОКРУГЛЕННЯ,0)*ОКРУГЛЕННЯ) -> 5218 | N20: =IF(OR($AF20=0,N$8>$Z20),"",ROUND(((W20*X20*Y20+MAX(0,N$8-$AA20)*КРОК_ГОСТЯ)*(1-$U$5)+N$8*$AC20*(1-$U$5*$U$6)+$AD20*(1-$U$5*$U$7))/ОКРУГЛЕННЯ,0)*ОКРУГЛЕННЯ) -> 5718 | O20: =IF(OR($AF20=0,O$8>$Z20),"",ROUND(((W20*X20*Y20+MAX(0,O$8-$AA20)*КРОК_ГОСТЯ)*(1-$U$5)+O$8*$AC20*(1-$U$5*$U$6)+$AD20*(1-$U$5*$U$7))/ОКРУГЛЕННЯ,0)*ОКРУГЛЕННЯ) -> 6218 | P20: =IF(OR($AF20=0,P$8>$Z20),"",ROUND(((W20*X20*Y20+MAX(0,P$8-$AA20)*КРОК_ГОСТЯ)*(1-$U$5)+P$8*$AC20*(1-$U$5*$U$6)+$AD20*(1-$U$5*$U$7))/ОКРУГЛЕННЯ,0)*ОКРУГЛЕННЯ) -> 6718 | Q20: =IF(OR($AF20=0,Q$8>$Z20),"",ROUND(((W20*X20*Y20+MAX(0,Q$8-$AA20)*КРОК_ГОСТЯ)*(1-$U$5)+Q$8*$AC20*(1-$U$5*$U$6)+$AD20*(1-$U$5*$U$7))/ОКРУГЛЕННЯ,0)*ОКРУГЛЕННЯ) | R20: =IF(OR($AF20=0,R$8>$Z20),"",ROUND(((W20*X20*Y20+MAX(0,R$8-$AA20)*КРОК_ГОСТЯ)*(1-$U$5)+R$8*$AC20*(1-$U$5*$U$6)+$AD20*(1-$U$5*$U$7))/ОКРУГЛЕННЯ,0)*ОКРУГЛЕННЯ) | S20: =IF(OR($AF20=0,S$8>$Z20),"",ROUND(((W20*X20*Y20+MAX(0,S$8-$AA20)*КРОК_ГОСТЯ)*(1-$U$5)+S$8*$AC20*(1-$U$5*$U$6)+$AD20*(1-$U$5*$U$7))/ОКРУГЛЕННЯ,0)*ОКРУГЛЕННЯ) | W20: =IF(OR($U$3=0,$A20=""),0,IFERROR(INDEX(БАЗА_RO,MATCH(INDEX(ДОВ_ОПОРА,MATCH($A20,КАТЕГОРІЇ,0)),БАЗА_КАТ,0),$U$3),0)) -> 2370 | X20: =IF(OR($U$3=0,$A20=""),0,IFERROR(INDEX(МНОЖНИКИ,MATCH($A20,МНОЖ_КАТ,0),$U$3),0)) -> 1.9 | Y20: =IF(OR($U$3=0,$A20=""),0,IFERROR(INDEX(МНОЖНИКИ,MATCH($A20,МНОЖ_КАТ,0),$U$3+1),0)) -> 1.07 | Z20: =IF($A20="",0,IFERROR(INDEX(ДОВ_МАКС,MATCH($A20,КАТЕГОРІЇ,0)),0)) -> 5 | AA20: =IF($A20="",0,IFERROR(INDEX(ДОВ_ВКЛ,MATCH($A20,КАТЕГОРІЇ,0)),0)) -> 2 | AB20: =IF(OR($U$3=0,$U$8=0),0,IFERROR(INDEX(ПАКЕТИ_ЦІНИ,MATCH($U$10&"|Будні",ПАКЕТИ_КЛЮЧ,0),$U$3),0)) -> 0 | AC20: =IF(OR($U$3=0,$U$8=0),0,IFERROR(INDEX(ПАКЕТИ_ЦІНИ,MATCH($U$10&"|Вихідні",ПАКЕТИ_КЛЮЧ,0),$U$3),0)) -> 0 | AD20: =IF(OR($U$3=0,$U$9=0,$A20=""),0,IFERROR(INDEX(SPA_ЦІНИ,MATCH(INDEX(ДОВ_SPA,MATCH($A20,КАТЕГОРІЇ,0)),SPA_РОЛЬ,0),$U$3),0)) -> 400 | AE20: =IF(OR($A20="",W20=0,X20=0,AND($U$8=1,AB20=0),AND($U$9=1,AD20=0)),0,1) -> 1 | AF20: =IF(OR(AE20=0,Y20=0,AND($U$8=1,AC20=0)),0,1) -> 1
A21: =IF('Довідник категорій'!A17="","",'Довідник категорій'!A17) -> Апартаменти 1-й поверх 45 м² | B21: =IF($A21="","",IFERROR(INDEX(ДОВ_BOOKING,MATCH($A21,КАТЕГОРІЇ,0)),"")) -> Апартаменти 1-й поверх 45 м² | C21: =IF($A21="","",IFERROR(INDEX(ДОВ_ГРУПА,MATCH($A21,КАТЕГОРІЇ,0)),"")) -> Apartments B | D21: =IF(OR($AE21=0,D$8>$Z21),"",ROUND(((W21*X21+MAX(0,D$8-$AA21)*КРОК_ГОСТЯ)*(1-$U$5)+D$8*$AB21*(1-$U$5*$U$6)+$AD21*(1-$U$5*$U$7))/ОКРУГЛЕННЯ,0)*ОКРУГЛЕННЯ) -> 3330 | E21: =IF(OR($AE21=0,E$8>$Z21),"",ROUND(((W21*X21+MAX(0,E$8-$AA21)*КРОК_ГОСТЯ)*(1-$U$5)+E$8*$AB21*(1-$U$5*$U$6)+$AD21*(1-$U$5*$U$7))/ОКРУГЛЕННЯ,0)*ОКРУГЛЕННЯ) -> 3330 | F21: =IF(OR($AE21=0,F$8>$Z21),"",ROUND(((W21*X21+MAX(0,F$8-$AA21)*КРОК_ГОСТЯ)*(1-$U$5)+F$8*$AB21*(1-$U$5*$U$6)+$AD21*(1-$U$5*$U$7))/ОКРУГЛЕННЯ,0)*ОКРУГЛЕННЯ) -> 3830 | G21: =IF(OR($AE21=0,G$8>$Z21),"",ROUND(((W21*X21+MAX(0,G$8-$AA21)*КРОК_ГОСТЯ)*(1-$U$5)+G$8*$AB21*(1-$U$5*$U$6)+$AD21*(1-$U$5*$U$7))/ОКРУГЛЕННЯ,0)*ОКРУГЛЕННЯ) | H21: =IF(OR($AE21=0,H$8>$Z21),"",ROUND(((W21*X21+MAX(0,H$8-$AA21)*КРОК_ГОСТЯ)*(1-$U$5)+H$8*$AB21*(1-$U$5*$U$6)+$AD21*(1-$U$5*$U$7))/ОКРУГЛЕННЯ,0)*ОКРУГЛЕННЯ) | I21: =IF(OR($AE21=0,I$8>$Z21),"",ROUND(((W21*X21+MAX(0,I$8-$AA21)*КРОК_ГОСТЯ)*(1-$U$5)+I$8*$AB21*(1-$U$5*$U$6)+$AD21*(1-$U$5*$U$7))/ОКРУГЛЕННЯ,0)*ОКРУГЛЕННЯ) | J21: =IF(OR($AE21=0,J$8>$Z21),"",ROUND(((W21*X21+MAX(0,J$8-$AA21)*КРОК_ГОСТЯ)*(1-$U$5)+J$8*$AB21*(1-$U$5*$U$6)+$AD21*(1-$U$5*$U$7))/ОКРУГЛЕННЯ,0)*ОКРУГЛЕННЯ) | K21: =IF(OR($AE21=0,K$8>$Z21),"",ROUND(((W21*X21+MAX(0,K$8-$AA21)*КРОК_ГОСТЯ)*(1-$U$5)+K$8*$AB21*(1-$U$5*$U$6)+$AD21*(1-$U$5*$U$7))/ОКРУГЛЕННЯ,0)*ОКРУГЛЕННЯ) | L21: =IF(OR($AF21=0,L$8>$Z21),"",ROUND(((W21*X21*Y21+MAX(0,L$8-$AA21)*КРОК_ГОСТЯ)*(1-$U$5)+L$8*$AC21*(1-$U$5*$U$6)+$AD21*(1-$U$5*$U$7))/ОКРУГЛЕННЯ,0)*ОКРУГЛЕННЯ) -> 3535 | M21: =IF(OR($AF21=0,M$8>$Z21),"",ROUND(((W21*X21*Y21+MAX(0,M$8-$AA21)*КРОК_ГОСТЯ)*(1-$U$5)+M$8*$AC21*(1-$U$5*$U$6)+$AD21*(1-$U$5*$U$7))/ОКРУГЛЕННЯ,0)*ОКРУГЛЕННЯ) -> 3535 | N21: =IF(OR($AF21=0,N$8>$Z21),"",ROUND(((W21*X21*Y21+MAX(0,N$8-$AA21)*КРОК_ГОСТЯ)*(1-$U$5)+N$8*$AC21*(1-$U$5*$U$6)+$AD21*(1-$U$5*$U$7))/ОКРУГЛЕННЯ,0)*ОКРУГЛЕННЯ) -> 4035 | O21: =IF(OR($AF21=0,O$8>$Z21),"",ROUND(((W21*X21*Y21+MAX(0,O$8-$AA21)*КРОК_ГОСТЯ)*(1-$U$5)+O$8*$AC21*(1-$U$5*$U$6)+$AD21*(1-$U$5*$U$7))/ОКРУГЛЕННЯ,0)*ОКРУГЛЕННЯ) | P21: =IF(OR($AF21=0,P$8>$Z21),"",ROUND(((W21*X21*Y21+MAX(0,P$8-$AA21)*КРОК_ГОСТЯ)*(1-$U$5)+P$8*$AC21*(1-$U$5*$U$6)+$AD21*(1-$U$5*$U$7))/ОКРУГЛЕННЯ,0)*ОКРУГЛЕННЯ) | Q21: =IF(OR($AF21=0,Q$8>$Z21),"",ROUND(((W21*X21*Y21+MAX(0,Q$8-$AA21)*КРОК_ГОСТЯ)*(1-$U$5)+Q$8*$AC21*(1-$U$5*$U$6)+$AD21*(1-$U$5*$U$7))/ОКРУГЛЕННЯ,0)*ОКРУГЛЕННЯ) | R21: =IF(OR($AF21=0,R$8>$Z21),"",ROUND(((W21*X21*Y21+MAX(0,R$8-$AA21)*КРОК_ГОСТЯ)*(1-$U$5)+R$8*$AC21*(1-$U$5*$U$6)+$AD21*(1-$U$5*$U$7))/ОКРУГЛЕННЯ,0)*ОКРУГЛЕННЯ) | S21: =IF(OR($AF21=0,S$8>$Z21),"",ROUND(((W21*X21*Y21+MAX(0,S$8-$AA21)*КРОК_ГОСТЯ)*(1-$U$5)+S$8*$AC21*(1-$U$5*$U$6)+$AD21*(1-$U$5*$U$7))/ОКРУГЛЕННЯ,0)*ОКРУГЛЕННЯ) | W21: =IF(OR($U$3=0,$A21=""),0,IFERROR(INDEX(БАЗА_RO,MATCH(INDEX(ДОВ_ОПОРА,MATCH($A21,КАТЕГОРІЇ,0)),БАЗА_КАТ,0),$U$3),0)) -> 2930 | X21: =IF(OR($U$3=0,$A21=""),0,IFERROR(INDEX(МНОЖНИКИ,MATCH($A21,МНОЖ_КАТ,0),$U$3),0)) -> 1 | Y21: =IF(OR($U$3=0,$A21=""),0,IFERROR(INDEX(МНОЖНИКИ,MATCH($A21,МНОЖ_КАТ,0),$U$3+1),0)) -> 1.07 | Z21: =IF($A21="",0,IFERROR(INDEX(ДОВ_МАКС,MATCH($A21,КАТЕГОРІЇ,0)),0)) -> 3 | AA21: =IF($A21="",0,IFERROR(INDEX(ДОВ_ВКЛ,MATCH($A21,КАТЕГОРІЇ,0)),0)) -> 2 | AB21: =IF(OR($U$3=0,$U$8=0),0,IFERROR(INDEX(ПАКЕТИ_ЦІНИ,MATCH($U$10&"|Будні",ПАКЕТИ_КЛЮЧ,0),$U$3),0)) -> 0 | AC21: =IF(OR($U$3=0,$U$8=0),0,IFERROR(INDEX(ПАКЕТИ_ЦІНИ,MATCH($U$10&"|Вихідні",ПАКЕТИ_КЛЮЧ,0),$U$3),0)) -> 0 | AD21: =IF(OR($U$3=0,$U$9=0,$A21=""),0,IFERROR(INDEX(SPA_ЦІНИ,MATCH(INDEX(ДОВ_SPA,MATCH($A21,КАТЕГОРІЇ,0)),SPA_РОЛЬ,0),$U$3),0)) -> 400 | AE21: =IF(OR($A21="",W21=0,X21=0,AND($U$8=1,AB21=0),AND($U$9=1,AD21=0)),0,1) -> 1 | AF21: =IF(OR(AE21=0,Y21=0,AND($U$8=1,AC21=0)),0,1) -> 1
A22: =IF('Довідник категорій'!A18="","",'Довідник категорій'!A18) -> Апартаменти 2-кімнатні 1-й поверх | B22: =IF($A22="","",IFERROR(INDEX(ДОВ_BOOKING,MATCH($A22,КАТЕГОРІЇ,0)),"")) -> Апартаменти Делюкс 40 м² | C22: =IF($A22="","",IFERROR(INDEX(ДОВ_ГРУПА,MATCH($A22,КАТЕГОРІЇ,0)),"")) -> Apartments B | D22: =IF(OR($AE22=0,D$8>$Z22),"",ROUND(((W22*X22+MAX(0,D$8-$AA22)*КРОК_ГОСТЯ)*(1-$U$5)+D$8*$AB22*(1-$U$5*$U$6)+$AD22*(1-$U$5*$U$7))/ОКРУГЛЕННЯ,0)*ОКРУГЛЕННЯ) -> 3594 | E22: =IF(OR($AE22=0,E$8>$Z22),"",ROUND(((W22*X22+MAX(0,E$8-$AA22)*КРОК_ГОСТЯ)*(1-$U$5)+E$8*$AB22*(1-$U$5*$U$6)+$AD22*(1-$U$5*$U$7))/ОКРУГЛЕННЯ,0)*ОКРУГЛЕННЯ) -> 3594 | F22: =IF(OR($AE22=0,F$8>$Z22),"",ROUND(((W22*X22+MAX(0,F$8-$AA22)*КРОК_ГОСТЯ)*(1-$U$5)+F$8*$AB22*(1-$U$5*$U$6)+$AD22*(1-$U$5*$U$7))/ОКРУГЛЕННЯ,0)*ОКРУГЛЕННЯ) -> 4094 | G22: =IF(OR($AE22=0,G$8>$Z22),"",ROUND(((W22*X22+MAX(0,G$8-$AA22)*КРОК_ГОСТЯ)*(1-$U$5)+G$8*$AB22*(1-$U$5*$U$6)+$AD22*(1-$U$5*$U$7))/ОКРУГЛЕННЯ,0)*ОКРУГЛЕННЯ) | H22: =IF(OR($AE22=0,H$8>$Z22),"",ROUND(((W22*X22+MAX(0,H$8-$AA22)*КРОК_ГОСТЯ)*(1-$U$5)+H$8*$AB22*(1-$U$5*$U$6)+$AD22*(1-$U$5*$U$7))/ОКРУГЛЕННЯ,0)*ОКРУГЛЕННЯ) | I22: =IF(OR($AE22=0,I$8>$Z22),"",ROUND(((W22*X22+MAX(0,I$8-$AA22)*КРОК_ГОСТЯ)*(1-$U$5)+I$8*$AB22*(1-$U$5*$U$6)+$AD22*(1-$U$5*$U$7))/ОКРУГЛЕННЯ,0)*ОКРУГЛЕННЯ) | J22: =IF(OR($AE22=0,J$8>$Z22),"",ROUND(((W22*X22+MAX(0,J$8-$AA22)*КРОК_ГОСТЯ)*(1-$U$5)+J$8*$AB22*(1-$U$5*$U$6)+$AD22*(1-$U$5*$U$7))/ОКРУГЛЕННЯ,0)*ОКРУГЛЕННЯ) | K22: =IF(OR($AE22=0,K$8>$Z22),"",ROUND(((W22*X22+MAX(0,K$8-$AA22)*КРОК_ГОСТЯ)*(1-$U$5)+K$8*$AB22*(1-$U$5*$U$6)+$AD22*(1-$U$5*$U$7))/ОКРУГЛЕННЯ,0)*ОКРУГЛЕННЯ) | L22: =IF(OR($AF22=0,L$8>$Z22),"",ROUND(((W22*X22*Y22+MAX(0,L$8-$AA22)*КРОК_ГОСТЯ)*(1-$U$5)+L$8*$AC22*(1-$U$5*$U$6)+$AD22*(1-$U$5*$U$7))/ОКРУГЛЕННЯ,0)*ОКРУГЛЕННЯ) -> 3802 | M22: =IF(OR($AF22=0,M$8>$Z22),"",ROUND(((W22*X22*Y22+MAX(0,M$8-$AA22)*КРОК_ГОСТЯ)*(1-$U$5)+M$8*$AC22*(1-$U$5*$U$6)+$AD22*(1-$U$5*$U$7))/ОКРУГЛЕННЯ,0)*ОКРУГЛЕННЯ) -> 3802 | N22: =IF(OR($AF22=0,N$8>$Z22),"",ROUND(((W22*X22*Y22+MAX(0,N$8-$AA22)*КРОК_ГОСТЯ)*(1-$U$5)+N$8*$AC22*(1-$U$5*$U$6)+$AD22*(1-$U$5*$U$7))/ОКРУГЛЕННЯ,0)*ОКРУГЛЕННЯ) -> 4302 | O22: =IF(OR($AF22=0,O$8>$Z22),"",ROUND(((W22*X22*Y22+MAX(0,O$8-$AA22)*КРОК_ГОСТЯ)*(1-$U$5)+O$8*$AC22*(1-$U$5*$U$6)+$AD22*(1-$U$5*$U$7))/ОКРУГЛЕННЯ,0)*ОКРУГЛЕННЯ) | P22: =IF(OR($AF22=0,P$8>$Z22),"",ROUND(((W22*X22*Y22+MAX(0,P$8-$AA22)*КРОК_ГОСТЯ)*(1-$U$5)+P$8*$AC22*(1-$U$5*$U$6)+$AD22*(1-$U$5*$U$7))/ОКРУГЛЕННЯ,0)*ОКРУГЛЕННЯ) | Q22: =IF(OR($AF22=0,Q$8>$Z22),"",ROUND(((W22*X22*Y22+MAX(0,Q$8-$AA22)*КРОК_ГОСТЯ)*(1-$U$5)+Q$8*$AC22*(1-$U$5*$U$6)+$AD22*(1-$U$5*$U$7))/ОКРУГЛЕННЯ,0)*ОКРУГЛЕННЯ) | R22: =IF(OR($AF22=0,R$8>$Z22),"",ROUND(((W22*X22*Y22+MAX(0,R$8-$AA22)*КРОК_ГОСТЯ)*(1-$U$5)+R$8*$AC22*(1-$U$5*$U$6)+$AD22*(1-$U$5*$U$7))/ОКРУГЛЕННЯ,0)*ОКРУГЛЕННЯ) | S22: =IF(OR($AF22=0,S$8>$Z22),"",ROUND(((W22*X22*Y22+MAX(0,S$8-$AA22)*КРОК_ГОСТЯ)*(1-$U$5)+S$8*$AC22*(1-$U$5*$U$6)+$AD22*(1-$U$5*$U$7))/ОКРУГЛЕННЯ,0)*ОКРУГЛЕННЯ) | W22: =IF(OR($U$3=0,$A22=""),0,IFERROR(INDEX(БАЗА_RO,MATCH(INDEX(ДОВ_ОПОРА,MATCH($A22,КАТЕГОРІЇ,0)),БАЗА_КАТ,0),$U$3),0)) -> 2930 | X22: =IF(OR($U$3=0,$A22=""),0,IFERROR(INDEX(МНОЖНИКИ,MATCH($A22,МНОЖ_КАТ,0),$U$3),0)) -> 1.09 | Y22: =IF(OR($U$3=0,$A22=""),0,IFERROR(INDEX(МНОЖНИКИ,MATCH($A22,МНОЖ_КАТ,0),$U$3+1),0)) -> 1.0652 | Z22: =IF($A22="",0,IFERROR(INDEX(ДОВ_МАКС,MATCH($A22,КАТЕГОРІЇ,0)),0)) -> 3 | AA22: =IF($A22="",0,IFERROR(INDEX(ДОВ_ВКЛ,MATCH($A22,КАТЕГОРІЇ,0)),0)) -> 2 | AB22: =IF(OR($U$3=0,$U$8=0),0,IFERROR(INDEX(ПАКЕТИ_ЦІНИ,MATCH($U$10&"|Будні",ПАКЕТИ_КЛЮЧ,0),$U$3),0)) -> 0 | AC22: =IF(OR($U$3=0,$U$8=0),0,IFERROR(INDEX(ПАКЕТИ_ЦІНИ,MATCH($U$10&"|Вихідні",ПАКЕТИ_КЛЮЧ,0),$U$3),0)) -> 0 | AD22: =IF(OR($U$3=0,$U$9=0,$A22=""),0,IFERROR(INDEX(SPA_ЦІНИ,MATCH(INDEX(ДОВ_SPA,MATCH($A22,КАТЕГОРІЇ,0)),SPA_РОЛЬ,0),$U$3),0)) -> 400 | AE22: =IF(OR($A22="",W22=0,X22=0,AND($U$8=1,AB22=0),AND($U$9=1,AD22=0)),0,1) -> 1 | AF22: =IF(OR(AE22=0,Y22=0,AND($U$8=1,AC22=0)),0,1) -> 1
