Workbook

Sheet Прайс
A1: ="ПРАЙС PHOENIX СХІДНИЦЯ · "&$B$3&" · "&$U$11&" · Тариф: "&$B$4&" · Пакет: "&$B$5 -> ПРАЙС PHOENIX СХІДНИЦЯ · 0сінь 26 0-10% · 01.10.2026 – 30.11.2026 · Тариф: Rack Rate · Пакет: RO | U1: ТЕХНІЧНІ ДАНІ — НЕ РЕДАГУВАТИ
A3: Активний прайс-лист | B3: 0сінь 26 0-10% | D3: ="Період дії: "&$U$11 -> Період дії: 01.10.2026 – 30.11.2026 | U3: =IFERROR(MATCH($B$3,ПЛ_РЯДОК,0),0) -> 5 | V3: колонка прайс-листа
A4: Тариф (знижка) | B4: Rack Rate | D4: ="Знижка на проживання: "&TEXT($U$5,"0%")&IF($B$5="BBSPA"," — фіксована для пакета BBSPA; обраний тариф не застосовується","") -> Знижка на проживання: 0% | U4: =IFERROR(SUMIFS(ТАРИФИ_ЗНИЖКИ,ТАРИФИ_НАЗВИ,$B$4),0) -> 0 | V4: знижка тарифу
A5: Пакет | B5: RO | D5: =IF($B$5="RO","Лише проживання.",IF($B$5="BB","Проживання + сніданок за кожного гостя.",IF($B$5="BBSPA","Проживання + сніданок і SPA за кожного гостя.",IF($B$5="ROSPA","Проживання + 1 фіксований SPA-візит на обʼєкт.",IF($B$5="ROSPABB","Проживання + сніданки за кількістю гостей + 1 SPA-візит на обʼєкт.",""))))) -> Лише проживання. | U5: =IF($B$5="BBSPA",ЗНИЖКА_BBSPA,$U$4) -> 0 | V5: знижка на проживання
A6: =IF($U$3=0,"⚠ Прайс-лист не обрано або не знайдено — оберіть значення у клітинці B3.",IF($U$13=0,"⚠ У цьому прайс-листі ще не заповнені базові RO-ціни — сітка буде порожньою. Заповніть його блок на листі «Керування прайсом».","Усі ціни — за ніч, за дорослих гостей, у гривні. Дитячі тарифи рахує лист «Калькулятор». Ціна діє за базовою місткістю категорії; кожне додаткове місце додає доплату з «Довідника категорій» × знижку.")) -> Усі ціни — за ніч, за дорослих гостей, у гривні. Дитячі тарифи рахує лист «Калькулятор». Ціна діє за базовою місткістю категорії; кожне додаткове місце додає доплату з «Довідника категорій» × знижку. | U6: =IF($U$3=0,0,IFERROR(INDEX(ПЕРЕМИКАЧІ,IF($B$5="BBSPA",2,1),$U$3),0)) -> 0 | V6: перемикач: пакет
D7: БУДНІ — кількість гостей | M7: ВИХІДНІ — кількість гостей | U7: =IF($U$3=0,0,IFERROR(INDEX(ПЕРЕМИКАЧІ,3,$U$3),0)) -> 0 | V7: перемикач: SPA
A8: Категорія | B8: Назва на Booking | C8: Код | D8: 1 | E8: 2 | F8: 3 | G8: 4 | H8: 5 | I8: 6 | J8: 7 | K8: 8 | M8: 1 | N8: 2 | O8: 3 | P8: 4 | Q8: 5 | R8: 6 | S8: 7 | T8: 8 | U8: =IF(OR($B$5="BB",$B$5="BBSPA",$B$5="ROSPABB"),1,0) -> 0 | V8: потрібен пакет
A9: =IF('Довідник категорій'!B5="","",'Довідник категорій'!B5) -> Classic Chalet | B9: =IF($A9="","",IFERROR(INDEX(ДОВ_BOOKING,MATCH($A9,КАТЕГОРІЇ,0)),"")) -> Шале з 1 спальнею | C9: =IF($A9="","",IFERROR(INDEX(ДОВ_КОД,MATCH($A9,КАТЕГОРІЇ,0)),"")) -> CH-CL | D9: =IF(OR($AF9=0,D$8>$Y9),"",ROUND($W9*(1-$U$5)/ОКРУГЛЕННЯ,0)*ОКРУГЛЕННЯ+MAX(0,D$8-$Z9)*$AA9*(1-$U$5)+D$8*$AB9*(1-$U$5*$U$6)+$AD9*(1-$U$5*$U$7)) -> 4200 | E9: =IF(OR($AF9=0,E$8>$Y9),"",ROUND($W9*(1-$U$5)/ОКРУГЛЕННЯ,0)*ОКРУГЛЕННЯ+MAX(0,E$8-$Z9)*$AA9*(1-$U$5)+E$8*$AB9*(1-$U$5*$U$6)+$AD9*(1-$U$5*$U$7)) -> 4200 | F9: =IF(OR($AF9=0,F$8>$Y9),"",ROUND($W9*(1-$U$5)/ОКРУГЛЕННЯ,0)*ОКРУГЛЕННЯ+MAX(0,F$8-$Z9)*$AA9*(1-$U$5)+F$8*$AB9*(1-$U$5*$U$6)+$AD9*(1-$U$5*$U$7)) -> 5200 | G9: =IF(OR($AF9=0,G$8>$Y9),"",ROUND($W9*(1-$U$5)/ОКРУГЛЕННЯ,0)*ОКРУГЛЕННЯ+MAX(0,G$8-$Z9)*$AA9*(1-$U$5)+G$8*$AB9*(1-$U$5*$U$6)+$AD9*(1-$U$5*$U$7)) | H9: =IF(OR($AF9=0,H$8>$Y9),"",ROUND($W9*(1-$U$5)/ОКРУГЛЕННЯ,0)*ОКРУГЛЕННЯ+MAX(0,H$8-$Z9)*$AA9*(1-$U$5)+H$8*$AB9*(1-$U$5*$U$6)+$AD9*(1-$U$5*$U$7)) | I9: =IF(OR($AF9=0,I$8>$Y9),"",ROUND($W9*(1-$U$5)/ОКРУГЛЕННЯ,0)*ОКРУГЛЕННЯ+MAX(0,I$8-$Z9)*$AA9*(1-$U$5)+I$8*$AB9*(1-$U$5*$U$6)+$AD9*(1-$U$5*$U$7)) | J9: =IF(OR($AF9=0,J$8>$Y9),"",ROUND($W9*(1-$U$5)/ОКРУГЛЕННЯ,0)*ОКРУГЛЕННЯ+MAX(0,J$8-$Z9)*$AA9*(1-$U$5)+J$8*$AB9*(1-$U$5*$U$6)+$AD9*(1-$U$5*$U$7)) | K9: =IF(OR($AF9=0,K$8>$Y9),"",ROUND($W9*(1-$U$5)/ОКРУГЛЕННЯ,0)*ОКРУГЛЕННЯ+MAX(0,K$8-$Z9)*$AA9*(1-$U$5)+K$8*$AB9*(1-$U$5*$U$6)+$AD9*(1-$U$5*$U$7)) | M9: =IF(OR($AG9=0,M$8>$Y9),"",ROUND($X9*(1-$U$5)/ОКРУГЛЕННЯ,0)*ОКРУГЛЕННЯ+MAX(0,M$8-$Z9)*$AA9*(1-$U$5)+M$8*$AC9*(1-$U$5*$U$6)+$AE9*(1-$U$5*$U$7)) -> 4700 | N9: =IF(OR($AG9=0,N$8>$Y9),"",ROUND($X9*(1-$U$5)/ОКРУГЛЕННЯ,0)*ОКРУГЛЕННЯ+MAX(0,N$8-$Z9)*$AA9*(1-$U$5)+N$8*$AC9*(1-$U$5*$U$6)+$AE9*(1-$U$5*$U$7)) -> 4700 | O9: =IF(OR($AG9=0,O$8>$Y9),"",ROUND($X9*(1-$U$5)/ОКРУГЛЕННЯ,0)*ОКРУГЛЕННЯ+MAX(0,O$8-$Z9)*$AA9*(1-$U$5)+O$8*$AC9*(1-$U$5*$U$6)+$AE9*(1-$U$5*$U$7)) -> 5700 | P9: =IF(OR($AG9=0,P$8>$Y9),"",ROUND($X9*(1-$U$5)/ОКРУГЛЕННЯ,0)*ОКРУГЛЕННЯ+MAX(0,P$8-$Z9)*$AA9*(1-$U$5)+P$8*$AC9*(1-$U$5*$U$6)+$AE9*(1-$U$5*$U$7)) | Q9: =IF(OR($AG9=0,Q$8>$Y9),"",ROUND($X9*(1-$U$5)/ОКРУГЛЕННЯ,0)*ОКРУГЛЕННЯ+MAX(0,Q$8-$Z9)*$AA9*(1-$U$5)+Q$8*$AC9*(1-$U$5*$U$6)+$AE9*(1-$U$5*$U$7)) | R9: =IF(OR($AG9=0,R$8>$Y9),"",ROUND($X9*(1-$U$5)/ОКРУГЛЕННЯ,0)*ОКРУГЛЕННЯ+MAX(0,R$8-$Z9)*$AA9*(1-$U$5)+R$8*$AC9*(1-$U$5*$U$6)+$AE9*(1-$U$5*$U$7)) | S9: =IF(OR($AG9=0,S$8>$Y9),"",ROUND($X9*(1-$U$5)/ОКРУГЛЕННЯ,0)*ОКРУГЛЕННЯ+MAX(0,S$8-$Z9)*$AA9*(1-$U$5)+S$8*$AC9*(1-$U$5*$U$6)+$AE9*(1-$U$5*$U$7)) | T9: =IF(OR($AG9=0,T$8>$Y9),"",ROUND($X9*(1-$U$5)/ОКРУГЛЕННЯ,0)*ОКРУГЛЕННЯ+MAX(0,T$8-$Z9)*$AA9*(1-$U$5)+T$8*$AC9*(1-$U$5*$U$6)+$AE9*(1-$U$5*$U$7)) | U9: =IF(OR($B$5="ROSPA",$B$5="ROSPABB"),1,0) -> 0 | V9: потрібен SPA | W9: =IF(OR($U$3=0,$A9=""),0,IFERROR(INDEX(БАЗА_ЦІНИ,MATCH($A9,БАЗА_КАТ,0),$U$3),0)) -> 4200 | X9: =IF(OR($U$3=0,$A9=""),0,IFERROR(INDEX(БАЗА_ЦІНИ,MATCH($A9,БАЗА_КАТ,0),$U$3+1),0)) -> 4700 | Y9: =IF($A9="",0,IFERROR(INDEX(ДОВ_МАКС,MATCH($A9,КАТЕГОРІЇ,0)),0)) -> 3 | Z9: =IF($A9="",0,IFERROR(INDEX(ДОВ_ВКЛ,MATCH($A9,КАТЕГОРІЇ,0)),0)) -> 2 | AA9: =IF($A9="",0,IFERROR(INDEX(ДОВ_ДОПЛ_ДОР,MATCH($A9,КАТЕГОРІЇ,0)),0)) -> 1000 | AB9: =IF(OR($U$3=0,$U$8=0),0,IFERROR(INDEX(ПАКЕТИ_ЦІНИ,MATCH($U$10&"|Будні",ПАКЕТИ_КЛЮЧ,0),$U$3),0)) -> 0 | AC9: =IF(OR($U$3=0,$U$8=0),0,IFERROR(INDEX(ПАКЕТИ_ЦІНИ,MATCH($U$10&"|Вихідні",ПАКЕТИ_КЛЮЧ,0),$U$3),0)) -> 0 | AD9: =IF(OR($U$3=0,$U$9=0,$A9=""),0,IFERROR(INDEX(SPA_ЦІНИ,MATCH(INDEX(ДОВ_SPA,MATCH($A9,КАТЕГОРІЇ,0)),SPA_РІВЕНЬ,0),$U$3),0)) -> 0 | AE9: =IF(OR($U$3=0,$U$9=0,$A9=""),0,IFERROR(INDEX(SPA_ЦІНИ,MATCH(INDEX(ДОВ_SPA,MATCH($A9,КАТЕГОРІЇ,0)),SPA_РІВЕНЬ,0),$U$3+1),0)) -> 0 | AF9: =IF(OR($A9="",W9=0,AND($U$8=1,AB9=0),AND($U$9=1,AD9=0)),0,1) -> 1 | AG9: =IF(OR($A9="",X9=0,AND($U$8=1,AC9=0),AND($U$9=1,AE9=0)),0,1) -> 1
A10: =IF('Довідник категорій'!B6="","",'Довідник категорій'!B6) -> Forest View Chalet | B10: =IF($A10="","",IFERROR(INDEX(ДОВ_BOOKING,MATCH($A10,КАТЕГОРІЇ,0)),"")) -> Вілла Делюкс | C10: =IF($A10="","",IFERROR(INDEX(ДОВ_КОД,MATCH($A10,КАТЕГОРІЇ,0)),"")) -> CH-FV | D10: =IF(OR($AF10=0,D$8>$Y10),"",ROUND($W10*(1-$U$5)/ОКРУГЛЕННЯ,0)*ОКРУГЛЕННЯ+MAX(0,D$8-$Z10)*$AA10*(1-$U$5)+D$8*$AB10*(1-$U$5*$U$6)+$AD10*(1-$U$5*$U$7)) -> 4600 | E10: =IF(OR($AF10=0,E$8>$Y10),"",ROUND($W10*(1-$U$5)/ОКРУГЛЕННЯ,0)*ОКРУГЛЕННЯ+MAX(0,E$8-$Z10)*$AA10*(1-$U$5)+E$8*$AB10*(1-$U$5*$U$6)+$AD10*(1-$U$5*$U$7)) -> 4600 | F10: =IF(OR($AF10=0,F$8>$Y10),"",ROUND($W10*(1-$U$5)/ОКРУГЛЕННЯ,0)*ОКРУГЛЕННЯ+MAX(0,F$8-$Z10)*$AA10*(1-$U$5)+F$8*$AB10*(1-$U$5*$U$6)+$AD10*(1-$U$5*$U$7)) -> 5600 | G10: =IF(OR($AF10=0,G$8>$Y10),"",ROUND($W10*(1-$U$5)/ОКРУГЛЕННЯ,0)*ОКРУГЛЕННЯ+MAX(0,G$8-$Z10)*$AA10*(1-$U$5)+G$8*$AB10*(1-$U$5*$U$6)+$AD10*(1-$U$5*$U$7)) | H10: =IF(OR($AF10=0,H$8>$Y10),"",ROUND($W10*(1-$U$5)/ОКРУГЛЕННЯ,0)*ОКРУГЛЕННЯ+MAX(0,H$8-$Z10)*$AA10*(1-$U$5)+H$8*$AB10*(1-$U$5*$U$6)+$AD10*(1-$U$5*$U$7)) | I10: =IF(OR($AF10=0,I$8>$Y10),"",ROUND($W10*(1-$U$5)/ОКРУГЛЕННЯ,0)*ОКРУГЛЕННЯ+MAX(0,I$8-$Z10)*$AA10*(1-$U$5)+I$8*$AB10*(1-$U$5*$U$6)+$AD10*(1-$U$5*$U$7)) | J10: =IF(OR($AF10=0,J$8>$Y10),"",ROUND($W10*(1-$U$5)/ОКРУГЛЕННЯ,0)*ОКРУГЛЕННЯ+MAX(0,J$8-$Z10)*$AA10*(1-$U$5)+J$8*$AB10*(1-$U$5*$U$6)+$AD10*(1-$U$5*$U$7)) | K10: =IF(OR($AF10=0,K$8>$Y10),"",ROUND($W10*(1-$U$5)/ОКРУГЛЕННЯ,0)*ОКРУГЛЕННЯ+MAX(0,K$8-$Z10)*$AA10*(1-$U$5)+K$8*$AB10*(1-$U$5*$U$6)+$AD10*(1-$U$5*$U$7)) | M10: =IF(OR($AG10=0,M$8>$Y10),"",ROUND($X10*(1-$U$5)/ОКРУГЛЕННЯ,0)*ОКРУГЛЕННЯ+MAX(0,M$8-$Z10)*$AA10*(1-$U$5)+M$8*$AC10*(1-$U$5*$U$6)+$AE10*(1-$U$5*$U$7)) -> 5200 | N10: =IF(OR($AG10=0,N$8>$Y10),"",ROUND($X10*(1-$U$5)/ОКРУГЛЕННЯ,0)*ОКРУГЛЕННЯ+MAX(0,N$8-$Z10)*$AA10*(1-$U$5)+N$8*$AC10*(1-$U$5*$U$6)+$AE10*(1-$U$5*$U$7)) -> 5200 | O10: =IF(OR($AG10=0,O$8>$Y10),"",ROUND($X10*(1-$U$5)/ОКРУГЛЕННЯ,0)*ОКРУГЛЕННЯ+MAX(0,O$8-$Z10)*$AA10*(1-$U$5)+O$8*$AC10*(1-$U$5*$U$6)+$AE10*(1-$U$5*$U$7)) -> 6200 | P10: =IF(OR($AG10=0,P$8>$Y10),"",ROUND($X10*(1-$U$5)/ОКРУГЛЕННЯ,0)*ОКРУГЛЕННЯ+MAX(0,P$8-$Z10)*$AA10*(1-$U$5)+P$8*$AC10*(1-$U$5*$U$6)+$AE10*(1-$U$5*$U$7)) | Q10: =IF(OR($AG10=0,Q$8>$Y10),"",ROUND($X10*(1-$U$5)/ОКРУГЛЕННЯ,0)*ОКРУГЛЕННЯ+MAX(0,Q$8-$Z10)*$AA10*(1-$U$5)+Q$8*$AC10*(1-$U$5*$U$6)+$AE10*(1-$U$5*$U$7)) | R10: =IF(OR($AG10=0,R$8>$Y10),"",ROUND($X10*(1-$U$5)/ОКРУГЛЕННЯ,0)*ОКРУГЛЕННЯ+MAX(0,R$8-$Z10)*$AA10*(1-$U$5)+R$8*$AC10*(1-$U$5*$U$6)+$AE10*(1-$U$5*$U$7)) | S10: =IF(OR($AG10=0,S$8>$Y10),"",ROUND($X10*(1-$U$5)/ОКРУГЛЕННЯ,0)*ОКРУГЛЕННЯ+MAX(0,S$8-$Z10)*$AA10*(1-$U$5)+S$8*$AC10*(1-$U$5*$U$6)+$AE10*(1-$U$5*$U$7)) | T10: =IF(OR($AG10=0,T$8>$Y10),"",ROUND($X10*(1-$U$5)/ОКРУГЛЕННЯ,0)*ОКРУГЛЕННЯ+MAX(0,T$8-$Z10)*$AA10*(1-$U$5)+T$8*$AC10*(1-$U$5*$U$6)+$AE10*(1-$U$5*$U$7)) | U10: =IF($U$8=0,"",IF($B$5="ROSPABB","BB",$B$5)) | V10: ключ пакета | W10: =IF(OR($U$3=0,$A10=""),0,IFERROR(INDEX(БАЗА_ЦІНИ,MATCH($A10,БАЗА_КАТ,0),$U$3),0)) -> 4550 | X10: =IF(OR($U$3=0,$A10=""),0,IFERROR(INDEX(БАЗА_ЦІНИ,MATCH($A10,БАЗА_КАТ,0),$U$3+1),0)) -> 5150 | Y10: =IF($A10="",0,IFERROR(INDEX(ДОВ_МАКС,MATCH($A10,КАТЕГОРІЇ,0)),0)) -> 3 | Z10: =IF($A10="",0,IFERROR(INDEX(ДОВ_ВКЛ,MATCH($A10,КАТЕГОРІЇ,0)),0)) -> 2 | AA10: =IF($A10="",0,IFERROR(INDEX(ДОВ_ДОПЛ_ДОР,MATCH($A10,КАТЕГОРІЇ,0)),0)) -> 1000 | AB10: =IF(OR($U$3=0,$U$8=0),0,IFERROR(INDEX(ПАКЕТИ_ЦІНИ,MATCH($U$10&"|Будні",ПАКЕТИ_КЛЮЧ,0),$U$3),0)) -> 0 | AC10: =IF(OR($U$3=0,$U$8=0),0,IFERROR(INDEX(ПАКЕТИ_ЦІНИ,MATCH($U$10&"|Вихідні",ПАКЕТИ_КЛЮЧ,0),$U$3),0)) -> 0 | AD10: =IF(OR($U$3=0,$U$9=0,$A10=""),0,IFERROR(INDEX(SPA_ЦІНИ,MATCH(INDEX(ДОВ_SPA,MATCH($A10,КАТЕГОРІЇ,0)),SPA_РІВЕНЬ,0),$U$3),0)) -> 0 | AE10: =IF(OR($U$3=0,$U$9=0,$A10=""),0,IFERROR(INDEX(SPA_ЦІНИ,MATCH(INDEX(ДОВ_SPA,MATCH($A10,КАТЕГОРІЇ,0)),SPA_РІВЕНЬ,0),$U$3+1),0)) -> 0 | AF10: =IF(OR($A10="",W10=0,AND($U$8=1,AB10=0),AND($U$9=1,AD10=0)),0,1) -> 1 | AG10: =IF(OR($A10="",X10=0,AND($U$8=1,AC10=0),AND($U$9=1,AE10=0)),0,1) -> 1
A11: =IF('Довідник категорій'!B7="","",'Довідник категорій'!B7) -> Premium Chalet | B11: =IF($A11="","",IFERROR(INDEX(ДОВ_BOOKING,MATCH($A11,КАТЕГОРІЇ,0)),"")) -> Шале з 3 спальнями | C11: =IF($A11="","",IFERROR(INDEX(ДОВ_КОД,MATCH($A11,КАТЕГОРІЇ,0)),"")) -> CH-PR | D11: =IF(OR($AF11=0,D$8>$Y11),"",ROUND($W11*(1-$U$5)/ОКРУГЛЕННЯ,0)*ОКРУГЛЕННЯ+MAX(0,D$8-$Z11)*$AA11*(1-$U$5)+D$8*$AB11*(1-$U$5*$U$6)+$AD11*(1-$U$5*$U$7)) -> 7800 | E11: =IF(OR($AF11=0,E$8>$Y11),"",ROUND($W11*(1-$U$5)/ОКРУГЛЕННЯ,0)*ОКРУГЛЕННЯ+MAX(0,E$8-$Z11)*$AA11*(1-$U$5)+E$8*$AB11*(1-$U$5*$U$6)+$AD11*(1-$U$5*$U$7)) -> 7800 | F11: =IF(OR($AF11=0,F$8>$Y11),"",ROUND($W11*(1-$U$5)/ОКРУГЛЕННЯ,0)*ОКРУГЛЕННЯ+MAX(0,F$8-$Z11)*$AA11*(1-$U$5)+F$8*$AB11*(1-$U$5*$U$6)+$AD11*(1-$U$5*$U$7)) -> 7800 | G11: =IF(OR($AF11=0,G$8>$Y11),"",ROUND($W11*(1-$U$5)/ОКРУГЛЕННЯ,0)*ОКРУГЛЕННЯ+MAX(0,G$8-$Z11)*$AA11*(1-$U$5)+G$8*$AB11*(1-$U$5*$U$6)+$AD11*(1-$U$5*$U$7)) -> 7800 | H11: =IF(OR($AF11=0,H$8>$Y11),"",ROUND($W11*(1-$U$5)/ОКРУГЛЕННЯ,0)*ОКРУГЛЕННЯ+MAX(0,H$8-$Z11)*$AA11*(1-$U$5)+H$8*$AB11*(1-$U$5*$U$6)+$AD11*(1-$U$5*$U$7)) -> 7800 | I11: =IF(OR($AF11=0,I$8>$Y11),"",ROUND($W11*(1-$U$5)/ОКРУГЛЕННЯ,0)*ОКРУГЛЕННЯ+MAX(0,I$8-$Z11)*$AA11*(1-$U$5)+I$8*$AB11*(1-$U$5*$U$6)+$AD11*(1-$U$5*$U$7)) -> 7800 | J11: =IF(OR($AF11=0,J$8>$Y11),"",ROUND($W11*(1-$U$5)/ОКРУГЛЕННЯ,0)*ОКРУГЛЕННЯ+MAX(0,J$8-$Z11)*$AA11*(1-$U$5)+J$8*$AB11*(1-$U$5*$U$6)+$AD11*(1-$U$5*$U$7)) -> 8800 | K11: =IF(OR($AF11=0,K$8>$Y11),"",ROUND($W11*(1-$U$5)/ОКРУГЛЕННЯ,0)*ОКРУГЛЕННЯ+MAX(0,K$8-$Z11)*$AA11*(1-$U$5)+K$8*$AB11*(1-$U$5*$U$6)+$AD11*(1-$U$5*$U$7)) -> 9800 | M11: =IF(OR($AG11=0,M$8>$Y11),"",ROUND($X11*(1-$U$5)/ОКРУГЛЕННЯ,0)*ОКРУГЛЕННЯ+MAX(0,M$8-$Z11)*$AA11*(1-$U$5)+M$8*$AC11*(1-$U$5*$U$6)+$AE11*(1-$U$5*$U$7)) -> 9800 | N11: =IF(OR($AG11=0,N$8>$Y11),"",ROUND($X11*(1-$U$5)/ОКРУГЛЕННЯ,0)*ОКРУГЛЕННЯ+MAX(0,N$8-$Z11)*$AA11*(1-$U$5)+N$8*$AC11*(1-$U$5*$U$6)+$AE11*(1-$U$5*$U$7)) -> 9800 | O11: =IF(OR($AG11=0,O$8>$Y11),"",ROUND($X11*(1-$U$5)/ОКРУГЛЕННЯ,0)*ОКРУГЛЕННЯ+MAX(0,O$8-$Z11)*$AA11*(1-$U$5)+O$8*$AC11*(1-$U$5*$U$6)+$AE11*(1-$U$5*$U$7)) -> 9800 | P11: =IF(OR($AG11=0,P$8>$Y11),"",ROUND($X11*(1-$U$5)/ОКРУГЛЕННЯ,0)*ОКРУГЛЕННЯ+MAX(0,P$8-$Z11)*$AA11*(1-$U$5)+P$8*$AC11*(1-$U$5*$U$6)+$AE11*(1-$U$5*$U$7)) -> 9800 | Q11: =IF(OR($AG11=0,Q$8>$Y11),"",ROUND($X11*(1-$U$5)/ОКРУГЛЕННЯ,0)*ОКРУГЛЕННЯ+MAX(0,Q$8-$Z11)*$AA11*(1-$U$5)+Q$8*$AC11*(1-$U$5*$U$6)+$AE11*(1-$U$5*$U$7)) -> 9800 | R11: =IF(OR($AG11=0,R$8>$Y11),"",ROUND($X11*(1-$U$5)/ОКРУГЛЕННЯ,0)*ОКРУГЛЕННЯ+MAX(0,R$8-$Z11)*$AA11*(1-$U$5)+R$8*$AC11*(1-$U$5*$U$6)+$AE11*(1-$U$5*$U$7)) -> 9800 | S11: =IF(OR($AG11=0,S$8>$Y11),"",ROUND($X11*(1-$U$5)/ОКРУГЛЕННЯ,0)*ОКРУГЛЕННЯ+MAX(0,S$8-$Z11)*$AA11*(1-$U$5)+S$8*$AC11*(1-$U$5*$U$6)+$AE11*(1-$U$5*$U$7)) -> 10800 | T11: =IF(OR($AG11=0,T$8>$Y11),"",ROUND($X11*(1-$U$5)/ОКРУГЛЕННЯ,0)*ОКРУГЛЕННЯ+MAX(0,T$8-$Z11)*$AA11*(1-$U$5)+T$8*$AC11*(1-$U$5*$U$6)+$AE11*(1-$U$5*$U$7)) -> 11800 | U11: =IF($U$12=0,"період не заданий",IFERROR(IF(OR(INDEX(ПЛ_ДАТА_З,$U$12)="",INDEX(ПЛ_ДАТА_ПО,$U$12)=""),"період не заданий",TEXT(DAY(INDEX(ПЛ_ДАТА_З,$U$12)),"00")&"."&TEXT(MONTH(INDEX(ПЛ_ДАТА_З,$U$12)),"00")&"."&YEAR(INDEX(ПЛ_ДАТА_З,$U$12))&" – "&TEXT(DAY(INDEX(ПЛ_ДАТА_ПО,$U$12)),"00")&"."&TEXT(MONTH(INDEX(ПЛ_ДАТА_ПО,$U$12)),"00")&"."&YEAR(INDEX(ПЛ_ДАТА_ПО,$U$12))),"період не заданий")) -> 01.10.2026 – 30.11.2026 | V11: період (текст) | W11: =IF(OR($U$3=0,$A11=""),0,IFERROR(INDEX(БАЗА_ЦІНИ,MATCH($A11,БАЗА_КАТ,0),$U$3),0)) -> 7770 | X11: =IF(OR($U$3=0,$A11=""),0,IFERROR(INDEX(БАЗА_ЦІНИ,MATCH($A11,БАЗА_КАТ,0),$U$3+1),0)) -> 9770 | Y11: =IF($A11="",0,IFERROR(INDEX(ДОВ_МАКС,MATCH($A11,КАТЕГОРІЇ,0)),0)) -> 8 | Z11: =IF($A11="",0,IFERROR(INDEX(ДОВ_ВКЛ,MATCH($A11,КАТЕГОРІЇ,0)),0)) -> 6 | AA11: =IF($A11="",0,IFERROR(INDEX(ДОВ_ДОПЛ_ДОР,MATCH($A11,КАТЕГОРІЇ,0)),0)) -> 1000 | AB11: =IF(OR($U$3=0,$U$8=0),0,IFERROR(INDEX(ПАКЕТИ_ЦІНИ,MATCH($U$10&"|Будні",ПАКЕТИ_КЛЮЧ,0),$U$3),0)) -> 0 | AC11: =IF(OR($U$3=0,$U$8=0),0,IFERROR(INDEX(ПАКЕТИ_ЦІНИ,MATCH($U$10&"|Вихідні",ПАКЕТИ_КЛЮЧ,0),$U$3),0)) -> 0 | AD11: =IF(OR($U$3=0,$U$9=0,$A11=""),0,IFERROR(INDEX(SPA_ЦІНИ,MATCH(INDEX(ДОВ_SPA,MATCH($A11,КАТЕГОРІЇ,0)),SPA_РІВЕНЬ,0),$U$3),0)) -> 0 | AE11: =IF(OR($U$3=0,$U$9=0,$A11=""),0,IFERROR(INDEX(SPA_ЦІНИ,MATCH(INDEX(ДОВ_SPA,MATCH($A11,КАТЕГОРІЇ,0)),SPA_РІВЕНЬ,0),$U$3+1),0)) -> 0 | AF11: =IF(OR($A11="",W11=0,AND($U$8=1,AB11=0),AND($U$9=1,AD11=0)),0,1) -> 1 | AG11: =IF(OR($A11="",X11=0,AND($U$8=1,AC11=0),AND($U$9=1,AE11=0)),0,1) -> 1
A12: =IF('Довідник категорій'!B8="","",'Довідник категорій'!B8) | B12: =IF($A12="","",IFERROR(INDEX(ДОВ_BOOKING,MATCH($A12,КАТЕГОРІЇ,0)),"")) | C12: =IF($A12="","",IFERROR(INDEX(ДОВ_КОД,MATCH($A12,КАТЕГОРІЇ,0)),"")) | D12: =IF(OR($AF12=0,D$8>$Y12),"",ROUND($W12*(1-$U$5)/ОКРУГЛЕННЯ,0)*ОКРУГЛЕННЯ+MAX(0,D$8-$Z12)*$AA12*(1-$U$5)+D$8*$AB12*(1-$U$5*$U$6)+$AD12*(1-$U$5*$U$7)) | E12: =IF(OR($AF12=0,E$8>$Y12),"",ROUND($W12*(1-$U$5)/ОКРУГЛЕННЯ,0)*ОКРУГЛЕННЯ+MAX(0,E$8-$Z12)*$AA12*(1-$U$5)+E$8*$AB12*(1-$U$5*$U$6)+$AD12*(1-$U$5*$U$7)) | F12: =IF(OR($AF12=0,F$8>$Y12),"",ROUND($W12*(1-$U$5)/ОКРУГЛЕННЯ,0)*ОКРУГЛЕННЯ+MAX(0,F$8-$Z12)*$AA12*(1-$U$5)+F$8*$AB12*(1-$U$5*$U$6)+$AD12*(1-$U$5*$U$7)) | G12: =IF(OR($AF12=0,G$8>$Y12),"",ROUND($W12*(1-$U$5)/ОКРУГЛЕННЯ,0)*ОКРУГЛЕННЯ+MAX(0,G$8-$Z12)*$AA12*(1-$U$5)+G$8*$AB12*(1-$U$5*$U$6)+$AD12*(1-$U$5*$U$7)) | H12: =IF(OR($AF12=0,H$8>$Y12),"",ROUND($W12*(1-$U$5)/ОКРУГЛЕННЯ,0)*ОКРУГЛЕННЯ+MAX(0,H$8-$Z12)*$AA12*(1-$U$5)+H$8*$AB12*(1-$U$5*$U$6)+$AD12*(1-$U$5*$U$7)) | I12: =IF(OR($AF12=0,I$8>$Y12),"",ROUND($W12*(1-$U$5)/ОКРУГЛЕННЯ,0)*ОКРУГЛЕННЯ+MAX(0,I$8-$Z12)*$AA12*(1-$U$5)+I$8*$AB12*(1-$U$5*$U$6)+$AD12*(1-$U$5*$U$7)) | J12: =IF(OR($AF12=0,J$8>$Y12),"",ROUND($W12*(1-$U$5)/ОКРУГЛЕННЯ,0)*ОКРУГЛЕННЯ+MAX(0,J$8-$Z12)*$AA12*(1-$U$5)+J$8*$AB12*(1-$U$5*$U$6)+$AD12*(1-$U$5*$U$7)) | K12: =IF(OR($AF12=0,K$8>$Y12),"",ROUND($W12*(1-$U$5)/ОКРУГЛЕННЯ,0)*ОКРУГЛЕННЯ+MAX(0,K$8-$Z12)*$AA12*(1-$U$5)+K$8*$AB12*(1-$U$5*$U$6)+$AD12*(1-$U$5*$U$7)) | M12: =IF(OR($AG12=0,M$8>$Y12),"",ROUND($X12*(1-$U$5)/ОКРУГЛЕННЯ,0)*ОКРУГЛЕННЯ+MAX(0,M$8-$Z12)*$AA12*(1-$U$5)+M$8*$AC12*(1-$U$5*$U$6)+$AE12*(1-$U$5*$U$7)) | N12: =IF(OR($AG12=0,N$8>$Y12),"",ROUND($X12*(1-$U$5)/ОКРУГЛЕННЯ,0)*ОКРУГЛЕННЯ+MAX(0,N$8-$Z12)*$AA12*(1-$U$5)+N$8*$AC12*(1-$U$5*$U$6)+$AE12*(1-$U$5*$U$7)) | O12: =IF(OR($AG12=0,O$8>$Y12),"",ROUND($X12*(1-$U$5)/ОКРУГЛЕННЯ,0)*ОКРУГЛЕННЯ+MAX(0,O$8-$Z12)*$AA12*(1-$U$5)+O$8*$AC12*(1-$U$5*$U$6)+$AE12*(1-$U$5*$U$7)) | P12: =IF(OR($AG12=0,P$8>$Y12),"",ROUND($X12*(1-$U$5)/ОКРУГЛЕННЯ,0)*ОКРУГЛЕННЯ+MAX(0,P$8-$Z12)*$AA12*(1-$U$5)+P$8*$AC12*(1-$U$5*$U$6)+$AE12*(1-$U$5*$U$7)) | Q12: =IF(OR($AG12=0,Q$8>$Y12),"",ROUND($X12*(1-$U$5)/ОКРУГЛЕННЯ,0)*ОКРУГЛЕННЯ+MAX(0,Q$8-$Z12)*$AA12*(1-$U$5)+Q$8*$AC12*(1-$U$5*$U$6)+$AE12*(1-$U$5*$U$7)) | R12: =IF(OR($AG12=0,R$8>$Y12),"",ROUND($X12*(1-$U$5)/ОКРУГЛЕННЯ,0)*ОКРУГЛЕННЯ+MAX(0,R$8-$Z12)*$AA12*(1-$U$5)+R$8*$AC12*(1-$U$5*$U$6)+$AE12*(1-$U$5*$U$7)) | S12: =IF(OR($AG12=0,S$8>$Y12),"",ROUND($X12*(1-$U$5)/ОКРУГЛЕННЯ,0)*ОКРУГЛЕННЯ+MAX(0,S$8-$Z12)*$AA12*(1-$U$5)+S$8*$AC12*(1-$U$5*$U$6)+$AE12*(1-$U$5*$U$7)) | T12: =IF(OR($AG12=0,T$8>$Y12),"",ROUND($X12*(1-$U$5)/ОКРУГЛЕННЯ,0)*ОКРУГЛЕННЯ+MAX(0,T$8-$Z12)*$AA12*(1-$U$5)+T$8*$AC12*(1-$U$5*$U$6)+$AE12*(1-$U$5*$U$7)) | U12: =IFERROR(MATCH($B$3,ПРАЙС_ЛИСТИ,0),0) -> 3 | V12: рядок прайс-листа | W12: =IF(OR($U$3=0,$A12=""),0,IFERROR(INDEX(БАЗА_ЦІНИ,MATCH($A12,БАЗА_КАТ,0),$U$3),0)) -> 0 | X12: =IF(OR($U$3=0,$A12=""),0,IFERROR(INDEX(БАЗА_ЦІНИ,MATCH($A12,БАЗА_КАТ,0),$U$3+1),0)) -> 0 | Y12: =IF($A12="",0,IFERROR(INDEX(ДОВ_МАКС,MATCH($A12,КАТЕГОРІЇ,0)),0)) -> 0 | Z12: =IF($A12="",0,IFERROR(INDEX(ДОВ_ВКЛ,MATCH($A12,КАТЕГОРІЇ,0)),0)) -> 0 | AA12: =IF($A12="",0,IFERROR(INDEX(ДОВ_ДОПЛ_ДОР,MATCH($A12,КАТЕГОРІЇ,0)),0)) -> 0 | AB12: =IF(OR($U$3=0,$U$8=0),0,IFERROR(INDEX(ПАКЕТИ_ЦІНИ,MATCH($U$10&"|Будні",ПАКЕТИ_КЛЮЧ,0),$U$3),0)) -> 0 | AC12: =IF(OR($U$3=0,$U$8=0),0,IFERROR(INDEX(ПАКЕТИ_ЦІНИ,MATCH($U$10&"|Вихідні",ПАКЕТИ_КЛЮЧ,0),$U$3),0)) -> 0 | AD12: =IF(OR($U$3=0,$U$9=0,$A12=""),0,IFERROR(INDEX(SPA_ЦІНИ,MATCH(INDEX(ДОВ_SPA,MATCH($A12,КАТЕГОРІЇ,0)),SPA_РІВЕНЬ,0),$U$3),0)) -> 0 | AE12: =IF(OR($U$3=0,$U$9=0,$A12=""),0,IFERROR(INDEX(SPA_ЦІНИ,MATCH(INDEX(ДОВ_SPA,MATCH($A12,КАТЕГОРІЇ,0)),SPA_РІВЕНЬ,0),$U$3+1),0)) -> 0 | AF12: =IF(OR($A12="",W12=0,AND($U$8=1,AB12=0),AND($U$9=1,AD12=0)),0,1) -> 0 | AG12: =IF(OR($A12="",X12=0,AND($U$8=1,AC12=0),AND($U$9=1,AE12=0)),0,1) -> 0
A13: =IF('Довідник категорій'!B9="","",'Довідник категорій'!B9) | B13: =IF($A13="","",IFERROR(INDEX(ДОВ_BOOKING,MATCH($A13,КАТЕГОРІЇ,0)),"")) | C13: =IF($A13="","",IFERROR(INDEX(ДОВ_КОД,MATCH($A13,КАТЕГОРІЇ,0)),"")) | D13: =IF(OR($AF13=0,D$8>$Y13),"",ROUND($W13*(1-$U$5)/ОКРУГЛЕННЯ,0)*ОКРУГЛЕННЯ+MAX(0,D$8-$Z13)*$AA13*(1-$U$5)+D$8*$AB13*(1-$U$5*$U$6)+$AD13*(1-$U$5*$U$7)) | E13: =IF(OR($AF13=0,E$8>$Y13),"",ROUND($W13*(1-$U$5)/ОКРУГЛЕННЯ,0)*ОКРУГЛЕННЯ+MAX(0,E$8-$Z13)*$AA13*(1-$U$5)+E$8*$AB13*(1-$U$5*$U$6)+$AD13*(1-$U$5*$U$7)) | F13: =IF(OR($AF13=0,F$8>$Y13),"",ROUND($W13*(1-$U$5)/ОКРУГЛЕННЯ,0)*ОКРУГЛЕННЯ+MAX(0,F$8-$Z13)*$AA13*(1-$U$5)+F$8*$AB13*(1-$U$5*$U$6)+$AD13*(1-$U$5*$U$7)) | G13: =IF(OR($AF13=0,G$8>$Y13),"",ROUND($W13*(1-$U$5)/ОКРУГЛЕННЯ,0)*ОКРУГЛЕННЯ+MAX(0,G$8-$Z13)*$AA13*(1-$U$5)+G$8*$AB13*(1-$U$5*$U$6)+$AD13*(1-$U$5*$U$7)) | H13: =IF(OR($AF13=0,H$8>$Y13),"",ROUND($W13*(1-$U$5)/ОКРУГЛЕННЯ,0)*ОКРУГЛЕННЯ+MAX(0,H$8-$Z13)*$AA13*(1-$U$5)+H$8*$AB13*(1-$U$5*$U$6)+$AD13*(1-$U$5*$U$7)) | I13: =IF(OR($AF13=0,I$8>$Y13),"",ROUND($W13*(1-$U$5)/ОКРУГЛЕННЯ,0)*ОКРУГЛЕННЯ+MAX(0,I$8-$Z13)*$AA13*(1-$U$5)+I$8*$AB13*(1-$U$5*$U$6)+$AD13*(1-$U$5*$U$7)) | J13: =IF(OR($AF13=0,J$8>$Y13),"",ROUND($W13*(1-$U$5)/ОКРУГЛЕННЯ,0)*ОКРУГЛЕННЯ+MAX(0,J$8-$Z13)*$AA13*(1-$U$5)+J$8*$AB13*(1-$U$5*$U$6)+$AD13*(1-$U$5*$U$7)) | K13: =IF(OR($AF13=0,K$8>$Y13),"",ROUND($W13*(1-$U$5)/ОКРУГЛЕННЯ,0)*ОКРУГЛЕННЯ+MAX(0,K$8-$Z13)*$AA13*(1-$U$5)+K$8*$AB13*(1-$U$5*$U$6)+$AD13*(1-$U$5*$U$7)) | M13: =IF(OR($AG13=0,M$8>$Y13),"",ROUND($X13*(1-$U$5)/ОКРУГЛЕННЯ,0)*ОКРУГЛЕННЯ+MAX(0,M$8-$Z13)*$AA13*(1-$U$5)+M$8*$AC13*(1-$U$5*$U$6)+$AE13*(1-$U$5*$U$7)) | N13: =IF(OR($AG13=0,N$8>$Y13),"",ROUND($X13*(1-$U$5)/ОКРУГЛЕННЯ,0)*ОКРУГЛЕННЯ+MAX(0,N$8-$Z13)*$AA13*(1-$U$5)+N$8*$AC13*(1-$U$5*$U$6)+$AE13*(1-$U$5*$U$7)) | O13: =IF(OR($AG13=0,O$8>$Y13),"",ROUND($X13*(1-$U$5)/ОКРУГЛЕННЯ,0)*ОКРУГЛЕННЯ+MAX(0,O$8-$Z13)*$AA13*(1-$U$5)+O$8*$AC13*(1-$U$5*$U$6)+$AE13*(1-$U$5*$U$7)) | P13: =IF(OR($AG13=0,P$8>$Y13),"",ROUND($X13*(1-$U$5)/ОКРУГЛЕННЯ,0)*ОКРУГЛЕННЯ+MAX(0,P$8-$Z13)*$AA13*(1-$U$5)+P$8*$AC13*(1-$U$5*$U$6)+$AE13*(1-$U$5*$U$7)) | Q13: =IF(OR($AG13=0,Q$8>$Y13),"",ROUND($X13*(1-$U$5)/ОКРУГЛЕННЯ,0)*ОКРУГЛЕННЯ+MAX(0,Q$8-$Z13)*$AA13*(1-$U$5)+Q$8*$AC13*(1-$U$5*$U$6)+$AE13*(1-$U$5*$U$7)) | R13: =IF(OR($AG13=0,R$8>$Y13),"",ROUND($X13*(1-$U$5)/ОКРУГЛЕННЯ,0)*ОКРУГЛЕННЯ+MAX(0,R$8-$Z13)*$AA13*(1-$U$5)+R$8*$AC13*(1-$U$5*$U$6)+$AE13*(1-$U$5*$U$7)) | S13: =IF(OR($AG13=0,S$8>$Y13),"",ROUND($X13*(1-$U$5)/ОКРУГЛЕННЯ,0)*ОКРУГЛЕННЯ+MAX(0,S$8-$Z13)*$AA13*(1-$U$5)+S$8*$AC13*(1-$U$5*$U$6)+$AE13*(1-$U$5*$U$7)) | T13: =IF(OR($AG13=0,T$8>$Y13),"",ROUND($X13*(1-$U$5)/ОКРУГЛЕННЯ,0)*ОКРУГЛЕННЯ+MAX(0,T$8-$Z13)*$AA13*(1-$U$5)+T$8*$AC13*(1-$U$5*$U$6)+$AE13*(1-$U$5*$U$7)) | U13: =IF($U$3=0,0,SUMPRODUCT(--(INDEX(БАЗА_ЦІНИ,0,$U$3)<>""))) -> 3 | V13: заповнених баз | W13: =IF(OR($U$3=0,$A13=""),0,IFERROR(INDEX(БАЗА_ЦІНИ,MATCH($A13,БАЗА_КАТ,0),$U$3),0)) -> 0 | X13: =IF(OR($U$3=0,$A13=""),0,IFERROR(INDEX(БАЗА_ЦІНИ,MATCH($A13,БАЗА_КАТ,0),$U$3+1),0)) -> 0 | Y13: =IF($A13="",0,IFERROR(INDEX(ДОВ_МАКС,MATCH($A13,КАТЕГОРІЇ,0)),0)) -> 0 | Z13: =IF($A13="",0,IFERROR(INDEX(ДОВ_ВКЛ,MATCH($A13,КАТЕГОРІЇ,0)),0)) -> 0 | AA13: =IF($A13="",0,IFERROR(INDEX(ДОВ_ДОПЛ_ДОР,MATCH($A13,КАТЕГОРІЇ,0)),0)) -> 0 | AB13: =IF(OR($U$3=0,$U$8=0),0,IFERROR(INDEX(ПАКЕТИ_ЦІНИ,MATCH($U$10&"|Будні",ПАКЕТИ_КЛЮЧ,0),$U$3),0)) -> 0 | AC13: =IF(OR($U$3=0,$U$8=0),0,IFERROR(INDEX(ПАКЕТИ_ЦІНИ,MATCH($U$10&"|Вихідні",ПАКЕТИ_КЛЮЧ,0),$U$3),0)) -> 0 | AD13: =IF(OR($U$3=0,$U$9=0,$A13=""),0,IFERROR(INDEX(SPA_ЦІНИ,MATCH(INDEX(ДОВ_SPA,MATCH($A13,КАТЕГОРІЇ,0)),SPA_РІВЕНЬ,0),$U$3),0)) -> 0 | AE13: =IF(OR($U$3=0,$U$9=0,$A13=""),0,IFERROR(INDEX(SPA_ЦІНИ,MATCH(INDEX(ДОВ_SPA,MATCH($A13,КАТЕГОРІЇ,0)),SPA_РІВЕНЬ,0),$U$3+1),0)) -> 0 | AF13: =IF(OR($A13="",W13=0,AND($U$8=1,AB13=0),AND($U$9=1,AD13=0)),0,1) -> 0 | AG13: =IF(OR($A13="",X13=0,AND($U$8=1,AC13=0),AND($U$9=1,AE13=0)),0,1) -> 0
A14: =IF('Довідник категорій'!B10="","",'Довідник категорій'!B10) | B14: =IF($A14="","",IFERROR(INDEX(ДОВ_BOOKING,MATCH($A14,КАТЕГОРІЇ,0)),"")) | C14: =IF($A14="","",IFERROR(INDEX(ДОВ_КОД,MATCH($A14,КАТЕГОРІЇ,0)),"")) | D14: =IF(OR($AF14=0,D$8>$Y14),"",ROUND($W14*(1-$U$5)/ОКРУГЛЕННЯ,0)*ОКРУГЛЕННЯ+MAX(0,D$8-$Z14)*$AA14*(1-$U$5)+D$8*$AB14*(1-$U$5*$U$6)+$AD14*(1-$U$5*$U$7)) | E14: =IF(OR($AF14=0,E$8>$Y14),"",ROUND($W14*(1-$U$5)/ОКРУГЛЕННЯ,0)*ОКРУГЛЕННЯ+MAX(0,E$8-$Z14)*$AA14*(1-$U$5)+E$8*$AB14*(1-$U$5*$U$6)+$AD14*(1-$U$5*$U$7)) | F14: =IF(OR($AF14=0,F$8>$Y14),"",ROUND($W14*(1-$U$5)/ОКРУГЛЕННЯ,0)*ОКРУГЛЕННЯ+MAX(0,F$8-$Z14)*$AA14*(1-$U$5)+F$8*$AB14*(1-$U$5*$U$6)+$AD14*(1-$U$5*$U$7)) | G14: =IF(OR($AF14=0,G$8>$Y14),"",ROUND($W14*(1-$U$5)/ОКРУГЛЕННЯ,0)*ОКРУГЛЕННЯ+MAX(0,G$8-$Z14)*$AA14*(1-$U$5)+G$8*$AB14*(1-$U$5*$U$6)+$AD14*(1-$U$5*$U$7)) | H14: =IF(OR($AF14=0,H$8>$Y14),"",ROUND($W14*(1-$U$5)/ОКРУГЛЕННЯ,0)*ОКРУГЛЕННЯ+MAX(0,H$8-$Z14)*$AA14*(1-$U$5)+H$8*$AB14*(1-$U$5*$U$6)+$AD14*(1-$U$5*$U$7)) | I14: =IF(OR($AF14=0,I$8>$Y14),"",ROUND($W14*(1-$U$5)/ОКРУГЛЕННЯ,0)*ОКРУГЛЕННЯ+MAX(0,I$8-$Z14)*$AA14*(1-$U$5)+I$8*$AB14*(1-$U$5*$U$6)+$AD14*(1-$U$5*$U$7)) | J14: =IF(OR($AF14=0,J$8>$Y14),"",ROUND($W14*(1-$U$5)/ОКРУГЛЕННЯ,0)*ОКРУГЛЕННЯ+MAX(0,J$8-$Z14)*$AA14*(1-$U$5)+J$8*$AB14*(1-$U$5*$U$6)+$AD14*(1-$U$5*$U$7)) | K14: =IF(OR($AF14=0,K$8>$Y14),"",ROUND($W14*(1-$U$5)/ОКРУГЛЕННЯ,0)*ОКРУГЛЕННЯ+MAX(0,K$8-$Z14)*$AA14*(1-$U$5)+K$8*$AB14*(1-$U$5*$U$6)+$AD14*(1-$U$5*$U$7)) | M14: =IF(OR($AG14=0,M$8>$Y14),"",ROUND($X14*(1-$U$5)/ОКРУГЛЕННЯ,0)*ОКРУГЛЕННЯ+MAX(0,M$8-$Z14)*$AA14*(1-$U$5)+M$8*$AC14*(1-$U$5*$U$6)+$AE14*(1-$U$5*$U$7)) | N14: =IF(OR($AG14=0,N$8>$Y14),"",ROUND($X14*(1-$U$5)/ОКРУГЛЕННЯ,0)*ОКРУГЛЕННЯ+MAX(0,N$8-$Z14)*$AA14*(1-$U$5)+N$8*$AC14*(1-$U$5*$U$6)+$AE14*(1-$U$5*$U$7)) | O14: =IF(OR($AG14=0,O$8>$Y14),"",ROUND($X14*(1-$U$5)/ОКРУГЛЕННЯ,0)*ОКРУГЛЕННЯ+MAX(0,O$8-$Z14)*$AA14*(1-$U$5)+O$8*$AC14*(1-$U$5*$U$6)+$AE14*(1-$U$5*$U$7)) | P14: =IF(OR($AG14=0,P$8>$Y14),"",ROUND($X14*(1-$U$5)/ОКРУГЛЕННЯ,0)*ОКРУГЛЕННЯ+MAX(0,P$8-$Z14)*$AA14*(1-$U$5)+P$8*$AC14*(1-$U$5*$U$6)+$AE14*(1-$U$5*$U$7)) | Q14: =IF(OR($AG14=0,Q$8>$Y14),"",ROUND($X14*(1-$U$5)/ОКРУГЛЕННЯ,0)*ОКРУГЛЕННЯ+MAX(0,Q$8-$Z14)*$AA14*(1-$U$5)+Q$8*$AC14*(1-$U$5*$U$6)+$AE14*(1-$U$5*$U$7)) | R14: =IF(OR($AG14=0,R$8>$Y14),"",ROUND($X14*(1-$U$5)/ОКРУГЛЕННЯ,0)*ОКРУГЛЕННЯ+MAX(0,R$8-$Z14)*$AA14*(1-$U$5)+R$8*$AC14*(1-$U$5*$U$6)+$AE14*(1-$U$5*$U$7)) | S14: =IF(OR($AG14=0,S$8>$Y14),"",ROUND($X14*(1-$U$5)/ОКРУГЛЕННЯ,0)*ОКРУГЛЕННЯ+MAX(0,S$8-$Z14)*$AA14*(1-$U$5)+S$8*$AC14*(1-$U$5*$U$6)+$AE14*(1-$U$5*$U$7)) | T14: =IF(OR($AG14=0,T$8>$Y14),"",ROUND($X14*(1-$U$5)/ОКРУГЛЕННЯ,0)*ОКРУГЛЕННЯ+MAX(0,T$8-$Z14)*$AA14*(1-$U$5)+T$8*$AC14*(1-$U$5*$U$6)+$AE14*(1-$U$5*$U$7)) | W14: =IF(OR($U$3=0,$A14=""),0,IFERROR(INDEX(БАЗА_ЦІНИ,MATCH($A14,БАЗА_КАТ,0),$U$3),0)) -> 0 | X14: =IF(OR($U$3=0,$A14=""),0,IFERROR(INDEX(БАЗА_ЦІНИ,MATCH($A14,БАЗА_КАТ,0),$U$3+1),0)) -> 0 | Y14: =IF($A14="",0,IFERROR(INDEX(ДОВ_МАКС,MATCH($A14,КАТЕГОРІЇ,0)),0)) -> 0 | Z14: =IF($A14="",0,IFERROR(INDEX(ДОВ_ВКЛ,MATCH($A14,КАТЕГОРІЇ,0)),0)) -> 0 | AA14: =IF($A14="",0,IFERROR(INDEX(ДОВ_ДОПЛ_ДОР,MATCH($A14,КАТЕГОРІЇ,0)),0)) -> 0 | AB14: =IF(OR($U$3=0,$U$8=0),0,IFERROR(INDEX(ПАКЕТИ_ЦІНИ,MATCH($U$10&"|Будні",ПАКЕТИ_КЛЮЧ,0),$U$3),0)) -> 0 | AC14: =IF(OR($U$3=0,$U$8=0),0,IFERROR(INDEX(ПАКЕТИ_ЦІНИ,MATCH($U$10&"|Вихідні",ПАКЕТИ_КЛЮЧ,0),$U$3),0)) -> 0 | AD14: =IF(OR($U$3=0,$U$9=0,$A14=""),0,IFERROR(INDEX(SPA_ЦІНИ,MATCH(INDEX(ДОВ_SPA,MATCH($A14,КАТЕГОРІЇ,0)),SPA_РІВЕНЬ,0),$U$3),0)) -> 0 | AE14: =IF(OR($U$3=0,$U$9=0,$A14=""),0,IFERROR(INDEX(SPA_ЦІНИ,MATCH(INDEX(ДОВ_SPA,MATCH($A14,КАТЕГОРІЇ,0)),SPA_РІВЕНЬ,0),$U$3+1),0)) -> 0 | AF14: =IF(OR($A14="",W14=0,AND($U$8=1,AB14=0),AND($U$9=1,AD14=0)),0,1) -> 0 | AG14: =IF(OR($A14="",X14=0,AND($U$8=1,AC14=0),AND($U$9=1,AE14=0)),0,1) -> 0
A15: =IF('Довідник категорій'!B11="","",'Довідник категорій'!B11) | B15: =IF($A15="","",IFERROR(INDEX(ДОВ_BOOKING,MATCH($A15,КАТЕГОРІЇ,0)),"")) | C15: =IF($A15="","",IFERROR(INDEX(ДОВ_КОД,MATCH($A15,КАТЕГОРІЇ,0)),"")) | D15: =IF(OR($AF15=0,D$8>$Y15),"",ROUND($W15*(1-$U$5)/ОКРУГЛЕННЯ,0)*ОКРУГЛЕННЯ+MAX(0,D$8-$Z15)*$AA15*(1-$U$5)+D$8*$AB15*(1-$U$5*$U$6)+$AD15*(1-$U$5*$U$7)) | E15: =IF(OR($AF15=0,E$8>$Y15),"",ROUND($W15*(1-$U$5)/ОКРУГЛЕННЯ,0)*ОКРУГЛЕННЯ+MAX(0,E$8-$Z15)*$AA15*(1-$U$5)+E$8*$AB15*(1-$U$5*$U$6)+$AD15*(1-$U$5*$U$7)) | F15: =IF(OR($AF15=0,F$8>$Y15),"",ROUND($W15*(1-$U$5)/ОКРУГЛЕННЯ,0)*ОКРУГЛЕННЯ+MAX(0,F$8-$Z15)*$AA15*(1-$U$5)+F$8*$AB15*(1-$U$5*$U$6)+$AD15*(1-$U$5*$U$7)) | G15: =IF(OR($AF15=0,G$8>$Y15),"",ROUND($W15*(1-$U$5)/ОКРУГЛЕННЯ,0)*ОКРУГЛЕННЯ+MAX(0,G$8-$Z15)*$AA15*(1-$U$5)+G$8*$AB15*(1-$U$5*$U$6)+$AD15*(1-$U$5*$U$7)) | H15: =IF(OR($AF15=0,H$8>$Y15),"",ROUND($W15*(1-$U$5)/ОКРУГЛЕННЯ,0)*ОКРУГЛЕННЯ+MAX(0,H$8-$Z15)*$AA15*(1-$U$5)+H$8*$AB15*(1-$U$5*$U$6)+$AD15*(1-$U$5*$U$7)) | I15: =IF(OR($AF15=0,I$8>$Y15),"",ROUND($W15*(1-$U$5)/ОКРУГЛЕННЯ,0)*ОКРУГЛЕННЯ+MAX(0,I$8-$Z15)*$AA15*(1-$U$5)+I$8*$AB15*(1-$U$5*$U$6)+$AD15*(1-$U$5*$U$7)) | J15: =IF(OR($AF15=0,J$8>$Y15),"",ROUND($W15*(1-$U$5)/ОКРУГЛЕННЯ,0)*ОКРУГЛЕННЯ+MAX(0,J$8-$Z15)*$AA15*(1-$U$5)+J$8*$AB15*(1-$U$5*$U$6)+$AD15*(1-$U$5*$U$7)) | K15: =IF(OR($AF15=0,K$8>$Y15),"",ROUND($W15*(1-$U$5)/ОКРУГЛЕННЯ,0)*ОКРУГЛЕННЯ+MAX(0,K$8-$Z15)*$AA15*(1-$U$5)+K$8*$AB15*(1-$U$5*$U$6)+$AD15*(1-$U$5*$U$7)) | M15: =IF(OR($AG15=0,M$8>$Y15),"",ROUND($X15*(1-$U$5)/ОКРУГЛЕННЯ,0)*ОКРУГЛЕННЯ+MAX(0,M$8-$Z15)*$AA15*(1-$U$5)+M$8*$AC15*(1-$U$5*$U$6)+$AE15*(1-$U$5*$U$7)) | N15: =IF(OR($AG15=0,N$8>$Y15),"",ROUND($X15*(1-$U$5)/ОКРУГЛЕННЯ,0)*ОКРУГЛЕННЯ+MAX(0,N$8-$Z15)*$AA15*(1-$U$5)+N$8*$AC15*(1-$U$5*$U$6)+$AE15*(1-$U$5*$U$7)) | O15: =IF(OR($AG15=0,O$8>$Y15),"",ROUND($X15*(1-$U$5)/ОКРУГЛЕННЯ,0)*ОКРУГЛЕННЯ+MAX(0,O$8-$Z15)*$AA15*(1-$U$5)+O$8*$AC15*(1-$U$5*$U$6)+$AE15*(1-$U$5*$U$7)) | P15: =IF(OR($AG15=0,P$8>$Y15),"",ROUND($X15*(1-$U$5)/ОКРУГЛЕННЯ,0)*ОКРУГЛЕННЯ+MAX(0,P$8-$Z15)*$AA15*(1-$U$5)+P$8*$AC15*(1-$U$5*$U$6)+$AE15*(1-$U$5*$U$7)) | Q15: =IF(OR($AG15=0,Q$8>$Y15),"",ROUND($X15*(1-$U$5)/ОКРУГЛЕННЯ,0)*ОКРУГЛЕННЯ+MAX(0,Q$8-$Z15)*$AA15*(1-$U$5)+Q$8*$AC15*(1-$U$5*$U$6)+$AE15*(1-$U$5*$U$7)) | R15: =IF(OR($AG15=0,R$8>$Y15),"",ROUND($X15*(1-$U$5)/ОКРУГЛЕННЯ,0)*ОКРУГЛЕННЯ+MAX(0,R$8-$Z15)*$AA15*(1-$U$5)+R$8*$AC15*(1-$U$5*$U$6)+$AE15*(1-$U$5*$U$7)) | S15: =IF(OR($AG15=0,S$8>$Y15),"",ROUND($X15*(1-$U$5)/ОКРУГЛЕННЯ,0)*ОКРУГЛЕННЯ+MAX(0,S$8-$Z15)*$AA15*(1-$U$5)+S$8*$AC15*(1-$U$5*$U$6)+$AE15*(1-$U$5*$U$7)) | T15: =IF(OR($AG15=0,T$8>$Y15),"",ROUND($X15*(1-$U$5)/ОКРУГЛЕННЯ,0)*ОКРУГЛЕННЯ+MAX(0,T$8-$Z15)*$AA15*(1-$U$5)+T$8*$AC15*(1-$U$5*$U$6)+$AE15*(1-$U$5*$U$7)) | W15: =IF(OR($U$3=0,$A15=""),0,IFERROR(INDEX(БАЗА_ЦІНИ,MATCH($A15,БАЗА_КАТ,0),$U$3),0)) -> 0 | X15: =IF(OR($U$3=0,$A15=""),0,IFERROR(INDEX(БАЗА_ЦІНИ,MATCH($A15,БАЗА_КАТ,0),$U$3+1),0)) -> 0 | Y15: =IF($A15="",0,IFERROR(INDEX(ДОВ_МАКС,MATCH($A15,КАТЕГОРІЇ,0)),0)) -> 0 | Z15: =IF($A15="",0,IFERROR(INDEX(ДОВ_ВКЛ,MATCH($A15,КАТЕГОРІЇ,0)),0)) -> 0 | AA15: =IF($A15="",0,IFERROR(INDEX(ДОВ_ДОПЛ_ДОР,MATCH($A15,КАТЕГОРІЇ,0)),0)) -> 0 | AB15: =IF(OR($U$3=0,$U$8=0),0,IFERROR(INDEX(ПАКЕТИ_ЦІНИ,MATCH($U$10&"|Будні",ПАКЕТИ_КЛЮЧ,0),$U$3),0)) -> 0 | AC15: =IF(OR($U$3=0,$U$8=0),0,IFERROR(INDEX(ПАКЕТИ_ЦІНИ,MATCH($U$10&"|Вихідні",ПАКЕТИ_КЛЮЧ,0),$U$3),0)) -> 0 | AD15: =IF(OR($U$3=0,$U$9=0,$A15=""),0,IFERROR(INDEX(SPA_ЦІНИ,MATCH(INDEX(ДОВ_SPA,MATCH($A15,КАТЕГОРІЇ,0)),SPA_РІВЕНЬ,0),$U$3),0)) -> 0 | AE15: =IF(OR($U$3=0,$U$9=0,$A15=""),0,IFERROR(INDEX(SPA_ЦІНИ,MATCH(INDEX(ДОВ_SPA,MATCH($A15,КАТЕГОРІЇ,0)),SPA_РІВЕНЬ,0),$U$3+1),0)) -> 0 | AF15: =IF(OR($A15="",W15=0,AND($U$8=1,AB15=0),AND($U$9=1,AD15=0)),0,1) -> 0 | AG15: =IF(OR($A15="",X15=0,AND($U$8=1,AC15=0),AND($U$9=1,AE15=0)),0,1) -> 0
A16: =IF('Довідник категорій'!B12="","",'Довідник категорій'!B12) | B16: =IF($A16="","",IFERROR(INDEX(ДОВ_BOOKING,MATCH($A16,КАТЕГОРІЇ,0)),"")) | C16: =IF($A16="","",IFERROR(INDEX(ДОВ_КОД,MATCH($A16,КАТЕГОРІЇ,0)),"")) | D16: =IF(OR($AF16=0,D$8>$Y16),"",ROUND($W16*(1-$U$5)/ОКРУГЛЕННЯ,0)*ОКРУГЛЕННЯ+MAX(0,D$8-$Z16)*$AA16*(1-$U$5)+D$8*$AB16*(1-$U$5*$U$6)+$AD16*(1-$U$5*$U$7)) | E16: =IF(OR($AF16=0,E$8>$Y16),"",ROUND($W16*(1-$U$5)/ОКРУГЛЕННЯ,0)*ОКРУГЛЕННЯ+MAX(0,E$8-$Z16)*$AA16*(1-$U$5)+E$8*$AB16*(1-$U$5*$U$6)+$AD16*(1-$U$5*$U$7)) | F16: =IF(OR($AF16=0,F$8>$Y16),"",ROUND($W16*(1-$U$5)/ОКРУГЛЕННЯ,0)*ОКРУГЛЕННЯ+MAX(0,F$8-$Z16)*$AA16*(1-$U$5)+F$8*$AB16*(1-$U$5*$U$6)+$AD16*(1-$U$5*$U$7)) | G16: =IF(OR($AF16=0,G$8>$Y16),"",ROUND($W16*(1-$U$5)/ОКРУГЛЕННЯ,0)*ОКРУГЛЕННЯ+MAX(0,G$8-$Z16)*$AA16*(1-$U$5)+G$8*$AB16*(1-$U$5*$U$6)+$AD16*(1-$U$5*$U$7)) | H16: =IF(OR($AF16=0,H$8>$Y16),"",ROUND($W16*(1-$U$5)/ОКРУГЛЕННЯ,0)*ОКРУГЛЕННЯ+MAX(0,H$8-$Z16)*$AA16*(1-$U$5)+H$8*$AB16*(1-$U$5*$U$6)+$AD16*(1-$U$5*$U$7)) | I16: =IF(OR($AF16=0,I$8>$Y16),"",ROUND($W16*(1-$U$5)/ОКРУГЛЕННЯ,0)*ОКРУГЛЕННЯ+MAX(0,I$8-$Z16)*$AA16*(1-$U$5)+I$8*$AB16*(1-$U$5*$U$6)+$AD16*(1-$U$5*$U$7)) | J16: =IF(OR($AF16=0,J$8>$Y16),"",ROUND($W16*(1-$U$5)/ОКРУГЛЕННЯ,0)*ОКРУГЛЕННЯ+MAX(0,J$8-$Z16)*$AA16*(1-$U$5)+J$8*$AB16*(1-$U$5*$U$6)+$AD16*(1-$U$5*$U$7)) | K16: =IF(OR($AF16=0,K$8>$Y16),"",ROUND($W16*(1-$U$5)/ОКРУГЛЕННЯ,0)*ОКРУГЛЕННЯ+MAX(0,K$8-$Z16)*$AA16*(1-$U$5)+K$8*$AB16*(1-$U$5*$U$6)+$AD16*(1-$U$5*$U$7)) | M16: =IF(OR($AG16=0,M$8>$Y16),"",ROUND($X16*(1-$U$5)/ОКРУГЛЕННЯ,0)*ОКРУГЛЕННЯ+MAX(0,M$8-$Z16)*$AA16*(1-$U$5)+M$8*$AC16*(1-$U$5*$U$6)+$AE16*(1-$U$5*$U$7)) | N16: =IF(OR($AG16=0,N$8>$Y16),"",ROUND($X16*(1-$U$5)/ОКРУГЛЕННЯ,0)*ОКРУГЛЕННЯ+MAX(0,N$8-$Z16)*$AA16*(1-$U$5)+N$8*$AC16*(1-$U$5*$U$6)+$AE16*(1-$U$5*$U$7)) | O16: =IF(OR($AG16=0,O$8>$Y16),"",ROUND($X16*(1-$U$5)/ОКРУГЛЕННЯ,0)*ОКРУГЛЕННЯ+MAX(0,O$8-$Z16)*$AA16*(1-$U$5)+O$8*$AC16*(1-$U$5*$U$6)+$AE16*(1-$U$5*$U$7)) | P16: =IF(OR($AG16=0,P$8>$Y16),"",ROUND($X16*(1-$U$5)/ОКРУГЛЕННЯ,0)*ОКРУГЛЕННЯ+MAX(0,P$8-$Z16)*$AA16*(1-$U$5)+P$8*$AC16*(1-$U$5*$U$6)+$AE16*(1-$U$5*$U$7)) | Q16: =IF(OR($AG16=0,Q$8>$Y16),"",ROUND($X16*(1-$U$5)/ОКРУГЛЕННЯ,0)*ОКРУГЛЕННЯ+MAX(0,Q$8-$Z16)*$AA16*(1-$U$5)+Q$8*$AC16*(1-$U$5*$U$6)+$AE16*(1-$U$5*$U$7)) | R16: =IF(OR($AG16=0,R$8>$Y16),"",ROUND($X16*(1-$U$5)/ОКРУГЛЕННЯ,0)*ОКРУГЛЕННЯ+MAX(0,R$8-$Z16)*$AA16*(1-$U$5)+R$8*$AC16*(1-$U$5*$U$6)+$AE16*(1-$U$5*$U$7)) | S16: =IF(OR($AG16=0,S$8>$Y16),"",ROUND($X16*(1-$U$5)/ОКРУГЛЕННЯ,0)*ОКРУГЛЕННЯ+MAX(0,S$8-$Z16)*$AA16*(1-$U$5)+S$8*$AC16*(1-$U$5*$U$6)+$AE16*(1-$U$5*$U$7)) | T16: =IF(OR($AG16=0,T$8>$Y16),"",ROUND($X16*(1-$U$5)/ОКРУГЛЕННЯ,0)*ОКРУГЛЕННЯ+MAX(0,T$8-$Z16)*$AA16*(1-$U$5)+T$8*$AC16*(1-$U$5*$U$6)+$AE16*(1-$U$5*$U$7)) | W16: =IF(OR($U$3=0,$A16=""),0,IFERROR(INDEX(БАЗА_ЦІНИ,MATCH($A16,БАЗА_КАТ,0),$U$3),0)) -> 0 | X16: =IF(OR($U$3=0,$A16=""),0,IFERROR(INDEX(БАЗА_ЦІНИ,MATCH($A16,БАЗА_КАТ,0),$U$3+1),0)) -> 0 | Y16: =IF($A16="",0,IFERROR(INDEX(ДОВ_МАКС,MATCH($A16,КАТЕГОРІЇ,0)),0)) -> 0 | Z16: =IF($A16="",0,IFERROR(INDEX(ДОВ_ВКЛ,MATCH($A16,КАТЕГОРІЇ,0)),0)) -> 0 | AA16: =IF($A16="",0,IFERROR(INDEX(ДОВ_ДОПЛ_ДОР,MATCH($A16,КАТЕГОРІЇ,0)),0)) -> 0 | AB16: =IF(OR($U$3=0,$U$8=0),0,IFERROR(INDEX(ПАКЕТИ_ЦІНИ,MATCH($U$10&"|Будні",ПАКЕТИ_КЛЮЧ,0),$U$3),0)) -> 0 | AC16: =IF(OR($U$3=0,$U$8=0),0,IFERROR(INDEX(ПАКЕТИ_ЦІНИ,MATCH($U$10&"|Вихідні",ПАКЕТИ_КЛЮЧ,0),$U$3),0)) -> 0 | AD16: =IF(OR($U$3=0,$U$9=0,$A16=""),0,IFERROR(INDEX(SPA_ЦІНИ,MATCH(INDEX(ДОВ_SPA,MATCH($A16,КАТЕГОРІЇ,0)),SPA_РІВЕНЬ,0),$U$3),0)) -> 0 | AE16: =IF(OR($U$3=0,$U$9=0,$A16=""),0,IFERROR(INDEX(SPA_ЦІНИ,MATCH(INDEX(ДОВ_SPA,MATCH($A16,КАТЕГОРІЇ,0)),SPA_РІВЕНЬ,0),$U$3+1),0)) -> 0 | AF16: =IF(OR($A16="",W16=0,AND($U$8=1,AB16=0),AND($U$9=1,AD16=0)),0,1) -> 0 | AG16: =IF(OR($A16="",X16=0,AND($U$8=1,AC16=0),AND($U$9=1,AE16=0)),0,1) -> 0
A17: =IF('Довідник категорій'!B13="","",'Довідник категорій'!B13) | B17: =IF($A17="","",IFERROR(INDEX(ДОВ_BOOKING,MATCH($A17,КАТЕГОРІЇ,0)),"")) | C17: =IF($A17="","",IFERROR(INDEX(ДОВ_КОД,MATCH($A17,КАТЕГОРІЇ,0)),"")) | D17: =IF(OR($AF17=0,D$8>$Y17),"",ROUND($W17*(1-$U$5)/ОКРУГЛЕННЯ,0)*ОКРУГЛЕННЯ+MAX(0,D$8-$Z17)*$AA17*(1-$U$5)+D$8*$AB17*(1-$U$5*$U$6)+$AD17*(1-$U$5*$U$7)) | E17: =IF(OR($AF17=0,E$8>$Y17),"",ROUND($W17*(1-$U$5)/ОКРУГЛЕННЯ,0)*ОКРУГЛЕННЯ+MAX(0,E$8-$Z17)*$AA17*(1-$U$5)+E$8*$AB17*(1-$U$5*$U$6)+$AD17*(1-$U$5*$U$7)) | F17: =IF(OR($AF17=0,F$8>$Y17),"",ROUND($W17*(1-$U$5)/ОКРУГЛЕННЯ,0)*ОКРУГЛЕННЯ+MAX(0,F$8-$Z17)*$AA17*(1-$U$5)+F$8*$AB17*(1-$U$5*$U$6)+$AD17*(1-$U$5*$U$7)) | G17: =IF(OR($AF17=0,G$8>$Y17),"",ROUND($W17*(1-$U$5)/ОКРУГЛЕННЯ,0)*ОКРУГЛЕННЯ+MAX(0,G$8-$Z17)*$AA17*(1-$U$5)+G$8*$AB17*(1-$U$5*$U$6)+$AD17*(1-$U$5*$U$7)) | H17: =IF(OR($AF17=0,H$8>$Y17),"",ROUND($W17*(1-$U$5)/ОКРУГЛЕННЯ,0)*ОКРУГЛЕННЯ+MAX(0,H$8-$Z17)*$AA17*(1-$U$5)+H$8*$AB17*(1-$U$5*$U$6)+$AD17*(1-$U$5*$U$7)) | I17: =IF(OR($AF17=0,I$8>$Y17),"",ROUND($W17*(1-$U$5)/ОКРУГЛЕННЯ,0)*ОКРУГЛЕННЯ+MAX(0,I$8-$Z17)*$AA17*(1-$U$5)+I$8*$AB17*(1-$U$5*$U$6)+$AD17*(1-$U$5*$U$7)) | J17: =IF(OR($AF17=0,J$8>$Y17),"",ROUND($W17*(1-$U$5)/ОКРУГЛЕННЯ,0)*ОКРУГЛЕННЯ+MAX(0,J$8-$Z17)*$AA17*(1-$U$5)+J$8*$AB17*(1-$U$5*$U$6)+$AD17*(1-$U$5*$U$7)) | K17: =IF(OR($AF17=0,K$8>$Y17),"",ROUND($W17*(1-$U$5)/ОКРУГЛЕННЯ,0)*ОКРУГЛЕННЯ+MAX(0,K$8-$Z17)*$AA17*(1-$U$5)+K$8*$AB17*(1-$U$5*$U$6)+$AD17*(1-$U$5*$U$7)) | M17: =IF(OR($AG17=0,M$8>$Y17),"",ROUND($X17*(1-$U$5)/ОКРУГЛЕННЯ,0)*ОКРУГЛЕННЯ+MAX(0,M$8-$Z17)*$AA17*(1-$U$5)+M$8*$AC17*(1-$U$5*$U$6)+$AE17*(1-$U$5*$U$7)) | N17: =IF(OR($AG17=0,N$8>$Y17),"",ROUND($X17*(1-$U$5)/ОКРУГЛЕННЯ,0)*ОКРУГЛЕННЯ+MAX(0,N$8-$Z17)*$AA17*(1-$U$5)+N$8*$AC17*(1-$U$5*$U$6)+$AE17*(1-$U$5*$U$7)) | O17: =IF(OR($AG17=0,O$8>$Y17),"",ROUND($X17*(1-$U$5)/ОКРУГЛЕННЯ,0)*ОКРУГЛЕННЯ+MAX(0,O$8-$Z17)*$AA17*(1-$U$5)+O$8*$AC17*(1-$U$5*$U$6)+$AE17*(1-$U$5*$U$7)) | P17: =IF(OR($AG17=0,P$8>$Y17),"",ROUND($X17*(1-$U$5)/ОКРУГЛЕННЯ,0)*ОКРУГЛЕННЯ+MAX(0,P$8-$Z17)*$AA17*(1-$U$5)+P$8*$AC17*(1-$U$5*$U$6)+$AE17*(1-$U$5*$U$7)) | Q17: =IF(OR($AG17=0,Q$8>$Y17),"",ROUND($X17*(1-$U$5)/ОКРУГЛЕННЯ,0)*ОКРУГЛЕННЯ+MAX(0,Q$8-$Z17)*$AA17*(1-$U$5)+Q$8*$AC17*(1-$U$5*$U$6)+$AE17*(1-$U$5*$U$7)) | R17: =IF(OR($AG17=0,R$8>$Y17),"",ROUND($X17*(1-$U$5)/ОКРУГЛЕННЯ,0)*ОКРУГЛЕННЯ+MAX(0,R$8-$Z17)*$AA17*(1-$U$5)+R$8*$AC17*(1-$U$5*$U$6)+$AE17*(1-$U$5*$U$7)) | S17: =IF(OR($AG17=0,S$8>$Y17),"",ROUND($X17*(1-$U$5)/ОКРУГЛЕННЯ,0)*ОКРУГЛЕННЯ+MAX(0,S$8-$Z17)*$AA17*(1-$U$5)+S$8*$AC17*(1-$U$5*$U$6)+$AE17*(1-$U$5*$U$7)) | T17: =IF(OR($AG17=0,T$8>$Y17),"",ROUND($X17*(1-$U$5)/ОКРУГЛЕННЯ,0)*ОКРУГЛЕННЯ+MAX(0,T$8-$Z17)*$AA17*(1-$U$5)+T$8*$AC17*(1-$U$5*$U$6)+$AE17*(1-$U$5*$U$7)) | W17: =IF(OR($U$3=0,$A17=""),0,IFERROR(INDEX(БАЗА_ЦІНИ,MATCH($A17,БАЗА_КАТ,0),$U$3),0)) -> 0 | X17: =IF(OR($U$3=0,$A17=""),0,IFERROR(INDEX(БАЗА_ЦІНИ,MATCH($A17,БАЗА_КАТ,0),$U$3+1),0)) -> 0 | Y17: =IF($A17="",0,IFERROR(INDEX(ДОВ_МАКС,MATCH($A17,КАТЕГОРІЇ,0)),0)) -> 0 | Z17: =IF($A17="",0,IFERROR(INDEX(ДОВ_ВКЛ,MATCH($A17,КАТЕГОРІЇ,0)),0)) -> 0 | AA17: =IF($A17="",0,IFERROR(INDEX(ДОВ_ДОПЛ_ДОР,MATCH($A17,КАТЕГОРІЇ,0)),0)) -> 0 | AB17: =IF(OR($U$3=0,$U$8=0),0,IFERROR(INDEX(ПАКЕТИ_ЦІНИ,MATCH($U$10&"|Будні",ПАКЕТИ_КЛЮЧ,0),$U$3),0)) -> 0 | AC17: =IF(OR($U$3=0,$U$8=0),0,IFERROR(INDEX(ПАКЕТИ_ЦІНИ,MATCH($U$10&"|Вихідні",ПАКЕТИ_КЛЮЧ,0),$U$3),0)) -> 0 | AD17: =IF(OR($U$3=0,$U$9=0,$A17=""),0,IFERROR(INDEX(SPA_ЦІНИ,MATCH(INDEX(ДОВ_SPA,MATCH($A17,КАТЕГОРІЇ,0)),SPA_РІВЕНЬ,0),$U$3),0)) -> 0 | AE17: =IF(OR($U$3=0,$U$9=0,$A17=""),0,IFERROR(INDEX(SPA_ЦІНИ,MATCH(INDEX(ДОВ_SPA,MATCH($A17,КАТЕГОРІЇ,0)),SPA_РІВЕНЬ,0),$U$3+1),0)) -> 0 | AF17: =IF(OR($A17="",W17=0,AND($U$8=1,AB17=0),AND($U$9=1,AD17=0)),0,1) -> 0 | AG17: =IF(OR($A17="",X17=0,AND($U$8=1,AC17=0),AND($U$9=1,AE17=0)),0,1) -> 0
A18: =IF('Довідник категорій'!B14="","",'Довідник категорій'!B14) | B18: =IF($A18="","",IFERROR(INDEX(ДОВ_BOOKING,MATCH($A18,КАТЕГОРІЇ,0)),"")) | C18: =IF($A18="","",IFERROR(INDEX(ДОВ_КОД,MATCH($A18,КАТЕГОРІЇ,0)),"")) | D18: =IF(OR($AF18=0,D$8>$Y18),"",ROUND($W18*(1-$U$5)/ОКРУГЛЕННЯ,0)*ОКРУГЛЕННЯ+MAX(0,D$8-$Z18)*$AA18*(1-$U$5)+D$8*$AB18*(1-$U$5*$U$6)+$AD18*(1-$U$5*$U$7)) | E18: =IF(OR($AF18=0,E$8>$Y18),"",ROUND($W18*(1-$U$5)/ОКРУГЛЕННЯ,0)*ОКРУГЛЕННЯ+MAX(0,E$8-$Z18)*$AA18*(1-$U$5)+E$8*$AB18*(1-$U$5*$U$6)+$AD18*(1-$U$5*$U$7)) | F18: =IF(OR($AF18=0,F$8>$Y18),"",ROUND($W18*(1-$U$5)/ОКРУГЛЕННЯ,0)*ОКРУГЛЕННЯ+MAX(0,F$8-$Z18)*$AA18*(1-$U$5)+F$8*$AB18*(1-$U$5*$U$6)+$AD18*(1-$U$5*$U$7)) | G18: =IF(OR($AF18=0,G$8>$Y18),"",ROUND($W18*(1-$U$5)/ОКРУГЛЕННЯ,0)*ОКРУГЛЕННЯ+MAX(0,G$8-$Z18)*$AA18*(1-$U$5)+G$8*$AB18*(1-$U$5*$U$6)+$AD18*(1-$U$5*$U$7)) | H18: =IF(OR($AF18=0,H$8>$Y18),"",ROUND($W18*(1-$U$5)/ОКРУГЛЕННЯ,0)*ОКРУГЛЕННЯ+MAX(0,H$8-$Z18)*$AA18*(1-$U$5)+H$8*$AB18*(1-$U$5*$U$6)+$AD18*(1-$U$5*$U$7)) | I18: =IF(OR($AF18=0,I$8>$Y18),"",ROUND($W18*(1-$U$5)/ОКРУГЛЕННЯ,0)*ОКРУГЛЕННЯ+MAX(0,I$8-$Z18)*$AA18*(1-$U$5)+I$8*$AB18*(1-$U$5*$U$6)+$AD18*(1-$U$5*$U$7)) | J18: =IF(OR($AF18=0,J$8>$Y18),"",ROUND($W18*(1-$U$5)/ОКРУГЛЕННЯ,0)*ОКРУГЛЕННЯ+MAX(0,J$8-$Z18)*$AA18*(1-$U$5)+J$8*$AB18*(1-$U$5*$U$6)+$AD18*(1-$U$5*$U$7)) | K18: =IF(OR($AF18=0,K$8>$Y18),"",ROUND($W18*(1-$U$5)/ОКРУГЛЕННЯ,0)*ОКРУГЛЕННЯ+MAX(0,K$8-$Z18)*$AA18*(1-$U$5)+K$8*$AB18*(1-$U$5*$U$6)+$AD18*(1-$U$5*$U$7)) | M18: =IF(OR($AG18=0,M$8>$Y18),"",ROUND($X18*(1-$U$5)/ОКРУГЛЕННЯ,0)*ОКРУГЛЕННЯ+MAX(0,M$8-$Z18)*$AA18*(1-$U$5)+M$8*$AC18*(1-$U$5*$U$6)+$AE18*(1-$U$5*$U$7)) | N18: =IF(OR($AG18=0,N$8>$Y18),"",ROUND($X18*(1-$U$5)/ОКРУГЛЕННЯ,0)*ОКРУГЛЕННЯ+MAX(0,N$8-$Z18)*$AA18*(1-$U$5)+N$8*$AC18*(1-$U$5*$U$6)+$AE18*(1-$U$5*$U$7)) | O18: =IF(OR($AG18=0,O$8>$Y18),"",ROUND($X18*(1-$U$5)/ОКРУГЛЕННЯ,0)*ОКРУГЛЕННЯ+MAX(0,O$8-$Z18)*$AA18*(1-$U$5)+O$8*$AC18*(1-$U$5*$U$6)+$AE18*(1-$U$5*$U$7)) | P18: =IF(OR($AG18=0,P$8>$Y18),"",ROUND($X18*(1-$U$5)/ОКРУГЛЕННЯ,0)*ОКРУГЛЕННЯ+MAX(0,P$8-$Z18)*$AA18*(1-$U$5)+P$8*$AC18*(1-$U$5*$U$6)+$AE18*(1-$U$5*$U$7)) | Q18: =IF(OR($AG18=0,Q$8>$Y18),"",ROUND($X18*(1-$U$5)/ОКРУГЛЕННЯ,0)*ОКРУГЛЕННЯ+MAX(0,Q$8-$Z18)*$AA18*(1-$U$5)+Q$8*$AC18*(1-$U$5*$U$6)+$AE18*(1-$U$5*$U$7)) | R18: =IF(OR($AG18=0,R$8>$Y18),"",ROUND($X18*(1-$U$5)/ОКРУГЛЕННЯ,0)*ОКРУГЛЕННЯ+MAX(0,R$8-$Z18)*$AA18*(1-$U$5)+R$8*$AC18*(1-$U$5*$U$6)+$AE18*(1-$U$5*$U$7)) | S18: =IF(OR($AG18=0,S$8>$Y18),"",ROUND($X18*(1-$U$5)/ОКРУГЛЕННЯ,0)*ОКРУГЛЕННЯ+MAX(0,S$8-$Z18)*$AA18*(1-$U$5)+S$8*$AC18*(1-$U$5*$U$6)+$AE18*(1-$U$5*$U$7)) | T18: =IF(OR($AG18=0,T$8>$Y18),"",ROUND($X18*(1-$U$5)/ОКРУГЛЕННЯ,0)*ОКРУГЛЕННЯ+MAX(0,T$8-$Z18)*$AA18*(1-$U$5)+T$8*$AC18*(1-$U$5*$U$6)+$AE18*(1-$U$5*$U$7)) | W18: =IF(OR($U$3=0,$A18=""),0,IFERROR(INDEX(БАЗА_ЦІНИ,MATCH($A18,БАЗА_КАТ,0),$U$3),0)) -> 0 | X18: =IF(OR($U$3=0,$A18=""),0,IFERROR(INDEX(БАЗА_ЦІНИ,MATCH($A18,БАЗА_КАТ,0),$U$3+1),0)) -> 0 | Y18: =IF($A18="",0,IFERROR(INDEX(ДОВ_МАКС,MATCH($A18,КАТЕГОРІЇ,0)),0)) -> 0 | Z18: =IF($A18="",0,IFERROR(INDEX(ДОВ_ВКЛ,MATCH($A18,КАТЕГОРІЇ,0)),0)) -> 0 | AA18: =IF($A18="",0,IFERROR(INDEX(ДОВ_ДОПЛ_ДОР,MATCH($A18,КАТЕГОРІЇ,0)),0)) -> 0 | AB18: =IF(OR($U$3=0,$U$8=0),0,IFERROR(INDEX(ПАКЕТИ_ЦІНИ,MATCH($U$10&"|Будні",ПАКЕТИ_КЛЮЧ,0),$U$3),0)) -> 0 | AC18: =IF(OR($U$3=0,$U$8=0),0,IFERROR(INDEX(ПАКЕТИ_ЦІНИ,MATCH($U$10&"|Вихідні",ПАКЕТИ_КЛЮЧ,0),$U$3),0)) -> 0 | AD18: =IF(OR($U$3=0,$U$9=0,$A18=""),0,IFERROR(INDEX(SPA_ЦІНИ,MATCH(INDEX(ДОВ_SPA,MATCH($A18,КАТЕГОРІЇ,0)),SPA_РІВЕНЬ,0),$U$3),0)) -> 0 | AE18: =IF(OR($U$3=0,$U$9=0,$A18=""),0,IFERROR(INDEX(SPA_ЦІНИ,MATCH(INDEX(ДОВ_SPA,MATCH($A18,КАТЕГОРІЇ,0)),SPA_РІВЕНЬ,0),$U$3+1),0)) -> 0 | AF18: =IF(OR($A18="",W18=0,AND($U$8=1,AB18=0),AND($U$9=1,AD18=0)),0,1) -> 0 | AG18: =IF(OR($A18="",X18=0,AND($U$8=1,AC18=0),AND($U$9=1,AE18=0)),0,1) -> 0
A19: =IF('Довідник категорій'!B15="","",'Довідник категорій'!B15) | B19: =IF($A19="","",IFERROR(INDEX(ДОВ_BOOKING,MATCH($A19,КАТЕГОРІЇ,0)),"")) | C19: =IF($A19="","",IFERROR(INDEX(ДОВ_КОД,MATCH($A19,КАТЕГОРІЇ,0)),"")) | D19: =IF(OR($AF19=0,D$8>$Y19),"",ROUND($W19*(1-$U$5)/ОКРУГЛЕННЯ,0)*ОКРУГЛЕННЯ+MAX(0,D$8-$Z19)*$AA19*(1-$U$5)+D$8*$AB19*(1-$U$5*$U$6)+$AD19*(1-$U$5*$U$7)) | E19: =IF(OR($AF19=0,E$8>$Y19),"",ROUND($W19*(1-$U$5)/ОКРУГЛЕННЯ,0)*ОКРУГЛЕННЯ+MAX(0,E$8-$Z19)*$AA19*(1-$U$5)+E$8*$AB19*(1-$U$5*$U$6)+$AD19*(1-$U$5*$U$7)) | F19: =IF(OR($AF19=0,F$8>$Y19),"",ROUND($W19*(1-$U$5)/ОКРУГЛЕННЯ,0)*ОКРУГЛЕННЯ+MAX(0,F$8-$Z19)*$AA19*(1-$U$5)+F$8*$AB19*(1-$U$5*$U$6)+$AD19*(1-$U$5*$U$7)) | G19: =IF(OR($AF19=0,G$8>$Y19),"",ROUND($W19*(1-$U$5)/ОКРУГЛЕННЯ,0)*ОКРУГЛЕННЯ+MAX(0,G$8-$Z19)*$AA19*(1-$U$5)+G$8*$AB19*(1-$U$5*$U$6)+$AD19*(1-$U$5*$U$7)) | H19: =IF(OR($AF19=0,H$8>$Y19),"",ROUND($W19*(1-$U$5)/ОКРУГЛЕННЯ,0)*ОКРУГЛЕННЯ+MAX(0,H$8-$Z19)*$AA19*(1-$U$5)+H$8*$AB19*(1-$U$5*$U$6)+$AD19*(1-$U$5*$U$7)) | I19: =IF(OR($AF19=0,I$8>$Y19),"",ROUND($W19*(1-$U$5)/ОКРУГЛЕННЯ,0)*ОКРУГЛЕННЯ+MAX(0,I$8-$Z19)*$AA19*(1-$U$5)+I$8*$AB19*(1-$U$5*$U$6)+$AD19*(1-$U$5*$U$7)) | J19: =IF(OR($AF19=0,J$8>$Y19),"",ROUND($W19*(1-$U$5)/ОКРУГЛЕННЯ,0)*ОКРУГЛЕННЯ+MAX(0,J$8-$Z19)*$AA19*(1-$U$5)+J$8*$AB19*(1-$U$5*$U$6)+$AD19*(1-$U$5*$U$7)) | K19: =IF(OR($AF19=0,K$8>$Y19),"",ROUND($W19*(1-$U$5)/ОКРУГЛЕННЯ,0)*ОКРУГЛЕННЯ+MAX(0,K$8-$Z19)*$AA19*(1-$U$5)+K$8*$AB19*(1-$U$5*$U$6)+$AD19*(1-$U$5*$U$7)) | M19: =IF(OR($AG19=0,M$8>$Y19),"",ROUND($X19*(1-$U$5)/ОКРУГЛЕННЯ,0)*ОКРУГЛЕННЯ+MAX(0,M$8-$Z19)*$AA19*(1-$U$5)+M$8*$AC19*(1-$U$5*$U$6)+$AE19*(1-$U$5*$U$7)) | N19: =IF(OR($AG19=0,N$8>$Y19),"",ROUND($X19*(1-$U$5)/ОКРУГЛЕННЯ,0)*ОКРУГЛЕННЯ+MAX(0,N$8-$Z19)*$AA19*(1-$U$5)+N$8*$AC19*(1-$U$5*$U$6)+$AE19*(1-$U$5*$U$7)) | O19: =IF(OR($AG19=0,O$8>$Y19),"",ROUND($X19*(1-$U$5)/ОКРУГЛЕННЯ,0)*ОКРУГЛЕННЯ+MAX(0,O$8-$Z19)*$AA19*(1-$U$5)+O$8*$AC19*(1-$U$5*$U$6)+$AE19*(1-$U$5*$U$7)) | P19: =IF(OR($AG19=0,P$8>$Y19),"",ROUND($X19*(1-$U$5)/ОКРУГЛЕННЯ,0)*ОКРУГЛЕННЯ+MAX(0,P$8-$Z19)*$AA19*(1-$U$5)+P$8*$AC19*(1-$U$5*$U$6)+$AE19*(1-$U$5*$U$7)) | Q19: =IF(OR($AG19=0,Q$8>$Y19),"",ROUND($X19*(1-$U$5)/ОКРУГЛЕННЯ,0)*ОКРУГЛЕННЯ+MAX(0,Q$8-$Z19)*$AA19*(1-$U$5)+Q$8*$AC19*(1-$U$5*$U$6)+$AE19*(1-$U$5*$U$7)) | R19: =IF(OR($AG19=0,R$8>$Y19),"",ROUND($X19*(1-$U$5)/ОКРУГЛЕННЯ,0)*ОКРУГЛЕННЯ+MAX(0,R$8-$Z19)*$AA19*(1-$U$5)+R$8*$AC19*(1-$U$5*$U$6)+$AE19*(1-$U$5*$U$7)) | S19: =IF(OR($AG19=0,S$8>$Y19),"",ROUND($X19*(1-$U$5)/ОКРУГЛЕННЯ,0)*ОКРУГЛЕННЯ+MAX(0,S$8-$Z19)*$AA19*(1-$U$5)+S$8*$AC19*(1-$U$5*$U$6)+$AE19*(1-$U$5*$U$7)) | T19: =IF(OR($AG19=0,T$8>$Y19),"",ROUND($X19*(1-$U$5)/ОКРУГЛЕННЯ,0)*ОКРУГЛЕННЯ+MAX(0,T$8-$Z19)*$AA19*(1-$U$5)+T$8*$AC19*(1-$U$5*$U$6)+$AE19*(1-$U$5*$U$7)) | W19: =IF(OR($U$3=0,$A19=""),0,IFERROR(INDEX(БАЗА_ЦІНИ,MATCH($A19,БАЗА_КАТ,0),$U$3),0)) -> 0 | X19: =IF(OR($U$3=0,$A19=""),0,IFERROR(INDEX(БАЗА_ЦІНИ,MATCH($A19,БАЗА_КАТ,0),$U$3+1),0)) -> 0 | Y19: =IF($A19="",0,IFERROR(INDEX(ДОВ_МАКС,MATCH($A19,КАТЕГОРІЇ,0)),0)) -> 0 | Z19: =IF($A19="",0,IFERROR(INDEX(ДОВ_ВКЛ,MATCH($A19,КАТЕГОРІЇ,0)),0)) -> 0 | AA19: =IF($A19="",0,IFERROR(INDEX(ДОВ_ДОПЛ_ДОР,MATCH($A19,КАТЕГОРІЇ,0)),0)) -> 0 | AB19: =IF(OR($U$3=0,$U$8=0),0,IFERROR(INDEX(ПАКЕТИ_ЦІНИ,MATCH($U$10&"|Будні",ПАКЕТИ_КЛЮЧ,0),$U$3),0)) -> 0 | AC19: =IF(OR($U$3=0,$U$8=0),0,IFERROR(INDEX(ПАКЕТИ_ЦІНИ,MATCH($U$10&"|Вихідні",ПАКЕТИ_КЛЮЧ,0),$U$3),0)) -> 0 | AD19: =IF(OR($U$3=0,$U$9=0,$A19=""),0,IFERROR(INDEX(SPA_ЦІНИ,MATCH(INDEX(ДОВ_SPA,MATCH($A19,КАТЕГОРІЇ,0)),SPA_РІВЕНЬ,0),$U$3),0)) -> 0 | AE19: =IF(OR($U$3=0,$U$9=0,$A19=""),0,IFERROR(INDEX(SPA_ЦІНИ,MATCH(INDEX(ДОВ_SPA,MATCH($A19,КАТЕГОРІЇ,0)),SPA_РІВЕНЬ,0),$U$3+1),0)) -> 0 | AF19: =IF(OR($A19="",W19=0,AND($U$8=1,AB19=0),AND($U$9=1,AD19=0)),0,1) -> 0 | AG19: =IF(OR($A19="",X19=0,AND($U$8=1,AC19=0),AND($U$9=1,AE19=0)),0,1) -> 0
A20: =IF('Довідник категорій'!B16="","",'Довідник категорій'!B16) | B20: =IF($A20="","",IFERROR(INDEX(ДОВ_BOOKING,MATCH($A20,КАТЕГОРІЇ,0)),"")) | C20: =IF($A20="","",IFERROR(INDEX(ДОВ_КОД,MATCH($A20,КАТЕГОРІЇ,0)),"")) | D20: =IF(OR($AF20=0,D$8>$Y20),"",ROUND($W20*(1-$U$5)/ОКРУГЛЕННЯ,0)*ОКРУГЛЕННЯ+MAX(0,D$8-$Z20)*$AA20*(1-$U$5)+D$8*$AB20*(1-$U$5*$U$6)+$AD20*(1-$U$5*$U$7)) | E20: =IF(OR($AF20=0,E$8>$Y20),"",ROUND($W20*(1-$U$5)/ОКРУГЛЕННЯ,0)*ОКРУГЛЕННЯ+MAX(0,E$8-$Z20)*$AA20*(1-$U$5)+E$8*$AB20*(1-$U$5*$U$6)+$AD20*(1-$U$5*$U$7)) | F20: =IF(OR($AF20=0,F$8>$Y20),"",ROUND($W20*(1-$U$5)/ОКРУГЛЕННЯ,0)*ОКРУГЛЕННЯ+MAX(0,F$8-$Z20)*$AA20*(1-$U$5)+F$8*$AB20*(1-$U$5*$U$6)+$AD20*(1-$U$5*$U$7)) | G20: =IF(OR($AF20=0,G$8>$Y20),"",ROUND($W20*(1-$U$5)/ОКРУГЛЕННЯ,0)*ОКРУГЛЕННЯ+MAX(0,G$8-$Z20)*$AA20*(1-$U$5)+G$8*$AB20*(1-$U$5*$U$6)+$AD20*(1-$U$5*$U$7)) | H20: =IF(OR($AF20=0,H$8>$Y20),"",ROUND($W20*(1-$U$5)/ОКРУГЛЕННЯ,0)*ОКРУГЛЕННЯ+MAX(0,H$8-$Z20)*$AA20*(1-$U$5)+H$8*$AB20*(1-$U$5*$U$6)+$AD20*(1-$U$5*$U$7)) | I20: =IF(OR($AF20=0,I$8>$Y20),"",ROUND($W20*(1-$U$5)/ОКРУГЛЕННЯ,0)*ОКРУГЛЕННЯ+MAX(0,I$8-$Z20)*$AA20*(1-$U$5)+I$8*$AB20*(1-$U$5*$U$6)+$AD20*(1-$U$5*$U$7)) | J20: =IF(OR($AF20=0,J$8>$Y20),"",ROUND($W20*(1-$U$5)/ОКРУГЛЕННЯ,0)*ОКРУГЛЕННЯ+MAX(0,J$8-$Z20)*$AA20*(1-$U$5)+J$8*$AB20*(1-$U$5*$U$6)+$AD20*(1-$U$5*$U$7)) | K20: =IF(OR($AF20=0,K$8>$Y20),"",ROUND($W20*(1-$U$5)/ОКРУГЛЕННЯ,0)*ОКРУГЛЕННЯ+MAX(0,K$8-$Z20)*$AA20*(1-$U$5)+K$8*$AB20*(1-$U$5*$U$6)+$AD20*(1-$U$5*$U$7)) | M20: =IF(OR($AG20=0,M$8>$Y20),"",ROUND($X20*(1-$U$5)/ОКРУГЛЕННЯ,0)*ОКРУГЛЕННЯ+MAX(0,M$8-$Z20)*$AA20*(1-$U$5)+M$8*$AC20*(1-$U$5*$U$6)+$AE20*(1-$U$5*$U$7)) | N20: =IF(OR($AG20=0,N$8>$Y20),"",ROUND($X20*(1-$U$5)/ОКРУГЛЕННЯ,0)*ОКРУГЛЕННЯ+MAX(0,N$8-$Z20)*$AA20*(1-$U$5)+N$8*$AC20*(1-$U$5*$U$6)+$AE20*(1-$U$5*$U$7)) | O20: =IF(OR($AG20=0,O$8>$Y20),"",ROUND($X20*(1-$U$5)/ОКРУГЛЕННЯ,0)*ОКРУГЛЕННЯ+MAX(0,O$8-$Z20)*$AA20*(1-$U$5)+O$8*$AC20*(1-$U$5*$U$6)+$AE20*(1-$U$5*$U$7)) | P20: =IF(OR($AG20=0,P$8>$Y20),"",ROUND($X20*(1-$U$5)/ОКРУГЛЕННЯ,0)*ОКРУГЛЕННЯ+MAX(0,P$8-$Z20)*$AA20*(1-$U$5)+P$8*$AC20*(1-$U$5*$U$6)+$AE20*(1-$U$5*$U$7)) | Q20: =IF(OR($AG20=0,Q$8>$Y20),"",ROUND($X20*(1-$U$5)/ОКРУГЛЕННЯ,0)*ОКРУГЛЕННЯ+MAX(0,Q$8-$Z20)*$AA20*(1-$U$5)+Q$8*$AC20*(1-$U$5*$U$6)+$AE20*(1-$U$5*$U$7)) | R20: =IF(OR($AG20=0,R$8>$Y20),"",ROUND($X20*(1-$U$5)/ОКРУГЛЕННЯ,0)*ОКРУГЛЕННЯ+MAX(0,R$8-$Z20)*$AA20*(1-$U$5)+R$8*$AC20*(1-$U$5*$U$6)+$AE20*(1-$U$5*$U$7)) | S20: =IF(OR($AG20=0,S$8>$Y20),"",ROUND($X20*(1-$U$5)/ОКРУГЛЕННЯ,0)*ОКРУГЛЕННЯ+MAX(0,S$8-$Z20)*$AA20*(1-$U$5)+S$8*$AC20*(1-$U$5*$U$6)+$AE20*(1-$U$5*$U$7)) | T20: =IF(OR($AG20=0,T$8>$Y20),"",ROUND($X20*(1-$U$5)/ОКРУГЛЕННЯ,0)*ОКРУГЛЕННЯ+MAX(0,T$8-$Z20)*$AA20*(1-$U$5)+T$8*$AC20*(1-$U$5*$U$6)+$AE20*(1-$U$5*$U$7)) | W20: =IF(OR($U$3=0,$A20=""),0,IFERROR(INDEX(БАЗА_ЦІНИ,MATCH($A20,БАЗА_КАТ,0),$U$3),0)) -> 0 | X20: =IF(OR($U$3=0,$A20=""),0,IFERROR(INDEX(БАЗА_ЦІНИ,MATCH($A20,БАЗА_КАТ,0),$U$3+1),0)) -> 0 | Y20: =IF($A20="",0,IFERROR(INDEX(ДОВ_МАКС,MATCH($A20,КАТЕГОРІЇ,0)),0)) -> 0 | Z20: =IF($A20="",0,IFERROR(INDEX(ДОВ_ВКЛ,MATCH($A20,КАТЕГОРІЇ,0)),0)) -> 0 | AA20: =IF($A20="",0,IFERROR(INDEX(ДОВ_ДОПЛ_ДОР,MATCH($A20,КАТЕГОРІЇ,0)),0)) -> 0 | AB20: =IF(OR($U$3=0,$U$8=0),0,IFERROR(INDEX(ПАКЕТИ_ЦІНИ,MATCH($U$10&"|Будні",ПАКЕТИ_КЛЮЧ,0),$U$3),0)) -> 0 | AC20: =IF(OR($U$3=0,$U$8=0),0,IFERROR(INDEX(ПАКЕТИ_ЦІНИ,MATCH($U$10&"|Вихідні",ПАКЕТИ_КЛЮЧ,0),$U$3),0)) -> 0 | AD20: =IF(OR($U$3=0,$U$9=0,$A20=""),0,IFERROR(INDEX(SPA_ЦІНИ,MATCH(INDEX(ДОВ_SPA,MATCH($A20,КАТЕГОРІЇ,0)),SPA_РІВЕНЬ,0),$U$3),0)) -> 0 | AE20: =IF(OR($U$3=0,$U$9=0,$A20=""),0,IFERROR(INDEX(SPA_ЦІНИ,MATCH(INDEX(ДОВ_SPA,MATCH($A20,КАТЕГОРІЇ,0)),SPA_РІВЕНЬ,0),$U$3+1),0)) -> 0 | AF20: =IF(OR($A20="",W20=0,AND($U$8=1,AB20=0),AND($U$9=1,AD20=0)),0,1) -> 0 | AG20: =IF(OR($A20="",X20=0,AND($U$8=1,AC20=0),AND($U$9=1,AE20=0)),0,1) -> 0

Sheet Калькулятор
A1: КАЛЬКУЛЯТОР ВАРТОСТІ БРОНЮВАННЯ — PHOENIX СХІДНИЦЯ | U1: ТЕХНІЧНІ ДАНІ — НЕ РЕДАГУВАТИ
A3: Заповнюйте лише жовті клітинки. Рахує тією самою формулою, що й лист «Прайс», але додатково розділяє дорослих і дітей: базову місткість заповнюють спершу дорослі, решта гостей іде як додаткові місця. Поле «Дата заїзду» необовʼязкове — воно лише підказує прайс-лист і тип дня. | U3: =IFERROR(MATCH($B$6,ПЛ_РЯДОК,0),0) -> 5 | V3: колонка прайс-листа
A5: ВХІДНІ ПАРАМЕТРИ | D5: РОЗРАХУНОК
A6: Активний прайс-лист | B6: =Прайс!$B$3 -> 0сінь 26 0-10% | D6: Статус | F6: =IF(OR($B$6="",$B$8="",$U$3=0,F7<F8,F7>F10,F11=0,AND($U$8=1,OR(AND($B$10>0,F18=0),AND($B$11>0,F19=0))),AND($U$9=1,F20=0)),"ПЕРЕВІРТЕ ПАРАМЕТРИ","OK") -> OK
A7: Тариф (знижка) | B7: Rack Rate | D7: Усього гостей | F7: =$B$10+$B$11 -> 2
A8: Категорія | B8: Classic Chalet | D8: Мін. гостей | F8: =IFERROR(INDEX(ДОВ_МІН,MATCH($B$8,КАТЕГОРІЇ,0)),0) -> 2 | U8: =IF(OR($B$12="BB",$B$12="BBSPA",$B$12="ROSPABB"),1,0) -> 0 | V8: потрібен пакет
A9: Тип дня | B9: Будні | D9: Включено у базову ціну | F9: =IFERROR(INDEX(ДОВ_ВКЛ,MATCH($B$8,КАТЕГОРІЇ,0)),0) -> 2 | U9: =IF(OR($B$12="ROSPA",$B$12="ROSPABB"),1,0) -> 0 | V9: потрібен SPA
A10: Дорослих | B10: 2 | D10: Макс. гостей | F10: =IFERROR(INDEX(ДОВ_МАКС,MATCH($B$8,КАТЕГОРІЇ,0)),0) -> 3 | U10: =IF($U$8=0,"",IF($B$12="ROSPABB","BB",$B$12)) | V10: ключ пакета
A11: Дітей | B11: 0 | D11: RO база за типом дня, грн | F11: =IF($U$3=0,0,IFERROR(INDEX(БАЗА_ЦІНИ,MATCH($B$8,БАЗА_КАТ,0),$U$3+IF($B$9="Вихідні",1,0)),0)) -> 4200
A12: Пакет | B12: RO | D12: Додаткових дорослих | F12: =MAX(0,$B$10-F9) -> 0
A13: Кількість тварин | B13: 0 | D13: Додаткових дітей | F13: =MAX(0,F7-F9)-F12 -> 0
A14: Кількість ночей | B14: 1 | D14: Доплата за додаткові місця, грн | F14: =F12*IFERROR(INDEX(ДОВ_ДОПЛ_ДОР,MATCH($B$8,КАТЕГОРІЇ,0)),0)+F13*IFERROR(INDEX(ДОВ_ДОПЛ_ДІТ,MATCH($B$8,КАТЕГОРІЇ,0)),0) -> 0
A15: Дата заїзду (необовʼязково) | D15: Знижка на проживання | F15: =IF($B$12="BBSPA",ЗНИЖКА_BBSPA,IFERROR(SUMIFS(ТАРИФИ_ЗНИЖКИ,ТАРИФИ_НАЗВИ,$B$7),0)) -> 0
D16: Перемикач: знижка на пакет | F16: =IF($U$3=0,0,IFERROR(INDEX(ПЕРЕМИКАЧІ,IF($B$12="BBSPA",2,1),$U$3),0)) -> 0
D17: Перемикач: знижка на SPA | F17: =IF($U$3=0,0,IFERROR(INDEX(ПЕРЕМИКАЧІ,3,$U$3),0)) -> 0
D18: Пакет, дорослий, грн | F18: =IF(OR($U$3=0,$U$8=0),0,IFERROR(INDEX(ПАКЕТИ_ЦІНИ,MATCH($U$10&"|"&$B$9,ПАКЕТИ_КЛЮЧ,0),$U$3),0)) -> 0
D19: Пакет, дитина, грн | F19: =IF(OR($U$3=0,$U$8=0),0,IFERROR(INDEX(ПАКЕТИ_ЦІНИ,MATCH($U$10&"|"&$B$9,ПАКЕТИ_КЛЮЧ,0),$U$3+1),0)) -> 0
D20: Фіксований SPA-візит, грн | F20: =IF(OR($U$3=0,$U$9=0),0,IFERROR(INDEX(SPA_ЦІНИ,MATCH(INDEX(ДОВ_SPA,MATCH($B$8,КАТЕГОРІЇ,0)),SPA_РІВЕНЬ,0),$U$3+IF($B$9="Вихідні",1,0)),0)) -> 0
D21: Проживання з тваринами, грн | F21: =$B$13*ТВАРИНИ -> 0
D22: Проживання за базовою місткістю до знижки, грн | F22: =F11 -> 4200
D23: ЦІНА ЗА НІЧ, грн | F23: =IF($F$6<>"OK","",ROUND(F22*(1-F15)/ОКРУГЛЕННЯ,0)*ОКРУГЛЕННЯ+F14*(1-F15)+($B$10*F18+$B$11*F19)*(1-F15*F16)+F20*(1-F15*F17)+F21) -> 4200
D24: ВАРТІСТЬ ПРОЖИВАННЯ, грн | F24: =IF(F23="","",F23*$B$14) -> 4200
D26: ПІДКАЗКА ЗА ДАТОЮ ЗАЇЗДУ
D27: Прайс-лист, що покриває дату | F27: =IF($B$15="","",IFERROR(INDEX(ПРАЙС_ЛИСТИ,SUMPRODUCT(MAX((ПЛ_ДАТА_З<=$B$15)*(ПЛ_ДАТА_ПО>=$B$15)*(ПЛ_СТАТУС="Активний")*(ПРАЙС_ЛИСТИ<>"")*ROW(ПРАЙС_ЛИСТИ)))-5),"— не знайдено —"))
D28: Тип дня за датою | F28: =IF($B$15="","",IF(WEEKDAY($B$15,2)>=ПЕРШИЙ_ВИХІДНИЙ,"Вихідні","Будні"))
D29: Підказка не змінює розрахунок — прайс-лист і тип дня обираються вручну вище.

Sheet Керування прайсом
A1: КЕРУВАННЯ ПРАЙСОМ — PHOENIX СХІДНИЦЯ
A2: Три кроки: 1) додайте прайс-лист у наступному вільному рядку зліва; 2) заповніть його двоколонковий блок праворуч (будні / вихідні); 3) перевірте результат у листі «Прайс». Жовті клітинки — ввід. | H2: технічний рядок — не редагувати | I2: =IF($A$6="","",$A$6) -> Осінь 2025 | J2: =IF($A$6="","",$A$6) -> Осінь 2025 | K2: =IF($A$7="","",$A$7) -> Осінь 2026 Базовий Прайс | L2: =IF($A$7="","",$A$7) -> Осінь 2026 Базовий Прайс | M2: =IF($A$8="","",$A$8) -> 0сінь 26 0-10% | N2: =IF($A$8="","",$A$8) -> 0сінь 26 0-10% | O2: =IF($A$9="","",$A$9) -> Осінь 26 канікули 0-10% | P2: =IF($A$9="","",$A$9) -> Осінь 26 канікули 0-10% | Q2: =IF($A$10="","",$A$10) -> 0сінь 26 10-20% | R2: =IF($A$10="","",$A$10) -> 0сінь 26 10-20% | S2: =IF($A$11="","",$A$11) -> Осінь 26 канікули 10-20% | T2: =IF($A$11="","",$A$11) -> Осінь 26 канікули 10-20% | U2: =IF($A$12="","",$A$12) -> 0сінь 26 20-30% | V2: =IF($A$12="","",$A$12) -> 0сінь 26 20-30% | W2: =IF($A$13="","",$A$13) -> Осінь 26 канікули 20-30% | X2: =IF($A$13="","",$A$13) -> Осінь 26 канікули 20-30% | Y2: =IF($A$14="","",$A$14) -> 0сінь 26 30-40% | Z2: =IF($A$14="","",$A$14) -> 0сінь 26 30-40% | AA2: =IF($A$15="","",$A$15) -> Осінь 26 канікули 30-40% | AB2: =IF($A$15="","",$A$15) -> Осінь 26 канікули 30-40% | AC2: =IF($A$16="","",$A$16) -> 0сінь 26 40-50% | AD2: =IF($A$16="","",$A$16) -> 0сінь 26 40-50% | AE2: =IF($A$17="","",$A$17) -> Осінь 26 канікули 40-50% | AF2: =IF($A$17="","",$A$17) -> Осінь 26 канікули 40-50% | AG2: =IF($A$18="","",$A$18) | AH2: =IF($A$18="","",$A$18) | AI2: =IF($A$19="","",$A$19) | AJ2: =IF($A$19="","",$A$19) | AK2: =IF($A$20="","",$A$20) | AL2: =IF($A$20="","",$A$20) | AM2: =IF($A$21="","",$A$21) | AN2: =IF($A$21="","",$A$21) | AO2: =IF($A$22="","",$A$22) | AP2: =IF($A$22="","",$A$22) | AQ2: =IF($A$23="","",$A$23) | AR2: =IF($A$23="","",$A$23) | AS2: =IF($A$24="","",$A$24) | AT2: =IF($A$24="","",$A$24) | AU2: =IF($A$25="","",$A$25) | AV2: =IF($A$25="","",$A$25) | AW2: =IF($A$26="","",$A$26) | AX2: =IF($A$26="","",$A$26) | AY2: =IF($A$27="","",$A$27) | AZ2: =IF($A$27="","",$A$27) | BA2: =IF($A$28="","",$A$28) | BB2: =IF($A$28="","",$A$28) | BC2: =IF($A$29="","",$A$29) | BD2: =IF($A$29="","",$A$29) | BE2: =IF($A$30="","",$A$30) | BF2: =IF($A$30="","",$A$30) | BG2: =IF($A$31="","",$A$31) | BH2: =IF($A$31="","",$A$31) | BI2: =IF($A$32="","",$A$32) | BJ2: =IF($A$32="","",$A$32) | BK2: =IF($A$33="","",$A$33) | BL2: =IF($A$33="","",$A$33) | BM2: =IF($A$34="","",$A$34) | BN2: =IF($A$34="","",$A$34) | BO2: =IF($A$35="","",$A$35) | BP2: =IF($A$35="","",$A$35) | BQ2: =IF($A$36="","",$A$36) | BR2: =IF($A$36="","",$A$36) | BS2: =IF($A$37="","",$A$37) | BT2: =IF($A$37="","",$A$37) | BU2: =IF($A$38="","",$A$38) | BV2: =IF($A$38="","",$A$38) | BW2: =IF($A$39="","",$A$39) | BX2: =IF($A$39="","",$A$39) | BY2: =IF($A$40="","",$A$40) | BZ2: =IF($A$40="","",$A$40) | CA2: =IF($A$41="","",$A$41) | CB2: =IF($A$41="","",$A$41) | CC2: =IF($A$42="","",$A$42) | CD2: =IF($A$42="","",$A$42) | CE2: =IF($A$43="","",$A$43) | CF2: =IF($A$43="","",$A$43) | CG2: =IF($A$44="","",$A$44) | CH2: =IF($A$44="","",$A$44) | CI2: =IF($A$45="","",$A$45) | CJ2: =IF($A$45="","",$A$45) | CK2: =IF($A$46="","",$A$46) | CL2: =IF($A$46="","",$A$46) | CM2: =IF($A$47="","",$A$47) | CN2: =IF($A$47="","",$A$47) | CO2: =IF($A$48="","",$A$48) | CP2: =IF($A$48="","",$A$48) | CQ2: =IF($A$49="","",$A$49) | CR2: =IF($A$49="","",$A$49) | CS2: =IF($A$50="","",$A$50) | CT2: =IF($A$50="","",$A$50) | CU2: =IF($A$51="","",$A$51) | CV2: =IF($A$51="","",$A$51) | CW2: =IF($A$52="","",$A$52) | CX2: =IF($A$52="","",$A$52) | CY2: =IF($A$53="","",$A$53) | CZ2: =IF($A$53="","",$A$53) | DA2: =IF($A$54="","",$A$54) | DB2: =IF($A$54="","",$A$54) | DC2: =IF($A$55="","",$A$55) | DD2: =IF($A$55="","",$A$55) | DE2: =IF($A$56="","",$A$56) | DF2: =IF($A$56="","",$A$56) | DG2: =IF($A$57="","",$A$57) | DH2: =IF($A$57="","",$A$57) | DI2: =IF($A$58="","",$A$58) | DJ2: =IF($A$58="","",$A$58) | DK2: =IF($A$59="","",$A$59) | DL2: =IF($A$59="","",$A$59) | DM2: =IF($A$60="","",$A$60) | DN2: =IF($A$60="","",$A$60) | DO2: =IF($A$61="","",$A$61) | DP2: =IF($A$61="","",$A$61) | DQ2: =IF($A$62="","",$A$62) | DR2: =IF($A$62="","",$A$62) | DS2: =IF($A$63="","",$A$63) | DT2: =IF($A$63="","",$A$63) | DU2: =IF($A$64="","",$A$64) | DV2: =IF($A$64="","",$A$64) | DW2: =IF($A$65="","",$A$65) | DX2: =IF($A$65="","",$A$65) | DY2: =IF($A$66="","",$A$66) | DZ2: =IF($A$66="","",$A$66) | EA2: =IF($A$67="","",$A$67) | EB2: =IF($A$67="","",$A$67) | EC2: =IF($A$68="","",$A$68) | ED2: =IF($A$68="","",$A$68) | EE2: =IF($A$69="","",$A$69) | EF2: =IF($A$69="","",$A$69) | EG2: =IF($A$70="","",$A$70) | EH2: =IF($A$70="","",$A$70) | EI2: =IF($A$71="","",$A$71) | EJ2: =IF($A$71="","",$A$71) | EK2: =IF($A$72="","",$A$72) | EL2: =IF($A$72="","",$A$72) | EM2: =IF($A$73="","",$A$73) | EN2: =IF($A$73="","",$A$73) | EO2: =IF($A$74="","",$A$74) | EP2: =IF($A$74="","",$A$74) | EQ2: =IF($A$75="","",$A$75) | ER2: =IF($A$75="","",$A$75) | ES2: =IF($A$76="","",$A$76) | ET2: =IF($A$76="","",$A$76) | EU2: =IF($A$77="","",$A$77) | EV2: =IF($A$77="","",$A$77) | EW2: =IF($A$78="","",$A$78) | EX2: =IF($A$78="","",$A$78) | EY2: =IF($A$79="","",$A$79) | EZ2: =IF($A$79="","",$A$79) | FA2: =IF($A$80="","",$A$80) | FB2: =IF($A$80="","",$A$80) | FC2: =IF($A$81="","",$A$81) | FD2: =IF($A$81="","",$A$81) | FE2: =IF($A$82="","",$A$82) | FF2: =IF($A$82="","",$A$82) | FG2: =IF($A$83="","",$A$83) | FH2: =IF($A$83="","",$A$83) | FI2: =IF($A$84="","",$A$84) | FJ2: =IF($A$84="","",$A$84) | FK2: =IF($A$85="","",$A$85) | FL2: =IF($A$85="","",$A$85) | FM2: =IF($A$86="","",$A$86) | FN2: =IF($A$86="","",$A$86) | FO2: =IF($A$87="","",$A$87) | FP2: =IF($A$87="","",$A$87) | FQ2: =IF($A$88="","",$A$88) | FR2: =IF($A$88="","",$A$88) | FS2: =IF($A$89="","",$A$89) | FT2: =IF($A$89="","",$A$89) | FU2: =IF($A$90="","",$A$90) | FV2: =IF($A$90="","",$A$90) | FW2: =IF($A$91="","",$A$91) | FX2: =IF($A$91="","",$A$91) | FY2: =IF($A$92="","",$A$92) | FZ2: =IF($A$92="","",$A$92) | GA2: =IF($A$93="","",$A$93) | GB2: =IF($A$93="","",$A$93) | GC2: =IF($A$94="","",$A$94) | GD2: =IF($A$94="","",$A$94) | GE2: =IF($A$95="","",$A$95) | GF2: =IF($A$95="","",$A$95) | GG2: =IF($A$96="","",$A$96) | GH2: =IF($A$96="","",$A$96) | GI2: =IF($A$97="","",$A$97) | GJ2: =IF($A$97="","",$A$97) | GK2: =IF($A$98="","",$A$98) | GL2: =IF($A$98="","",$A$98) | GM2: =IF($A$99="","",$A$99) | GN2: =IF($A$99="","",$A$99) | GO2: =IF($A$100="","",$A$100) | GP2: =IF($A$100="","",$A$100) | GQ2: =IF($A$101="","",$A$101) | GR2: =IF($A$101="","",$A$101) | GS2: =IF($A$102="","",$A$102) | GT2: =IF($A$102="","",$A$102) | GU2: =IF($A$103="","",$A$103) | GV2: =IF($A$103="","",$A$103) | GW2: =IF($A$104="","",$A$104) | GX2: =IF($A$104="","",$A$104) | GY2: =IF($A$105="","",$A$105) | GZ2: =IF($A$105="","",$A$105)
A4: 1. ПРАЙС-ЛИСТИ / ПЕРІОДИ | F4: 2. ГЛОБАЛЬНІ ПАРАМЕТРИ
